Workbook

Sheet PXD 04.10.25 cũ
H1: BM.04F/QT.05 Ngày hiệu lực: 06/06/2025 Lần sửa đổi: 02
B3: Số: 04.10.2025/LSX-XĐ-NM.HRC1
A4: LỆNH SẢN XUẤT
A5: - Bộ phận thực hiện: XĐ-NM.HRC1
A6: =+'PXC 05.10.25'!A6 -> - Thời gian hiệu lực: Từ 08h00, ngày 23/10/2025 đến 08h00, ngày 30/10/2025
A7: STT | B7: Máy đúc | C7: Mác phôi | D7: Kích thước | G7: Sản lượng yêu cầu (Tấn) | H7: Thời gian SX dự kiến | I7: Sản phẩm cán | J7: Order | K7: Ghi chú
D8: Tiết diện (mm x mm) | E8: Chiều dài (mm) | F8: Khối lượng phôi (tấn)
A9: =ROW()-8 -> 1 | B9: TSC 1 & 2 | C9: SAE1006-Al | D9: 65x1270 | E9: 34000 | F9: =LEFT(D9,2)*RIGHT(D9,4)*E9*7600/10^12 -> 21.33092 | G9: =SUMIF('PXC 05.10.25'!N10:T10,'PXD 04.10.25 cũ'!D9,'PXC 05.10.25'!#REF!)*1.05 -> #REF! | H9: 08h00 ngày 16/10/2025 08h00 ngày 23/10/2025 | I9: 4.00/3.00/2.75/...x126X | J9: 1010003305 | K9: (1)
A10: =ROW()-8 -> 2 | B10: TSC 1 & 2 | C10: SAE1006-Al | D10: 65x1240 | E10: 34000 | F10: =LEFT(D10,2)*RIGHT(D10,4)*E10*7600/10^12 -> 20.82704 | G10: =SUMIF('PXC 05.10.25'!N11:T11,'PXD 04.10.25 cũ'!D10,'PXC 05.10.25'!#REF!)*1.05 -> #REF! | I10: 4.00/3.00/2.95/...x123X
A11: =ROW()-8 -> 3 | B11: TSC 1 & 2 | C11: SAE1006-Al | D11: 65x1220 | E11: 34000 | F11: =LEFT(D11,2)*RIGHT(D11,4)*E11*7600/10^12 -> 20.49112 | G11: =SUMIF('PXC 05.10.25'!N11:T12,'PXD 04.10.25 cũ'!D11,'PXC 05.10.25'!#REF!)*1.05 -> #REF! | I11: 3.00/2.75/2.45/...x121X/121Y
B12: Tổng | G12: =SUM(G9:G11) -> #REF!
A13: *Ghi chú (1): - Thành phần mẻ đúc mác SAE1006-Al như sau: [C]≤0,055%; [Si]≤0,030%; [Mn]=(0,15 ÷0,18)%; [P]≤0,020%; [S]≤0,008%, [Altot]=(200÷400)ppm, [Ca]=(20-35)ppm.
F14: =+'PXC 05.10.25'!N13 -> Quảng Ngãi, ngày 22 tháng 10 năm 2025
D15: BGĐ | I15: T/P P.KH
A16: Nơi nhận:
A17: - BGĐ (thay BC);
A18: - Các BP/NM;
A19: - Lưu P.KH (EO).

Sheet PXC 04.10.25 cũ
P1: BM.04D/QT.05 Ngày hiệu lực: 06/06/2025 Lần sửa đổi: 02
B3: Số: 04.10.2025/LSX-XC-NM.HRC1
A4: LỆNH SẢN XUẤT
A5: - Bộ phận thực hiện: XC-NM.HRC1
A6: - Thời gian hiệu lực: Từ 08h00, ngày 16/10/2025 đến 08h00, ngày 23/10/2025
A7: TT | B7: Thời gian dự kiến SX Time/Date | C7: Sản phẩm/Product | M7: Phôi cán/Slab | O7: Yêu cầu đặc biệt | P7: Số Order number | Q7: Số lô/ Batch | R7: KL Cuộn (Tấn) | S7: Mục đích sử dụng | T7: KHÁCH HÀNG | V7: Khối lượng cuộn trung bình | W7: Số lượng cuộn yêu cầu | X7: Số cuộn tối thiểu | Y7: Số cuộn tối đa | AJ7: Số Order number tháng 9 | AK7: Số lô/ Batch tháng 9
C8: Kích cỡ Dimension T x W (mmxmm) | D8: Mác thép Steel grade | E8: Sản lượng Quantity (tấn) | G8: Sản lượng Quantity (cuộn) | I8: Cơ tính/Mechanical properties
E9: 1A | F9: 1B | G9: Yêu cầu | H9: Dung sai | I9: GHC Re (MPa) | J9: GHB Rm (Mpa) | K9: Giãn dài El (%) | L9: Độ cứng Hardnes (HRB) | M9: Mác phôi Steel grade | N9: Kích thước (mmxmm)
A10: =ROW()-9 -> 1 | B10: 08h00 16/10/2025 - 08h00 23/10/2025 | C10: 4.00x126X | D10: SAE1006 | E10: 1000 | F10: 0 | G10: =+W10 -> 44.444444 | H10: =+AH10 -> ±4 | I10: - | J10: - | K10: - | L10: ≤65 | M10: SAE1006-Al | N10: 65x1270 | P10: =+AA10 -> #N/A | Q10: =+AB10 -> #N/A | R10: 18-23 | S10: Tôn- Qua cán nguôi | T10: HOA SEN | U10: QUA CÁN NGUỘI | V10: =RIGHT(R10,2)-0.5 -> 22.5 | W10: =SUM(E10:F10)/V10 -> 44.444444 | X10: =SUM(E10:F10)*0.9/V10 -> 40 | Y10: =SUM(E10:F10)*1.1/V10 -> 48.888889 | Z10: ="Thép cuộn cán nóng "&C10&" "&D10&T10&U10 -> Thép cuộn cán nóng 4.00x126X SAE1006HOA SENQUA CÁN NGUỘI | AA10: =VLOOKUP(Z10,Order!F:H,2,FALSE) -> #N/A | AB10: =VLOOKUP(AA10,Order!G:H,2,FALSE) -> #N/A | AC10: =VLOOKUP(Z10,'ort9'!D:E,2,0) -> #N/A | AD10: =E10+F10 -> 1000 | AE10: =IF(SUM(E10:F10)>2000,((Y10-X10)/2)/2,(Y10-X10)/2) -> 4.4444444 | AF10: ± | AG10: =ROUND(AE10,0) -> 4 | AH10: =AF10&AG10 -> ±4 | AJ10: =VLOOKUP(Z10,'ort9'!H:I,2,0) -> #N/A | AK10: =VLOOKUP(AA10,'ort9'!I:J,2,0) -> #N/A
A11: =ROW()-9 -> 2 | C11: 3.00x126X | D11: SAE1006 | E11: 0 | F11: 1670 | G11: =+W11 -> 77.674419 | H11: =+AH11 -> ±8 | I11: - | J11: - | K11: - | L11: ≤65 | M11: SAE1006-Al | N11: 65x1270 | P11: =+AA11 -> #N/A | Q11: =+AB11 -> #N/A | R11: 17-22 | S11: Tôn-Ống_Qua cán nguội | T11: MINH PHÚ | U11: QUA CÁN NGUỘI | V11: =RIGHT(R11,2)-0.5 -> 21.5 | W11: =SUM(E11:F11)/V11 -> 77.674419 | X11: =SUM(E11:F11)*0.9/V11 -> 69.906977 | Y11: =SUM(E11:F11)*1.1/V11 -> 85.44186 | Z11: ="Thép cuộn cán nóng "&C11&" "&D11&T11&U11 -> Thép cuộn cán nóng 3.00x126X SAE1006MINH PHÚQUA CÁN NGUỘI | AA11: =VLOOKUP(Z11,Order!F:H,2,FALSE) -> #N/A | AB11: =VLOOKUP(AA11,Order!G:H,2,FALSE) -> #N/A | AC11: =VLOOKUP(Z11,'ort9'!D:E,2,0) -> #N/A | AD11: =E11+F11 -> 1670 | AE11: =IF(SUM(E11:F11)>2000,((Y11-X11)/2)/2,(Y11-X11)/2) -> 7.7674419 | AF11: ± | AG11: =ROUND(AE11,0) -> 8 | AH11: =AF11&AG11 -> ±8 | AJ11: =VLOOKUP(Z11,'ort9'!H:I,2,0) -> #N/A | AK11: =VLOOKUP(AA11,'ort9'!I:J,2,0) -> #N/A
A12: =ROW()-9 -> 3 | C12: 3.00x126X | D12: SAE1006 | E12: 500 | F12: 0 | G12: =+W12 -> 25.641026 | H12: =+AH12 -> ±3 | I12: - | J12: - | K12: - | L12: ≤65 | M12: SAE1006-Al | N12: 65x1270 | P12: =+AA12 -> #N/A | Q12: =+AB12 -> #N/A | R12: 17-20 | S12: Tôn-Qua cán nguội | T12: THÉP VIỆT NHẬT | U12: QUA CÁN NGUỘI | V12: =RIGHT(R12,2)-0.5 -> 19.5 | W12: =SUM(E12:F12)/V12 -> 25.641026 | X12: =SUM(E12:F12)*0.9/V12 -> 23.076923 | Y12: =SUM(E12:F12)*1.1/V12 -> 28.205128 | Z12: ="Thép cuộn cán nóng "&C12&" "&D12&T12&U12 -> Thép cuộn cán nóng 3.00x126X SAE1006THÉP VIỆT NHẬTQUA CÁN NGUỘI | AA12: =VLOOKUP(Z12,Order!F:H,2,FALSE) -> #N/A | AB12: =VLOOKUP(AA12,Order!G:H,2,FALSE) -> #N/A | AC12: =VLOOKUP(Z12,'ort9'!D:E,2,0) -> #N/A | AD12: =E12+F12 -> 500 | AE12: =IF(SUM(E12:F12)>2000,((Y12-X12)/2)/2,(Y12-X12)/2) -> 2.5641026 | AF12: ± | AG12: =ROUND(AE12,0) -> 3 | AH12: =AF12&AG12 -> ±3 | AJ12: =VLOOKUP(Z12,'ort9'!H:I,2,0) -> #N/A | AK12: =VLOOKUP(AA12,'ort9'!I:J,2,0) -> #N/A
A13: =ROW()-9 -> 4 | C13: 2.75x126X | D13: SAE1006 | E13: 500 | F13: 0 | G13: =+W13 -> 25.641026 | H13: =+AH13 -> ±3 | I13: - | J13: - | K13: - | L13: ≤65 | M13: SAE1006-Al | N13: 65x1270 | P13: =+AA13 -> #N/A | Q13: =+AB13 -> #N/A | R13: 17-20 | S13: Tôn-Qua cán nguội | T13: THÉP VIỆT NHẬT | U13: QUA CÁN NGUỘI | V13: =RIGHT(R13,2)-0.5 -> 19.5 | W13: =SUM(E13:F13)/V13 -> 25.641026 | X13: =SUM(E13:F13)*0.9/V13 -> 23.076923 | Y13: =SUM(E13:F13)*1.1/V13 -> 28.205128 | Z13: ="Thép cuộn cán nóng "&C13&" "&D13&T13&U13 -> Thép cuộn cán nóng 2.75x126X SAE1006THÉP VIỆT NHẬTQUA CÁN NGUỘI | AA13: =VLOOKUP(Z13,Order!F:H,2,FALSE) -> #N/A | AB13: =VLOOKUP(AA13,Order!G:H,2,FALSE) -> #N/A | AC13: =VLOOKUP(Z13,'ort9'!D:E,2,0) -> #N/A | AD13: =E13+F13 -> 500 | AE13: =IF(SUM(E13:F13)>2000,((Y13-X13)/2)/2,(Y13-X13)/2) -> 2.5641026 | AF13: ± | AG13: =ROUND(AE13,0) -> 3 | AH13: =AF13&AG13 -> ±3 | AJ13: =VLOOKUP(Z13,'ort9'!H:I,2,0) -> #N/A | AK13: =VLOOKUP(AA13,'ort9'!I:J,2,0) -> #N/A
A14: =ROW()-9 -> 5 | C14: 2.50x126X | D14: SAE1006 | E14: 0 | F14: 1760 | G14: =+W14 -> 81.860465 | H14: =+AH14 -> ±8 | I14: - | J14: - | K14: - | L14: ≤65 | M14: SAE1006-Al | N14: 65x1270 | P14: =+AA14 -> #N/A | Q14: =+AB14 -> #N/A | R14: 17-22 | S14: Tôn-Ống_Qua cán nguội | T14: MINH PHÚ | U14: QUA CÁN NGUỘI | V14: =RIGHT(R14,2)-0.5 -> 21.5 | W14: =SUM(E14:F14)/V14 -> 81.860465 | X14: =SUM(E14:F14)*0.9/V14 -> 73.674419 | Y14: =SUM(E14:F14)*1.1/V14 -> 90.046512 | Z14: ="Thép cuộn cán nóng "&C14&" "&D14&T14&U14 -> Thép cuộn cán nóng 2.50x126X SAE1006MINH PHÚQUA CÁN NGUỘI | AA14: =VLOOKUP(Z14,Order!F:H,2,FALSE) -> #N/A | AB14: =VLOOKUP(AA14,Order!G:H,2,FALSE) -> #N/A | AC14: =VLOOKUP(Z14,'ort9'!D:E,2,0) -> #N/A | AD14: =E14+F14 -> 1760 | AE14: =IF(SUM(E14:F14)>2000,((Y14-X14)/2)/2,(Y14-X14)/2) -> 8.1860465 | AF14: ± | AG14: =ROUND(AE14,0) -> 8 | AH14: =AF14&AG14 -> ±8 | AJ14: =VLOOKUP(Z14,'ort9'!H:I,2,0) -> #N/A | AK14: =VLOOKUP(AA14,'ort9'!I:J,2,0) -> #N/A
A15: =ROW()-9 -> 6 | C15: 2.50x126X | D15: SAE1006 | E15: 1000 | F15: 0 | G15: =+W15 -> 51.282051 | H15: =+AH15 -> ±5 | I15: - | J15: - | K15: - | L15: ≤65 | M15: SAE1006-Al | N15: 65x1270 | P15: =+AA15 -> #N/A | Q15: =+AB15 -> #N/A | R15: 17-20 | S15: Tôn-Qua cán nguội | T15: THÉP VIỆT NHẬT | U15: QUA CÁN NGUỘI | V15: =RIGHT(R15,2)-0.5 -> 19.5 | W15: =SUM(E15:F15)/V15 -> 51.282051 | X15: =SUM(E15:F15)*0.9/V15 -> 46.153846 | Y15: =SUM(E15:F15)*1.1/V15 -> 56.410256 | Z15: ="Thép cuộn cán nóng "&C15&" "&D15&T15&U15 -> Thép cuộn cán nóng 2.50x126X SAE1006THÉP VIỆT NHẬTQUA CÁN NGUỘI | AA15: =VLOOKUP(Z15,Order!F:H,2,FALSE) -> #N/A | AB15: =VLOOKUP(AA15,Order!G:H,2,FALSE) -> #N/A | AC15: =VLOOKUP(Z15,'ort9'!D:E,2,0) -> #N/A | AD15: =E15+F15 -> 1000 | AE15: =IF(SUM(E15:F15)>2000,((Y15-X15)/2)/2,(Y15-X15)/2) -> 5.1282051 | AF15: ± | AG15: =ROUND(AE15,0) -> 5 | AH15: =AF15&AG15 -> ±5 | AJ15: =VLOOKUP(Z15,'ort9'!H:I,2,0) -> #N/A | AK15: =VLOOKUP(AA15,'ort9'!I:J,2,0) -> #N/A
A16: =ROW()-9 -> 7 | C16: 2.25x126X | D16: SAE1006 | E16: 0 | F16: 4500 | G16: =+W16 -> 183.67347 | H16: =+AH16 -> ±9 | I16: - | J16: - | K16: - | L16: ≤65 | M16: SAE1006-Al | N16: 65x1270 | P16: =+AA16 -> #N/A | Q16: =+AB16 -> #N/A | R16: 18-25 | S16: Ống-Qua cán nguội | T16: THÉP ASIA | U16: QUA CÁN NGUỘI | V16: =RIGHT(R16,2)-0.5 -> 24.5 | W16: =SUM(E16:F16)/V16 -> 183.67347 | X16: =SUM(E16:F16)*0.9/V16 -> 165.30612 | Y16: =SUM(E16:F16)*1.1/V16 -> 202.04082 | Z16: ="Thép cuộn cán nóng "&C16&" "&D16&T16&U16 -> Thép cuộn cán nóng 2.25x126X SAE1006THÉP ASIAQUA CÁN NGUỘI | AA16: =VLOOKUP(Z16,Order!F:H,2,FALSE) -> #N/A | AB16: =VLOOKUP(AA16,Order!G:H,2,FALSE) -> #N/A | AC16: =VLOOKUP(Z16,'ort9'!D:E,2,0) -> #N/A | AD16: =E16+F16 -> 4500 | AE16: =IF(SUM(E16:F16)>2000,((Y16-X16)/2)/2,(Y16-X16)/2) -> 9.1836735 | AF16: ± | AG16: =ROUND(AE16,0) -> 9 | AH16: =AF16&AG16 -> ±9 | AJ16: =VLOOKUP(Z16,'ort9'!H:I,2,0) -> #N/A | AK16: =VLOOKUP(AA16,'ort9'!I:J,2,0) -> #N/A
A17: =ROW()-9 -> 8 | C17: 4.00x123X | D17: SAE1006 | E17: 500 | F17: 0 | G17: =+W17 -> 22.222222 | H17: =+AH17 -> ±2 | I17: - | J17: - | K17: - | L17: ≤65 | M17: SAE1006-Al | N17: 65x1240 | P17: =+AA17 -> #N/A | Q17: =+AB17 -> #N/A | R17: 18-23 | S17: Tôn- Qua cán nguôi | T17: HOA SEN | U17: QUA CÁN NGUỘI | V17: =RIGHT(R17,2)-0.5 -> 22.5 | W17: =SUM(E17:F17)/V17 -> 22.222222 | X17: =SUM(E17:F17)*0.9/V17 -> 20 | Y17: =SUM(E17:F17)*1.1/V17 -> 24.444444 | Z17: ="Thép cuộn cán nóng "&C17&" "&D17&T17&U17 -> Thép cuộn cán nóng 4.00x123X SAE1006HOA SENQUA CÁN NGUỘI | AA17: =VLOOKUP(Z17,Order!F:H,2,FALSE) -> #N/A | AB17: =VLOOKUP(AA17,Order!G:H,2,FALSE) -> #N/A | AC17: =VLOOKUP(Z17,'ort9'!D:E,2,0) -> #N/A | AD17: =E17+F17 -> 500 | AE17: =IF(SUM(E17:F17)>2000,((Y17-X17)/2)/2,(Y17-X17)/2) -> 2.2222222 | AF17: ± | AG17: =ROUND(AE17,0) -> 2 | AH17: =AF17&AG17 -> ±2 | AJ17: =VLOOKUP(Z17,'ort9'!H:I,2,0) -> #N/A | AK17: =VLOOKUP(AA17,'ort9'!I:J,2,0) -> #N/A
A18: =ROW()-9 -> 9 | C18: 3.45x123X | D18: SAE1006 | E18: 0 | F18: 6000 | G18: =+W18 -> 244.89796 | H18: =+AH18 -> ±12 | I18: - | J18: - | K18: - | L18: ≤65 | M18: SAE1006-Al | N18: 65x1240 | O18: Si=<0.03%; Si+2.5P=<0.085%. | P18: =+AA18 -> #N/A | Q18: =+AB18 -> #N/A | R18: 18-25 | S18: Ống-Qua cán nguội | T18: ỐNG THÉP HƯNG YÊN | U18: QUA CÁN NGUỘI | V18: =RIGHT(R18,2)-0.5 -> 24.5 | W18: =SUM(E18:F18)/V18 -> 244.89796 | X18: =SUM(E18:F18)*0.9/V18 -> 220.40816 | Y18: =SUM(E18:F18)*1.1/V18 -> 269.38776 | Z18: ="Thép cuộn cán nóng "&C18&" "&D18&T18&U18 -> Thép cuộn cán nóng 3.45x123X SAE1006ỐNG THÉP HƯNG YÊNQUA CÁN NGUỘI | AA18: =VLOOKUP(Z18,Order!F:H,2,FALSE) -> #N/A | AB18: =VLOOKUP(AA18,Order!G:H,2,FALSE) -> #N/A | AC18: =VLOOKUP(Z18,'ort9'!D:E,2,0) -> #N/A | AD18: =E18+F18 -> 6000 | AE18: =IF(SUM(E18:F18)>2000,((Y18-X18)/2)/2,(Y18-X18)/2) -> 12.244898 | AF18: ± | AG18: =ROUND(AE18,0) -> 12 | AH18: =AF18&AG18 -> ±12 | AJ18: =VLOOKUP(Z18,'ort9'!H:I,2,0) -> #N/A | AK18: =VLOOKUP(AA18,'ort9'!I:J,2,0) -> #N/A
A19: =ROW()-9 -> 10 | C19: 3.45x123X | D19: SAE1006 | E19: 0 | F19: 800 | G19: =+W19 -> 32.653061 | H19: =+AH19 -> ±3 | I19: - | J19: - | K19: - | L19: ≤65 | M19: SAE1006-Al | N19: 65x1240 | O19: Si=<0.03%; Si+2.5P=<0.085%. | P19: =+AA19 -> #N/A | Q19: =+AB19 -> #N/A | R19: 18-25 | S19: Ống-Qua cán nguội | T19: ỐNG THÉP ĐÀ NẴNG | U19: QUA CÁN NGUỘI | V19: =RIGHT(R19,2)-0.5 -> 24.5 | W19: =SUM(E19:F19)/V19 -> 32.653061 | X19: =SUM(E19:F19)*0.9/V19 -> 29.387755 | Y19: =SUM(E19:F19)*1.1/V19 -> 35.918367 | Z19: ="Thép cuộn cán nóng "&C19&" "&D19&T19&U19 -> Thép cuộn cán nóng 3.45x123X SAE1006ỐNG THÉP ĐÀ NẴNGQUA CÁN NGUỘI | AA19: =VLOOKUP(Z19,Order!F:H,2,FALSE) -> #N/A | AB19: =VLOOKUP(AA19,Order!G:H,2,FALSE) -> #N/A | AC19: =VLOOKUP(Z19,'ort9'!D:E,2,0) -> #N/A | AD19: =E19+F19 -> 800 | AE19: =IF(SUM(E19:F19)>2000,((Y19-X19)/2)/2,(Y19-X19)/2) -> 3.2653061 | AF19: ± | AG19: =ROUND(AE19,0) -> 3 | AH19: =AF19&AG19 -> ±3 | AJ19: =VLOOKUP(Z19,'ort9'!H:I,2,0) -> #N/A | AK19: =VLOOKUP(AA19,'ort9'!I:J,2,0) -> #N/A
A20: =ROW()-9 -> 11 | C20: 3.00x123X | D20: SAE1006 | E20: 0 | F20: 700 | G20: =+W20 -> 29.787234 | H20: =+AH20 -> ±3 | I20: - | J20: - | K20: - | L20: ≤65 | M20: SAE1006-Al | N20: 65x1240 | P20: =+AA20 -> #N/A | Q20: =+AB20 -> #N/A | R20: 18-24 | S20: Tôn-Ống_Qua cán nguội | T20: MINH PHÚ | U20: QUA CÁN NGUỘI | V20: =RIGHT(R20,2)-0.5 -> 23.5 | W20: =SUM(E20:F20)/V20 -> 29.787234 | X20: =SUM(E20:F20)*0.9/V20 -> 26.808511 | Y20: =SUM(E20:F20)*1.1/V20 -> 32.765957 | Z20: ="Thép cuộn cán nóng "&C20&" "&D20&T20&U20 -> Thép cuộn cán nóng 3.00x123X SAE1006MINH PHÚQUA CÁN NGUỘI | AA20: =VLOOKUP(Z20,Order!F:H,2,FALSE) -> #N/A | AB20: =VLOOKUP(AA20,Order!G:H,2,FALSE) -> #N/A | AC20: =VLOOKUP(Z20,'ort9'!D:E,2,0) -> #N/A | AD20: =E20+F20 -> 700 | AE20: =IF(SUM(E20:F20)>2000,((Y20-X20)/2)/2,(Y20-X20)/2) -> 2.9787234 | AF20: ± | AG20: =ROUND(AE20,0) -> 3 | AH20: =AF20&AG20 -> ±3 | AJ20: =VLOOKUP(Z20,'ort9'!H:I,2,0) -> #N/A | AK20: =VLOOKUP(AA20,'ort9'!I:J,2,0) -> #N/A
A21: =ROW()-9 -> 12 | C21: 2.95x123X | D21: SAE1006 | E21: 0 | F21: 2600 | G21: =+W21 -> 106.12245 | H21: =+AH21 -> ±5 | I21: - | J21: - | K21: - | L21: ≤65 | M21: SAE1006-Al | N21: 65x1240 | O21: Si=<0.03%; Si+2.5P=<0.085%. | P21: =+AA21 -> #N/A | Q21: =+AB21 -> #N/A | R21: 18-25 | S21: Ống-Qua cán nguội | T21: ỐNG THÉP ĐÀ NẴNG | U21: QUA CÁN NGUỘI | V21: =RIGHT(R21,2)-0.5 -> 24.5 | W21: =SUM(E21:F21)/V21 -> 106.12245 | X21: =SUM(E21:F21)*0.9/V21 -> 95.510204 | Y21: =SUM(E21:F21)*1.1/V21 -> 116.73469 | Z21: ="Thép cuộn cán nóng "&C21&" "&D21&T21&U21 -> Thép cuộn cán nóng 2.95x123X SAE1006ỐNG THÉP ĐÀ NẴNGQUA CÁN NGUỘI | AA21: =VLOOKUP(Z21,Order!F:H,2,FALSE) -> #N/A | AB21: =VLOOKUP(AA21,Order!G:H,2,FALSE) -> #N/A | AC21: =VLOOKUP(Z21,'ort9'!D:E,2,0) -> #N/A | AD21: =E21+F21 -> 2600 | AE21: =IF(SUM(E21:F21)>2000,((Y21-X21)/2)/2,(Y21-X21)/2) -> 5.3061224 | AF21: ± | AG21: =ROUND(AE21,0) -> 5 | AH21: =AF21&AG21 -> ±5 | AJ21: =VLOOKUP(Z21,'ort9'!H:I,2,0) -> #N/A | AK21: =VLOOKUP(AA21,'ort9'!I:J,2,0) -> #N/A
A22: =ROW()-9 -> 13 | C22: 2.75x123X | D22: SAE1006 | E22: 0 | F22: 380 | G22: =+W22 -> 17.674419 | H22: =+AH22 -> ±2 | I22: - | J22: - | K22: - | L22: ≤65 | M22: SAE1006-Al | N22: 65x1240 | P22: =+AA22 -> #N/A | Q22: =+AB22 -> #N/A | R22: 17-22 | S22: Tôn-Ống_Qua cán nguội | T22: MINH PHÚ | U22: QUA CÁN NGUỘI | V22: =RIGHT(R22,2)-0.5 -> 21.5 | W22: =SUM(E22:F22)/V22 -> 17.674419 | X22: =SUM(E22:F22)*0.9/V22 -> 15.906977 | Y22: =SUM(E22:F22)*1.1/V22 -> 19.44186 | Z22: ="Thép cuộn cán nóng "&C22&" "&D22&T22&U22 -> Thép cuộn cán nóng 2.75x123X SAE1006MINH PHÚQUA CÁN NGUỘI | AA22: =VLOOKUP(Z22,Order!F:H,2,FALSE) -> #N/A | AB22: =VLOOKUP(AA22,Order!G:H,2,FALSE) -> #N/A | AC22: =VLOOKUP(Z22,'ort9'!D:E,2,0) -> #N/A | AD22: =E22+F22 -> 380 | AE22: =IF(SUM(E22:F22)>2000,((Y22-X22)/2)/2,(Y22-X22)/2) -> 1.7674419 | AF22: ± | AG22: =ROUND(AE22,0) -> 2 | AH22: =AF22&AG22 -> ±2 | AJ22: =VLOOKUP(Z22,'ort9'!H:I,2,0) -> #N/A | AK22: =VLOOKUP(AA22,'ort9'!I:J,2,0) -> #N/A
A23: =ROW()-9 -> 14 | C23: 2.75x123X | D23: SAE1006 | E23: 0 | F23: 2000 | G23: =+W23 -> 85.106383 | H23: =+AH23 -> ±9 | I23: - | J23: - | K23: - | L23: ≤65 | M23: SAE1006-Al | N23: 65x1240 | P23: =+AA23 -> #N/A | Q23: =+AB23 -> #N/A | R23: 18-24 | S23: Tôn-Ống_Qua cán nguội | T23: MINH PHÚ | U23: QUA CÁN NGUỘI | V23: =RIGHT(R23,2)-0.5 -> 23.5 | W23: =SUM(E23:F23)/V23 -> 85.106383 | X23: =SUM(E23:F23)*0.9/V23 -> 76.595745 | Y23: =SUM(E23:F23)*1.1/V23 -> 93.617021 | Z23: ="Thép cuộn cán nóng "&C23&" "&D23&T23&U23 -> Thép cuộn cán nóng 2.75x123X SAE1006MINH PHÚQUA CÁN NGUỘI | AA23: =VLOOKUP(Z23,Order!F:H,2,FALSE) -> #N/A | AB23: =VLOOKUP(AA23,Order!G:H,2,FALSE) -> #N/A | AC23: =VLOOKUP(Z23,'ort9'!D:E,2,0) -> #N/A | AD23: =E23+F23 -> 2000 | AE23: =IF(SUM(E23:F23)>2000,((Y23-X23)/2)/2,(Y23-X23)/2) -> 8.5106383 | AF23: ± | AG23: =ROUND(AE23,0) -> 9 | AH23: =AF23&AG23 -> ±9 | AJ23: =VLOOKUP(Z23,'ort9'!H:I,2,0) -> #N/A | AK23: =VLOOKUP(AA23,'ort9'!I:J,2,0) -> #N/A
A24: =ROW()-9 -> 15 | C24: 2.75x123X | D24: SAE1006 | E24: 0 | F24: 2000 | G24: =+W24 -> 81.632653 | H24: =+AH24 -> ±8 | I24: - | J24: - | K24: - | L24: ≤65 | M24: SAE1006-Al | N24: 65x1240 | O24: Si=<0.03%; Si+2.5P=<0.085%. | P24: =+AA24 -> #N/A | Q24: =+AB24 -> #N/A | R24: 18-25 | S24: Ống-Qua cán nguội | T24: ỐNG THÉP ĐÀ NẴNG | U24: QUA CÁN NGUỘI | V24: =RIGHT(R24,2)-0.5 -> 24.5 | W24: =SUM(E24:F24)/V24 -> 81.632653 | X24: =SUM(E24:F24)*0.9/V24 -> 73.469388 | Y24: =SUM(E24:F24)*1.1/V24 -> 89.795918 | Z24: ="Thép cuộn cán nóng "&C24&" "&D24&T24&U24 -> Thép cuộn cán nóng 2.75x123X SAE1006ỐNG THÉP ĐÀ NẴNGQUA CÁN NGUỘI | AA24: =VLOOKUP(Z24,Order!F:H,2,FALSE) -> #N/A | AB24: =VLOOKUP(AA24,Order!G:H,2,FALSE) -> #N/A | AC24: =VLOOKUP(Z24,'ort9'!D:E,2,0) -> #N/A | AD24: =E24+F24 -> 2000 | AE24: =IF(SUM(E24:F24)>2000,((Y24-X24)/2)/2,(Y24-X24)/2) -> 8.1632653 | AF24: ± | AG24: =ROUND(AE24,0) -> 8 | AH24: =AF24&AG24 -> ±8 | AJ24: =VLOOKUP(Z24,'ort9'!H:I,2,0) -> #N/A | AK24: =VLOOKUP(AA24,'ort9'!I:J,2,0) -> #N/A
A25: =ROW()-9 -> 16 | C25: 2.45x123X | D25: SAE1006 | E25: 0 | F25: 2500 | G25: =+W25 -> 106.38298 | H25: =+AH25 -> ±5 | I25: - | J25: - | K25: - | L25: ≤65 | M25: SAE1006-Al | N25: 65x1240 | P25: =+AA25 -> #N/A | Q25: =+AB25 -> #N/A | R25: 18-24 | S25: Tôn-Ống_Qua cán nguội | T25: MINH PHÚ | U25: QUA CÁN NGUỘI | V25: =RIGHT(R25,2)-0.5 -> 23.5 | W25: =SUM(E25:F25)/V25 -> 106.38298 | X25: =SUM(E25:F25)*0.9/V25 -> 95.744681 | Y25: =SUM(E25:F25)*1.1/V25 -> 117.02128 | Z25: ="Thép cuộn cán nóng "&C25&" "&D25&T25&U25 -> Thép cuộn cán nóng 2.45x123X SAE1006MINH PHÚQUA CÁN NGUỘI | AA25: =VLOOKUP(Z25,Order!F:H,2,FALSE) -> #N/A | AB25: =VLOOKUP(AA25,Order!G:H,2,FALSE) -> #N/A | AC25: =VLOOKUP(Z25,'ort9'!D:E,2,0) -> #N/A | AD25: =E25+F25 -> 2500 | AE25: =IF(SUM(E25:F25)>2000,((Y25-X25)/2)/2,(Y25-X25)/2) -> 5.3191489 | AF25: ± | AG25: =ROUND(AE25,0) -> 5 | AH25: =AF25&AG25 -> ±5 | AJ25: =VLOOKUP(Z25,'ort9'!H:I,2,0) -> #N/A | AK25: =VLOOKUP(AA25,'ort9'!I:J,2,0) -> #N/A
A26: =ROW()-9 -> 17 | C26: 2.45x123X | D26: SAE1006 | E26: 0 | F26: 1500 | G26: =+W26 -> 61.22449 | H26: =+AH26 -> ±6 | I26: - | J26: - | K26: - | L26: ≤65 | M26: SAE1006-Al | N26: 65x1240 | O26: Si=<0.03%; Si+2.5P=<0.085%. | P26: =+AA26 -> #N/A | Q26: =+AB26 -> #N/A | R26: 18-25 | S26: Ống-Qua cán nguội | T26: ỐNG THÉP ĐÀ NẴNG | U26: QUA CÁN NGUỘI | V26: =RIGHT(R26,2)-0.5 -> 24.5 | W26: =SUM(E26:F26)/V26 -> 61.22449 | X26: =SUM(E26:F26)*0.9/V26 -> 55.102041 | Y26: =SUM(E26:F26)*1.1/V26 -> 67.346939 | Z26: ="Thép cuộn cán nóng "&C26&" "&D26&T26&U26 -> Thép cuộn cán nóng 2.45x123X SAE1006ỐNG THÉP ĐÀ NẴNGQUA CÁN NGUỘI | AA26: =VLOOKUP(Z26,Order!F:H,2,FALSE) -> #N/A | AB26: =VLOOKUP(AA26,Order!G:H,2,FALSE) -> #N/A | AC26: =VLOOKUP(Z26,'ort9'!D:E,2,0) -> #N/A | AD26: =E26+F26 -> 1500 | AE26: =IF(SUM(E26:F26)>2000,((Y26-X26)/2)/2,(Y26-X26)/2) -> 6.122449 | AF26: ± | AG26: =ROUND(AE26,0) -> 6 | AH26: =AF26&AG26 -> ±6 | AJ26: =VLOOKUP(Z26,'ort9'!H:I,2,0) -> #N/A | AK26: =VLOOKUP(AA26,'ort9'!I:J,2,0) -> #N/A
A27: =ROW()-9 -> 18 | C27: 2.40x123X | D27: SAE1006 | E27: 0 | F27: 800 | G27: =+W27 -> 37.209302 | H27: =+AH27 -> ±4 | I27: - | J27: - | K27: - | L27: ≤65 | M27: SAE1006-Al | N27: 65x1240 | P27: =+AA27 -> #N/A | Q27: =+AB27 -> #N/A | R27: 17-22 | S27: Tôn-Ống_Qua cán nguội | T27: MINH PHÚ | U27: QUA CÁN NGUỘI | V27: =RIGHT(R27,2)-0.5 -> 21.5 | W27: =SUM(E27:F27)/V27 -> 37.209302 | X27: =SUM(E27:F27)*0.9/V27 -> 33.488372 | Y27: =SUM(E27:F27)*1.1/V27 -> 40.930233 | Z27: ="Thép cuộn cán nóng "&C27&" "&D27&T27&U27 -> Thép cuộn cán nóng 2.40x123X SAE1006MINH PHÚQUA CÁN NGUỘI | AA27: =VLOOKUP(Z27,Order!F:H,2,FALSE) -> #N/A | AB27: =VLOOKUP(AA27,Order!G:H,2,FALSE) -> #N/A | AC27: =VLOOKUP(Z27,'ort9'!D:E,2,0) -> #N/A | AD27: =E27+F27 -> 800 | AE27: =IF(SUM(E27:F27)>2000,((Y27-X27)/2)/2,(Y27-X27)/2) -> 3.7209302 | AF27: ± | AG27: =ROUND(AE27,0) -> 4 | AH27: =AF27&AG27 -> ±4 | AJ27: =VLOOKUP(Z27,'ort9'!H:I,2,0) -> #N/A | AK27: =VLOOKUP(AA27,'ort9'!I:J,2,0) -> #N/A
A28: =ROW()-9 -> 19 | C28: 2.35x123X | D28: SAE1006 | E28: 0 | F28: 1000 | G28: =+W28 -> 40.816327 | H28: =+AH28 -> ±4 | I28: - | J28: - | K28: - | L28: ≤65 | M28: SAE1006-Al | N28: 65x1240 | O28: Si=<0.03%; Si+2.5P=<0.085%. | P28: =+AA28 -> #N/A | Q28: =+AB28 -> #N/A | R28: 18-25 | S28: Ống-Qua cán nguội | T28: ỐNG THÉP ĐÀ NẴNG | U28: QUA CÁN NGUỘI | V28: =RIGHT(R28,2)-0.5 -> 24.5 | W28: =SUM(E28:F28)/V28 -> 40.816327 | X28: =SUM(E28:F28)*0.9/V28 -> 36.734694 | Y28: =SUM(E28:F28)*1.1/V28 -> 44.897959 | Z28: ="Thép cuộn cán nóng "&C28&" "&D28&T28&U28 -> Thép cuộn cán nóng 2.35x123X SAE1006ỐNG THÉP ĐÀ NẴNGQUA CÁN NGUỘI | AA28: =VLOOKUP(Z28,Order!F:H,2,FALSE) -> #N/A | AB28: =VLOOKUP(AA28,Order!G:H,2,FALSE) -> #N/A | AC28: =VLOOKUP(Z28,'ort9'!D:E,2,0) -> #N/A | AD28: =E28+F28 -> 1000 | AE28: =IF(SUM(E28:F28)>2000,((Y28-X28)/2)/2,(Y28-X28)/2) -> 4.0816327 | AF28: ± | AG28: =ROUND(AE28,0) -> 4 | AH28: =AF28&AG28 -> ±4 | AJ28: =VLOOKUP(Z28,'ort9'!H:I,2,0) -> #N/A | AK28: =VLOOKUP(AA28,'ort9'!I:J,2,0) -> #N/A
A29: =ROW()-9 -> 20 | C29: 3.00x121X | D29: SAE1006 | E29: 200 | F29: 0 | G29: =+W29 -> 8.5106383 | H29: =+AH29 -> ±1 | I29: - | J29: - | K29: - | L29: ≤65 | M29: SAE1006-Al | N29: 65x1220 | O29: Trung gian hạn chế | P29: =+AA29 -> #N/A | Q29: =+AB29 -> #N/A | R29: 18-24 | S29: Tôn-Qua cán nguội | T29: HOA SEN | U29: QUA CÁN NGUỘI | V29: =RIGHT(R29,2)-0.5 -> 23.5 | W29: =SUM(E29:F29)/V29 -> 8.5106383 | X29: =SUM(E29:F29)*0.9/V29 -> 7.6595745 | Y29: =SUM(E29:F29)*1.1/V29 -> 9.3617021 | Z29: ="Thép cuộn cán nóng "&C29&" "&D29&T29&U29 -> Thép cuộn cán nóng 3.00x121X SAE1006HOA SENQUA CÁN NGUỘI | AA29: =VLOOKUP(Z29,Order!F:H,2,FALSE) -> #N/A | AB29: =VLOOKUP(AA29,Order!G:H,2,FALSE) -> #N/A | AC29: =VLOOKUP(Z29,'ort9'!D:E,2,0) -> #N/A | AD29: =E29+F29 -> 200 | AE29: =IF(SUM(E29:F29)>2000,((Y29-X29)/2)/2,(Y29-X29)/2) -> 0.85106383 | AF29: ± | AG29: =ROUND(AE29,0) -> 1 | AH29: =AF29&AG29 -> ±1 | AJ29: =VLOOKUP(Z29,'ort9'!H:I,2,0) -> #N/A | AK29: =VLOOKUP(AA29,'ort9'!I:J,2,0) -> #N/A
A30: =ROW()-9 -> 21 | C30: 2.75x121Y | D30: SAE1006 | E30: 0 | F30: 1350 | G30: =+W30 -> 57.446809 | H30: =+AH30 -> ±6 | I30: - | J30: - | K30: - | L30: ≤65 | M30: SAE1006-Al | N30: 65x1220 | P30: =+AA30 -> #N/A | Q30: =+AB30 -> #N/A | R30: 18-24 | S30: Tôn-Ống_Qua cán nguội | T30: MINH PHÚ | U30: QUA CÁN NGUỘI | V30: =RIGHT(R30,2)-0.5 -> 23.5 | W30: =SUM(E30:F30)/V30 -> 57.446809 | X30: =SUM(E30:F30)*0.9/V30 -> 51.702128 | Y30: =SUM(E30:F30)*1.1/V30 -> 63.191489 | Z30: ="Thép cuộn cán nóng "&C30&" "&D30&T30&U30 -> Thép cuộn cán nóng 2.75x121Y SAE1006MINH PHÚQUA CÁN NGUỘI | AA30: =VLOOKUP(Z30,Order!F:H,2,FALSE) -> #N/A | AB30: =VLOOKUP(AA30,Order!G:H,2,FALSE) -> #N/A | AC30: =VLOOKUP(Z30,'ort9'!D:E,2,0) -> #N/A | AD30: =E30+F30 -> 1350 | AE30: =IF(SUM(E30:F30)>2000,((Y30-X30)/2)/2,(Y30-X30)/2) -> 5.7446809 | AF30: ± | AG30: =ROUND(AE30,0) -> 6 | AH30: =AF30&AG30 -> ±6 | AJ30: =VLOOKUP(Z30,'ort9'!H:I,2,0) -> #N/A | AK30: =VLOOKUP(AA30,'ort9'!I:J,2,0) -> #N/A
A31: =ROW()-9 -> 22 | C31: 2.75x121Y | D31: SAE1006 | E31: 0 | F31: 8700 | G31: =+W31 -> 370.21277 | H31: =+AH31 -> ±19 | I31: - | J31: - | K31: - | L31: ≤65 | M31: SAE1006-Al | N31: 65x1220 | P31: =+AA31 -> #N/A | Q31: =+AB31 -> #N/A | R31: 18-24 | S31: Ống-Qua cán nguội | T31: ỐNG THÉP MIỀN NAM | U31: QUA CÁN NGUỘI | V31: =RIGHT(R31,2)-0.5 -> 23.5 | W31: =SUM(E31:F31)/V31 -> 370.21277 | X31: =SUM(E31:F31)*0.9/V31 -> 333.19149 | Y31: =SUM(E31:F31)*1.1/V31 -> 407.23404 | Z31: ="Thép cuộn cán nóng "&C31&" "&D31&T31&U31 -> Thép cuộn cán nóng 2.75x121Y SAE1006ỐNG THÉP MIỀN NAMQUA CÁN NGUỘI | AA31: =VLOOKUP(Z31,Order!F:H,2,FALSE) -> #N/A | AB31: =VLOOKUP(AA31,Order!G:H,2,FALSE) -> #N/A | AC31: =VLOOKUP(Z31,'ort9'!D:E,2,0) -> #N/A | AD31: =E31+F31 -> 8700 | AE31: =IF(SUM(E31:F31)>2000,((Y31-X31)/2)/2,(Y31-X31)/2) -> 18.510638 | AF31: ± | AG31: =ROUND(AE31,0) -> 19 | AH31: =AF31&AG31 -> ±19 | AJ31: =VLOOKUP(Z31,'ort9'!H:I,2,0) -> #N/A | AK31: =VLOOKUP(AA31,'ort9'!I:J,2,0) -> #N/A
A32: =ROW()-9 -> 23 | C32: 2.45x121Y | D32: SAE1006 | E32: 0 | F32: 2500 | G32: =+W32 -> 106.38298 | H32: =+AH32 -> ±5 | I32: - | J32: - | K32: - | L32: ≤65 | M32: SAE1006-Al | N32: 65x1220 | P32: =+AA32 -> #N/A | Q32: =+AB32 -> #N/A | R32: 18-24 | S32: Tôn-Ống_Qua cán nguội | T32: MINH PHÚ | U32: QUA CÁN NGUỘI | V32: =RIGHT(R32,2)-0.5 -> 23.5 | W32: =SUM(E32:F32)/V32 -> 106.38298 | X32: =SUM(E32:F32)*0.9/V32 -> 95.744681 | Y32: =SUM(E32:F32)*1.1/V32 -> 117.02128 | Z32: ="Thép cuộn cán nóng "&C32&" "&D32&T32&U32 -> Thép cuộn cán nóng 2.45x121Y SAE1006MINH PHÚQUA CÁN NGUỘI | AA32: =VLOOKUP(Z32,Order!F:H,2,FALSE) -> #N/A | AB32: =VLOOKUP(AA32,Order!G:H,2,FALSE) -> #N/A | AC32: =VLOOKUP(Z32,'ort9'!D:E,2,0) -> #N/A | AD32: =E32+F32 -> 2500 | AE32: =IF(SUM(E32:F32)>2000,((Y32-X32)/2)/2,(Y32-X32)/2) -> 5.3191489 | AF32: ± | AG32: =ROUND(AE32,0) -> 5 | AH32: =AF32&AG32 -> ±5 | AJ32: =VLOOKUP(Z32,'ort9'!H:I,2,0) -> #N/A | AK32: =VLOOKUP(AA32,'ort9'!I:J,2,0) -> #N/A
A33: =ROW()-9 -> 24 | C33: 2.30x121Y | D33: SAE1006 | E33: 1500 | F33: 0 | G33: =+W33 -> 76.923077 | H33: =+AH33 -> ±8 | I33: - | J33: - | K33: - | L33: ≤65 | M33: SAE1006-Al | N33: 65x1220 | O33: Dùng sản xuất tôn màu | P33: =+AA33 -> #N/A | Q33: =+AB33 -> #N/A | R33: 17-20 | S33: Tôn-Qua cán nguội | T33: THÉP VIỆT NHẬT | U33: QUA CÁN NGUỘI | V33: =RIGHT(R33,2)-0.5 -> 19.5 | W33: =SUM(E33:F33)/V33 -> 76.923077 | X33: =SUM(E33:F33)*0.9/V33 -> 69.230769 | Y33: =SUM(E33:F33)*1.1/V33 -> 84.615385 | Z33: ="Thép cuộn cán nóng "&C33&" "&D33&T33&U33 -> Thép cuộn cán nóng 2.30x121Y SAE1006THÉP VIỆT NHẬTQUA CÁN NGUỘI | AA33: =VLOOKUP(Z33,Order!F:H,2,FALSE) -> #N/A | AB33: =VLOOKUP(AA33,Order!G:H,2,FALSE) -> #N/A | AC33: =VLOOKUP(Z33,'ort9'!D:E,2,0) -> #N/A | AD33: =E33+F33 -> 1500 | AE33: =IF(SUM(E33:F33)>2000,((Y33-X33)/2)/2,(Y33-X33)/2) -> 7.6923077 | AF33: ± | AG33: =ROUND(AE33,0) -> 8 | AH33: =AF33&AG33 -> ±8 | AJ33: =VLOOKUP(Z33,'ort9'!H:I,2,0) -> #N/A | AK33: =VLOOKUP(AA33,'ort9'!I:J,2,0) -> #N/A
A34: =ROW()-9 -> 25 | B34: Tổng | E34: =SUM(E10:E33) -> 5200 | F34: =SUM(F10:F33) -> 40760 | G34: =SUM(G11:G28) -> 1311.5019 | AE34: =IF(SUM(E34:F34)>2000,((Y34-X34)/2)/2,(Y34-X34)/2) -> 0 | AF34: ± | AG34: =ROUND(AE34,0) -> 0 | AH34: =AF34&AG34 -> ±0 | AJ34: =VLOOKUP(Z34,'ort9'!H:I,2,TRUE) -> #N/A | AK34: =VLOOKUP(AA34,'ort9'!I:J,2,0) -> #N/A
A35: Ghi chú: - Cho phép cán lại phôi hồi lò đạt TPHH và không có các khuyết tật đúc nghiêm trọng như: ngậm xỉ sâu, nứt ngang, cong vênh ... - Các chỉ tiêu chất lượng khác đánh giá theo TCNB. MẶC ĐỊNH GIÁ TRỊ X=2, Y=7. - Các sản phẩm với mục đích làm Tôn, ống, Ống Gi sản xuất đủ loại I theo LSX. Phân loại chất lượng sản phẩm theo phiếu YCCN số 264.2024 NM.HRC1 / phiếu YCCN số 430.2025/YCCN- P.CN./. - Các sản phẩm với mục đích làm Cut sheet, kết cấu sản xuất đủ loại I theo LSX. Phân loại chất lượng sản phẩm theo phiếu YCCN số 248.2024 NM.HRC1 / phiếu YCCN số 431.2025/YCCN- P.CN./. | AE35: =(5-4)/2 -> 0.5 | AG35: =ROUND(AE35,0) -> 1
N36: Quảng Ngãi, ngày 16 tháng 10 năm 2025
E37: BGĐ | O37: T/P P.KH
A38: Nơi nhận:
A39: - BGĐ (thay BC);
A40: - Các BP/NM;
A41: - Lưu P.KH (EO).

Sheet mvt
A1: Material Description | B1: Quy cách | C1: Ngày hết hạng đăng ký | D1: Material
A2: Thép cuộn cán nóng 3.95x123X SS400 II | B2: 3.95×1232×C | C2: JIS G3101-2017 | D2: 1251121972977
A3: Thép cuộn cán nóng 3.95x123X SS400 | B3: 3.95×1232×C | C3: JIS G3101-2017 | D3: 1251121972960
A4: Thép cuộn cán nóng 3.50x123X SS400 II | B4: 3.50×1232×C | C4: JIS G3101-2017 | D4: 1251121972953
A5: Thép cuộn cán nóng 3.50x123X SS400 | B5: 3.50×1232×C | C5: JIS G3101-2017 | D5: 1251121972946
A6: Thép cuộn cán nóng 5.00x150X ASTM A36 II | B6: 5.00×1502×C | C6: ASTM A36/A36M | D6: 1251121972939
A7: Thép cuộn cán nóng 5.00x150X ASTM A36 | B7: 5.00×1502×C | C7: ASTM A36/A36M | D7: 1251121972922
A8: Thép cuộn cán nóng 2.70x150X SS400 II | B8: 2.70×1502×C | C8: JIS G3101-2017 | D8: 1251121972915
A9: Thép cuộn cán nóng 2.70x150X SS400 | B9: 2.70×1502×C | C9: JIS G3101-2017 | D9: 1251121972908
A10: Thép cuộn cán nóng 2.40x150X SS400 II | B10: 2.40×1502×C | C10: JIS G3101-2017 | D10: 1251121972892
A11: Thép cuộn cán nóng 2.40x150X SS400 | B11: 2.40×1502×C | C11: JIS G3101-2017 | D11: 1251121972885
A12: Thép cuộn cán nóng 2.20x125X SS400 II | B12: 2.20×1252×C | C12: JIS G3101-2017 | D12: 1251121972878
... A8471: Thép cuộn cán nóng 1.95x1197 SAE1006 | B8471: 1.95×1197×C | C8471: SAE J403-2014 | D8471: 1251121440025
A8472: Thép cuộn cán nóng | D8472: 1259999999995
A8473: Thép cuộn cán nóng 3.45x1200 SAE1006 II | B8473: 3.45×1200×C | C8473: SAE J403-2014 | D8473: 1251121470701
A8474: Thép cuộn cán nóng 3.45x1200 SAE1006 | B8474: 3.45×1200×C | C8474: SAE J403-2014 | D8474: 1251121470695
A8475: Thép cuộn cán nóng 2.45x1214 SS400 II | B8475: 2.45×1214×C | C8475: JIS G3101-2017 | D8475: 1251121470473
A8476: Thép cuộn cán nóng 2.45x1214 SS400 | B8476: 2.45×1214×C | C8476: JIS G3101-2017 | D8476: 1251121470466
A8477: Thép cuộn cán nóng 2.25x1214 SS400 II | B8477: 2.25×1214×C | C8477: JIS G3101-2017 | D8477: 1251121470459
A8478: Thép cuộn cán nóng 2.25x1214 SS400 | B8478: 2.25×1214×C | C8478: JIS G3101-2017 | D8478: 1251121470442
A8479: Thép cuộn cán nóng 5.30x1214 SS400 II | B8479: 5.30×1214×C | C8479: JIS G3101-2017 | D8479: 1251121470435
A8480: Thép cuộn cán nóng 5.30x1214 SS400 | B8480: 5.30×1214×C | C8480: JIS G3101-2017 | D8480: 1251121470428
A8481: Thép cuộn cán nóng 4.90x1214 SS400 II | B8481: 4.90×1214×C | C8481: JIS G3101-2017 | D8481: 1251121470411
A8482: Thép cuộn cán nóng 4.90x1214 SS400 | B8482: 4.90×1214×C | C8482: JIS G3101-2017 | D8482: 1251121470404
A8483: Thép cuộn cán nóng 4.60x1214 SS400 II | B8483: 4.60×1214×C | C8483: JIS G3101-2017 | D8483: 1251121470398
A8484: Thép cuộn cán nóng 4.60x1214 SS400 | B8484: 4.60×1214×C | C8484: JIS G3101-2017 | D8484: 1251121470381
... A9067: Thép cuộn cán nóng 1.5x1250mm SAE1006 | B9067: 1.5×1250×C | C9067: TCCS | D9067: 1251120490489
A9068: Thép cuộn cán nóng 1.8x1100mm SPHC, II | C9068: TCCS | D9068: 1251120490250
A9069: Thép cuộn cán nóng 1.8x1300mm SPHC, II | C9069: TCCS | D9069: 1251120490243
A9070: Thép cuộn cán nóng 2.0x1300mm SPHC, II | C9070: TCCS | D9070: 1251120490236
A9071: Thép cuộn cán nóng 2.2x1300mm SPHC, II | C9071: TCCS | D9071: 1251120490229
A9072: Thép cuộn cán nóng 1.8x1250mm SPHC, II | C9072: TCCS | D9072: 1251120490212
A9073: Thép cuộn cán nóng 2.0x1250mm SPHC, II | C9073: TCCS | D9073: 1251120490205
A9074: Thép cuộn cán nóng 2.2x1250mm SPHC, II | C9074: TCCS | D9074: 1251120490199
A9075: Thép cuộn cán nóng 2.4x1250mm SPHC, II | C9075: TCCS | D9075: 1251120490182
A9076: Thép cuộn cán nóng 2.6x1250mm SPHC, II | C9076: TCCS | D9076: 1251120490175
A9077: Thép cuộn cán nóng 3.0x1250mm SPHC, II | C9077: TCCS | D9077: 1251120490168
A9078: Thép cuộn cán nóng 2.0x1100mm SS400, II | C9078: TCCS | D9078: 1251120490151
A9079: Thép cuộn cán nóng 2.2x1100mm SS400, II | C9079: TCCS | D9079: 1251120490144
... A9111: [D]Thép cuộn cán nóng 5.0x1250mm SS400 | C9111: TCCS | D9111: 1251120489827
...

Sheet Theo dõi thực tế
U1: BM.04D/QT.05 Ngày hiệu lực: 06/06/2025 Lần sửa đổi: 02
B3: Số: 02.06.2025/LSX-PXC-NM.HRC1
A4: LỆNH SẢN XUẤT
A5: - Bộ phận thực hiện: PXC-NM.HRC1
A6: - Thời gian hiệu lực: Từ 08h00, ngày 05/06/2025 đến 08h00, ngày 12/06/2025
A7: TT | B7: Thời gian dự kiến SX Time/Date | C7: Sản phẩm/Product | R7: Phôi cán/Slab | T7: Yêu cầu đặc biệt | U7: Số Order number | V7: Số lô/ Batch | W7: KL Cuộn (Tấn) | X7: Mục đích sử dụng | Z7: Khối lượng cuộn trung bình | AA7: Số lượng cuộn yêu cầu | AB7: Số cuộn tối thiểu | AC7: Số cuộn tối đa
C8: Kích cỡ Dimension T x W (mmxmm) | D8: Mác thép Steel grade | E8: Sản lượng Quantity (tấn) | G8: Sản lượng Quantity (cuộn) | I8: Sản lượng thực tế Quantity (tấn) | J8: Sản lượng thực tế Quantity (cuộn) | K8: Chênh lệch (tấn) | L8: Chênh lệch (cuộn) | M8: Đánh giá | N8: Cơ tính/Mechanical properties
E9: 1A | F9: 1B | G9: Yêu cầu | H9: Dung sai | I9: 1A | J9: Yêu cầu | N9: GHC Re (MPa) | O9: GHB Rm (Mpa) | P9: Giãn dài El (%) | Q9: Độ cứng Hardnes (HRB) | R9: Mác phôi Steel grade | S9: Kích thước (mmxmm)
A10: =ROW()-9 -> 1 | B10: 08h00 05/06/2025 - 08h00 07/06/2025 | C10: 2.75x132Y | D10: SAE1006 | E10: 50 | F10: 0 | G10: =+AA10 -> 2.1276596 | H10: ±0 | I10: 1106 | J10: 48 | K10: =I10-E10 -> 1056 | L10: =+J10-G10 -> 45.87234 | M10: Đạt | N10: - | O10: - | P10: - | Q10: ≤65 | R10: SAE1006-Al | S10: 85x1330 | T10: Mục tiêu <62HRB, đang khiếu nại rạn nứt khi uốn - Trung gian (hạn chế) | U10: =+AF10 -> #N/A | V10: =+AG10 -> #N/A | W10: 20-24 | X10: Tôn-Qua cán nguội | Z10: =RIGHT(W10,2)-0.5 -> 23.5 | AA10: =SUM(E10:F10)/Z10 -> 2.1276596 | AB10: =SUM(E10:F10)*0.9/Z10 -> 1.9148936 | AC10: =SUM(E10:F10)*1.1/Z10 -> 2.3404255 | AD10: ="Thép cuộn cán nóng "&C10&" "&D10 -> Thép cuộn cán nóng 2.75x132Y SAE1006 | AE10: =VLOOKUP(AD10,mvt!A:D,4,0) -> 1251121969953 | AF10: =VLOOKUP('Theo dõi thực tế'!AD10,'ort9'!A:B,2,0) -> #N/A | AG10: =VLOOKUP(AD10,'ort9'!D:E,2,0) -> #N/A | AI10: =(AC10-AB10)/2 -> 0.21276596 | AJ10: ± | AK10: =ROUND(AI10,0) -> 0 | AL10: =AJ10&AK10 -> ±0
A11: =ROW()-9 -> 2 | C11: 2.50x132Y | D11: SAE1006 | E11: 1000 | F11: 0 | G11: =+AA11 -> 42.553191 | H11: ±4 | I11: 1083 | J11: 47 | K11: =I11-E11 -> 83 | L11: =+J11-G11 -> 4.4468085 | M11: Đạt | N11: - | O11: - | P11: - | Q11: ≤65 | R11: SAE1006-Al | S11: 85x1330 | T11: Mục tiêu <62HRB, đang khiếu nại rạn nứt khi uốn | U11: =+AF11 -> #N/A | V11: =+AG11 -> #N/A | W11: 20-24 | X11: Tôn-Qua cán nguội | Z11: =RIGHT(W11,2)-0.5 -> 23.5 | AA11: =SUM(E11:F11)/Z11 -> 42.553191 | AB11: =SUM(E11:F11)*0.9/Z11 -> 38.297872 | AC11: =SUM(E11:F11)*1.1/Z11 -> 46.808511 | AD11: ="Thép cuộn cán nóng "&C11&" "&D11 -> Thép cuộn cán nóng 2.50x132Y SAE1006 | AE11: =VLOOKUP(AD11,mvt!A:D,4,0) -> 1251121969939 | AF11: =VLOOKUP('Theo dõi thực tế'!AD11,'ort9'!A:B,2,0) -> #N/A | AG11: =VLOOKUP(AD11,'ort9'!D:E,2,0) -> #N/A | AI11: =(AC11-AB11)/2 -> 4.2553191 | AJ11: ± | AK11: =ROUND(AI11,0) -> 4 | AL11: =AJ11&AK11 -> ±4
A12: =ROW()-9 -> 3 | C12: 4.00x126X | D12: SAE1006 | E12: 500 | F12: 0 | G12: =+AA12 -> 22.222222 | H12: ±2 | N12: - | O12: - | P12: - | Q12: ≤65 | R12: SAE1006-Al | S12: 85x1270 | T12: Chú ý rỗ xước bề mặt | U12: =+AF12 -> #N/A | V12: =+AG12 -> #N/A | W12: 18-23 | X12: Tôn-Qua cán nguội | Z12: =RIGHT(W12,2)-0.5 -> 22.5 | AA12: =SUM(E12:F12)/Z12 -> 22.222222 | AB12: =SUM(E12:F12)*0.9/Z12 -> 20 | AC12: =SUM(E12:F12)*1.1/Z12 -> 24.444444 | AD12: ="Thép cuộn cán nóng "&C12&" "&D12 -> Thép cuộn cán nóng 4.00x126X SAE1006 | AE12: =VLOOKUP(AD12,mvt!A:D,4,0) -> 1251121920305 | AF12: =VLOOKUP('Theo dõi thực tế'!AD12,'ort9'!A:B,2,0) -> #N/A | AG12: =VLOOKUP(AD12,'ort9'!D:E,2,0) -> #N/A | AI12: =(AC12-AB12)/2 -> 2.2222222 | AJ12: ± | AK12: =ROUND(AI12,0) -> 2 | AL12: =AJ12&AK12 -> ±2
A13: =ROW()-9 -> 4 | C13: 3.80x126X | D13: SAE1006 | E13: 500 | F13: 0 | G13: =+AA13 -> 22.222222 | H13: ±2 | N13: - | O13: - | P13: - | Q13: ≤65 | R13: SAE1006-Al | S13: 85x1270 | T13: Chú ý rỗ xước bề mặt | U13: =+AF13 -> #N/A | V13: =+AG13 -> #N/A | W13: 18-23 | X13: Tôn-Qua cán nguội | Z13: =RIGHT(W13,2)-0.5 -> 22.5 | AA13: =SUM(E13:F13)/Z13 -> 22.222222 | AB13: =SUM(E13:F13)*0.9/Z13 -> 20 | AC13: =SUM(E13:F13)*1.1/Z13 -> 24.444444 | AD13: ="Thép cuộn cán nóng "&C13&" "&D13 -> Thép cuộn cán nóng 3.80x126X SAE1006 | AE13: =VLOOKUP(AD13,mvt!A:D,4,0) -> 1251121920961 | AF13: =VLOOKUP('Theo dõi thực tế'!AD13,'ort9'!A:B,2,0) -> #N/A | AG13: =VLOOKUP(AD13,'ort9'!D:E,2,0) -> #N/A | AI13: =(AC13-AB13)/2 -> 2.2222222 | AJ13: ± | AK13: =ROUND(AI13,0) -> 2 | AL13: =AJ13&AK13 -> ±2
A14: =ROW()-9 -> 5 | C14: 3.20x126X | D14: SAE1006 | E14: 2000 | F14: 0 | G14: =+AA14 -> 88.888889 | H14: ±9 | N14: - | O14: - | P14: - | Q14: ≤65 | R14: SAE1006-Al | S14: 85x1270 | T14: Chú ý rỗ xước bề mặt | U14: =+AF14 -> #N/A | V14: =+AG14 -> #N/A | W14: 18-23 | X14: Tôn-Qua cán nguội | Z14: =RIGHT(W14,2)-0.5 -> 22.5 | AA14: =SUM(E14:F14)/Z14 -> 88.888889 | AB14: =SUM(E14:F14)*0.9/Z14 -> 80 | AC14: =SUM(E14:F14)*1.1/Z14 -> 97.777778 | AD14: ="Thép cuộn cán nóng "&C14&" "&D14 -> Thép cuộn cán nóng 3.20x126X SAE1006 | AE14: =VLOOKUP(AD14,mvt!A:D,4,0) -> 1251121919538 | AF14: =VLOOKUP('Theo dõi thực tế'!AD14,'ort9'!A:B,2,0) -> #N/A | AG14: =VLOOKUP(AD14,'ort9'!D:E,2,0) -> #N/A | AI14: =(AC14-AB14)/2 -> 8.8888889 | AJ14: ± | AK14: =ROUND(AI14,0) -> 9 | AL14: =AJ14&AK14 -> ±9
A15: =ROW()-9 -> 6 | C15: 3.00x126X | D15: SAE1006 | E15: 150 | F15: 0 | G15: =+AA15 -> 6.3829787 | H15: ±1 | N15: - | O15: - | P15: - | Q15: ≤65 | R15: SAE1006-Al | S15: 85x1270 | U15: =+AF15 -> #N/A | V15: =+AG15 -> #N/A | W15: 18-24 | X15: Tôn-Qua cán nguội | Z15: =RIGHT(W15,2)-0.5 -> 23.5 | AA15: =SUM(E15:F15)/Z15 -> 6.3829787 | AB15: =SUM(E15:F15)*0.9/Z15 -> 5.7446809 | AC15: =SUM(E15:F15)*1.1/Z15 -> 7.0212766 | AD15: ="Thép cuộn cán nóng "&C15&" "&D15 -> Thép cuộn cán nóng 3.00x126X SAE1006 | AE15: =VLOOKUP(AD15,mvt!A:D,4,0) -> 1251121915400 | AF15: =VLOOKUP('Theo dõi thực tế'!AD15,'ort9'!A:B,2,0) -> #N/A | AG15: =VLOOKUP(AD15,'ort9'!D:E,2,0) -> #N/A | AI15: =(AC15-AB15)/2 -> 0.63829787 | AJ15: ± | AK15: =ROUND(AI15,0) -> 1 | AL15: =AJ15&AK15 -> ±1
A16: =ROW()-9 -> 7 | C16: 2.80x126X | D16: SAE1006 | E16: 1000 | F16: 0 | G16: =+AA16 -> 44.444444 | H16: ±4 | N16: - | O16: - | P16: - | Q16: ≤65 | R16: SAE1006-Al | S16: 85x1270 | T16: Chú ý rỗ xước bề mặt | U16: =+AF16 -> #N/A | V16: =+AG16 -> #N/A | W16: 18-23 | X16: Tôn-Qua cán nguội | Z16: =RIGHT(W16,2)-0.5 -> 22.5 | AA16: =SUM(E16:F16)/Z16 -> 44.444444 | AB16: =SUM(E16:F16)*0.9/Z16 -> 40 | AC16: =SUM(E16:F16)*1.1/Z16 -> 48.888889 | AD16: ="Thép cuộn cán nóng "&C16&" "&D16 -> Thép cuộn cán nóng 2.80x126X SAE1006 | AE16: =VLOOKUP(AD16,mvt!A:D,4,0) -> 1251121919552 | AF16: =VLOOKUP('Theo dõi thực tế'!AD16,'ort9'!A:B,2,0) -> #N/A | AG16: =VLOOKUP(AD16,'ort9'!D:E,2,0) -> #N/A | AI16: =(AC16-AB16)/2 -> 4.4444444 | AJ16: ± | AK16: =ROUND(AI16,0) -> 4 | AL16: =AJ16&AK16 -> ±4
A17: =ROW()-9 -> 8 | C17: 2.75x126Y | D17: SAE1006 | E17: 1000 | F17: 0 | G17: =+AA17 -> 42.553191 | H17: ±4 | N17: - | O17: - | P17: - | Q17: ≤65 | R17: SAE1006-Al | S17: 85x1270 | T17: Mục tiêu <62HRB, đang khiếu nại rạn nứt khi uốn | U17: =+AF17 -> #N/A | V17: =+AG17 -> #N/A | W17: 20-24 | X17: Tôn-Qua cán nguội | Z17: =RIGHT(W17,2)-0.5 -> 23.5 | AA17: =SUM(E17:F17)/Z17 -> 42.553191 | AB17: =SUM(E17:F17)*0.9/Z17 -> 38.297872 | AC17: =SUM(E17:F17)*1.1/Z17 -> 46.808511 | AD17: ="Thép cuộn cán nóng "&C17&" "&D17 -> Thép cuộn cán nóng 2.75x126Y SAE1006 | AE17: =VLOOKUP(AD17,mvt!A:D,4,0) -> 1251121961698 | AF17: =VLOOKUP('Theo dõi thực tế'!AD17,'ort9'!A:B,2,0) -> #N/A | AG17: =VLOOKUP(AD17,'ort9'!D:E,2,0) -> #N/A | AI17: =(AC17-AB17)/2 -> 4.2553191 | AJ17: ± | AK17: =ROUND(AI17,0) -> 4 | AL17: =AJ17&AK17 -> ±4
A18: =ROW()-9 -> 9 | C18: 2.50x126X | D18: SAE1006 | E18: 0 | F18: 3560 | G18: =+AA18 -> 165.5814 | H18: ±17 | N18: - | O18: - | P18: - | Q18: ≤65 | R18: SAE1006-Al | S18: 85x1270 | T18: Ưu tiên sx đầu chu kỳ | U18: =+AF18 -> #N/A | V18: =+AG18 -> #N/A | W18: 19-22 | X18: Ống-Qua cán nguội | Z18: =RIGHT(W18,2)-0.5 -> 21.5 | AA18: =SUM(E18:F18)/Z18 -> 165.5814 | AB18: =SUM(E18:F18)*0.9/Z18 -> 149.02326 | AC18: =SUM(E18:F18)*1.1/Z18 -> 182.13953 | AD18: ="Thép cuộn cán nóng "&C18&" "&D18 -> Thép cuộn cán nóng 2.50x126X SAE1006 | AE18: =VLOOKUP(AD18,mvt!A:D,4,0) -> 1251121918340 | AF18: =VLOOKUP('Theo dõi thực tế'!AD18,'ort9'!A:B,2,0) -> #N/A | AG18: =VLOOKUP(AD18,'ort9'!D:E,2,0) -> #N/A | AI18: =(AC18-AB18)/2 -> 16.55814 | AJ18: ± | AK18: =ROUND(AI18,0) -> 17 | AL18: =AJ18&AK18 -> ±17
A19: =ROW()-9 -> 10 | C19: 2.50x126X | D19: SAE1006 | E19: 1000 | F19: 0 | G19: =+AA19 -> 44.444444 | H19: ±4 | N19: - | O19: - | P19: - | Q19: ≤65 | R19: SAE1006-Al | S19: 85x1270 | T19: Chú ý rỗ xước bề mặt | U19: =+AF19 -> #N/A | V19: =+AG19 -> #N/A | W19: 18-23 | X19: Tôn-Qua cán nguội | Z19: =RIGHT(W19,2)-0.5 -> 22.5 | AA19: =SUM(E19:F19)/Z19 -> 44.444444 | AB19: =SUM(E19:F19)*0.9/Z19 -> 40 | AC19: =SUM(E19:F19)*1.1/Z19 -> 48.888889 | AD19: ="Thép cuộn cán nóng "&C19&" "&D19 -> Thép cuộn cán nóng 2.50x126X SAE1006 | AE19: =VLOOKUP(AD19,mvt!A:D,4,0) -> 1251121918340 | AF19: =VLOOKUP('Theo dõi thực tế'!AD19,'ort9'!A:B,2,0) -> #N/A | AG19: =VLOOKUP(AD19,'ort9'!D:E,2,0) -> #N/A | AI19: =(AC19-AB19)/2 -> 4.4444444 | AJ19: ± | AK19: =ROUND(AI19,0) -> 4 | AL19: =AJ19&AK19 -> ±4
A20: =ROW()-9 -> 11 | C20: 2.30x126Y | D20: SAE1006 | E20: 1000 | F20: 0 | G20: =+AA20 -> 42.553191 | H20: ±4 | N20: - | O20: - | P20: - | Q20: ≤65 | R20: SAE1006-Al | S20: 85x1270 | T20: Mục tiêu <62HRB, đang khiếu nại rạn nứt khi uốn | U20: =+AF20 -> #N/A | V20: =+AG20 -> #N/A | W20: 20-24 | X20: Tôn-Qua cán nguội | Z20: =RIGHT(W20,2)-0.5 -> 23.5 | AA20: =SUM(E20:F20)/Z20 -> 42.553191 | AB20: =SUM(E20:F20)*0.9/Z20 -> 38.297872 | AC20: =SUM(E20:F20)*1.1/Z20 -> 46.808511 | AD20: ="Thép cuộn cán nóng "&C20&" "&D20 -> Thép cuộn cán nóng 2.30x126Y SAE1006 | AE20: =VLOOKUP(AD20,mvt!A:D,4,0) -> 1251121915462 | AF20: =VLOOKUP('Theo dõi thực tế'!AD20,'ort9'!A:B,2,0) -> #N/A | AG20: =VLOOKUP(AD20,'ort9'!D:E,2,0) -> #N/A | AI20: =(AC20-AB20)/2 -> 4.2553191 | AJ20: ± | AK20: =ROUND(AI20,0) -> 4 | AL20: =AJ20&AK20 -> ±4
A21: =ROW()-9 -> 12 | C21: 2.30x126X | D21: SAE1006 | E21: 2000 | F21: 0 | G21: =+AA21 -> 88.888889 | H21: ±9 | N21: - | O21: - | P21: - | Q21: ≤65 | R21: SAE1006-Al | S21: 85x1270 | T21: Chú ý rỗ xước bề mặt | U21: =+AF21 -> #N/A | V21: =+AG21 -> #N/A | W21: 18-23 | X21: Tôn-Qua cán nguội | Z21: =RIGHT(W21,2)-0.5 -> 22.5 | AA21: =SUM(E21:F21)/Z21 -> 88.888889 | AB21: =SUM(E21:F21)*0.9/Z21 -> 80 | AC21: =SUM(E21:F21)*1.1/Z21 -> 97.777778 | AD21: ="Thép cuộn cán nóng "&C21&" "&D21 -> Thép cuộn cán nóng 2.30x126X SAE1006 | AE21: =VLOOKUP(AD21,mvt!A:D,4,0) -> 1251121915387 | AF21: =VLOOKUP('Theo dõi thực tế'!AD21,'ort9'!A:B,2,0) -> #N/A | AG21: =VLOOKUP(AD21,'ort9'!D:E,2,0) -> #N/A | AI21: =(AC21-AB21)/2 -> 8.8888889 | AJ21: ± | AK21: =ROUND(AI21,0) -> 9 | AL21: =AJ21&AK21 -> ±9
A22: =ROW()-9 -> 13 | C22: 2.00x126Y | D22: SAE1006 | E22: 1000 | F22: 0 | G22: =+AA22 -> 42.553191 | H22: ±4 | N22: - | O22: - | P22: - | Q22: ≤65 | R22: SAE1006-Al | S22: 85x1270 | T22: Mục tiêu <62HRB, đang khiếu nại rạn nứt khi uốn | U22: =+AF22 -> #N/A | V22: =+AG22 -> #N/A | W22: 20-24 | X22: Tôn-Qua cán nguội | Z22: =RIGHT(W22,2)-0.5 -> 23.5 | AA22: =SUM(E22:F22)/Z22 -> 42.553191 | AB22: =SUM(E22:F22)*0.9/Z22 -> 38.297872 | AC22: =SUM(E22:F22)*1.1/Z22 -> 46.808511 | AD22: ="Thép cuộn cán nóng "&C22&" "&D22 -> Thép cuộn cán nóng 2.00x126Y SAE1006 | AE22: =VLOOKUP(AD22,mvt!A:D,4,0) -> 1251121915721 | AF22: =VLOOKUP('Theo dõi thực tế'!AD22,'ort9'!A:B,2,0) -> #N/A | AG22: =VLOOKUP(AD22,'ort9'!D:E,2,0) -> #N/A | AI22: =(AC22-AB22)/2 -> 4.2553191 | AJ22: ± | AK22: =ROUND(AI22,0) -> 4 | AL22: =AJ22&AK22 -> ±4
A23: =ROW()-9 -> 14 | C23: 2.00x126X | D23: SAE1006 | E23: 1470 | F23: 0 | G23: =+AA23 -> 65.333333 | H23: ±7 | N23: - | O23: - | P23: - | Q23: ≤65 | R23: SAE1006-Al | S23: 85x1270 | T23: Chú ý rỗ xước bề mặt | U23: =+AF23 -> #N/A | V23: =+AG23 -> #N/A | W23: 18-23 | X23: Tôn-Qua cán nguội | Z23: =RIGHT(W23,2)-0.5 -> 22.5 | AA23: =SUM(E23:F23)/Z23 -> 65.333333 | AB23: =SUM(E23:F23)*0.9/Z23 -> 58.8 | AC23: =SUM(E23:F23)*1.1/Z23 -> 71.866667 | AD23: ="Thép cuộn cán nóng "&C23&" "&D23 -> Thép cuộn cán nóng 2.00x126X SAE1006 | AE23: =VLOOKUP(AD23,mvt!A:D,4,0) -> 1251121919057 | AF23: =VLOOKUP('Theo dõi thực tế'!AD23,'ort9'!A:B,2,0) -> #N/A | AG23: =VLOOKUP(AD23,'ort9'!D:E,2,0) -> #N/A | AI23: =(AC23-AB23)/2 -> 6.5333333 | AJ23: ± | AK23: =ROUND(AI23,0) -> 7 | AL23: =AJ23&AK23 -> ±7
A24: =ROW()-9 -> 15 | C24: 2.00x126X | D24: SAE1006 | E24: 530 | F24: 0 | G24: =+AA24 -> 23.555556 | H24: ±2 | N24: - | O24: - | P24: - | Q24: ≤65 | R24: SAE1006-Al | S24: 85x1270 | T24: Chú ý rỗ xước bề mặt, Skin | U24: =+AF24 -> #N/A | V24: =+AG24 -> #N/A | W24: 18-23 | X24: Tôn-Qua cán nguội | Z24: =RIGHT(W24,2)-0.5 -> 22.5 | AA24: =SUM(E24:F24)/Z24 -> 23.555556 | AB24: =SUM(E24:F24)*0.9/Z24 -> 21.2 | AC24: =SUM(E24:F24)*1.1/Z24 -> 25.911111 | AD24: ="Thép cuộn cán nóng "&C24&" "&D24 -> Thép cuộn cán nóng 2.00x126X SAE1006 | AE24: =VLOOKUP(AD24,mvt!A:D,4,0) -> 1251121919057 | AF24: =VLOOKUP('Theo dõi thực tế'!AD24,'ort9'!A:B,2,0) -> #N/A | AG24: =VLOOKUP(AD24,'ort9'!D:E,2,0) -> #N/A | AI24: =(AC24-AB24)/2 -> 2.3555556 | AJ24: ± | AK24: =ROUND(AI24,0) -> 2 | AL24: =AJ24&AK24 -> ±2
A25: =ROW()-9 -> 16 | B25: 08h00 07/06/2025 - 08h00 12/06/2025 | C25: 2.75x125X | D25: SAE1006 | E25: 0 | F25: 50 | G25: =+AA25 -> 2.0408163 | H25: ±0 | N25: - | O25: - | P25: - | Q25: ≤65 | R25: SAE1006-Al | S25: 85x1260 | T25: Trung gian (hạn chế) | U25: =+AF25 -> #N/A | V25: =+AG25 -> #N/A | W25: 21-25 | X25: Ống-Qua cán nguội | Z25: =RIGHT(W25,2)-0.5 -> 24.5 | AA25: =SUM(E25:F25)/Z25 -> 2.0408163 | AB25: =SUM(E25:F25)*0.9/Z25 -> 1.8367347 | AC25: =SUM(E25:F25)*1.1/Z25 -> 2.244898 | AD25: ="Thép cuộn cán nóng "&C25&" "&D25 -> Thép cuộn cán nóng 2.75x125X SAE1006 | AE25: =VLOOKUP(AD25,mvt!A:D,4,0) -> 1251121928226 | AF25: =VLOOKUP('Theo dõi thực tế'!AD25,'ort9'!A:B,2,0) -> #N/A | AG25: =VLOOKUP(AD25,'ort9'!D:E,2,0) -> #N/A | AI25: =(AC25-AB25)/2 -> 0.20408163 | AJ25: ± | AK25: =ROUND(AI25,0) -> 0 | AL25: =AJ25&AK25 -> ±0
A26: =ROW()-9 -> 17 | C26: 2.50x125X | D26: SAE1006 | E26: 0 | F26: 1000 | G26: =+AA26 -> 40.816327 | H26: ±4 | N26: - | O26: - | P26: - | Q26: ≤65 | R26: SAE1006-Al | S26: 85x1260 | U26: =+AF26 -> #N/A | V26: =+AG26 -> #N/A | W26: 21-25 | X26: Ống-Qua cán nguội | Z26: =RIGHT(W26,2)-0.5 -> 24.5 | AA26: =SUM(E26:F26)/Z26 -> 40.816327 | AB26: =SUM(E26:F26)*0.9/Z26 -> 36.734694 | AC26: =SUM(E26:F26)*1.1/Z26 -> 44.897959 | AD26: ="Thép cuộn cán nóng "&C26&" "&D26 -> Thép cuộn cán nóng 2.50x125X SAE1006 | AE26: =VLOOKUP(AD26,mvt!A:D,4,0) -> 1251121918005 | AF26: =VLOOKUP('Theo dõi thực tế'!AD26,'ort9'!A:B,2,0) -> #N/A | AG26: =VLOOKUP(AD26,'ort9'!D:E,2,0) -> #N/A | AI26: =(AC26-AB26)/2 -> 4.0816327 | AJ26: ± | AK26: =ROUND(AI26,0) -> 4 | AL26: =AJ26&AK26 -> ±4
A27: =ROW()-9 -> 18 | C27: 2.30x125X | D27: SAE1006 | E27: 0 | F27: 1000 | G27: =+AA27 -> 40.816327 | H27: ±4 | N27: - | O27: - | P27: - | Q27: ≤65 | R27: SAE1006-Al | S27: 85x1260 | U27: =+AF27 -> #N/A | V27: =+AG27 -> #N/A | W27: 21-25 | X27: Ống-Qua cán nguội | Z27: =RIGHT(W27,2)-0.5 -> 24.5 | AA27: =SUM(E27:F27)/Z27 -> 40.816327 | AB27: =SUM(E27:F27)*0.9/Z27 -> 36.734694 | AC27: =SUM(E27:F27)*1.1/Z27 -> 44.897959 | AD27: ="Thép cuộn cán nóng "&C27&" "&D27 -> Thép cuộn cán nóng 2.30x125X SAE1006 | AE27: =VLOOKUP(AD27,mvt!A:D,4,0) -> 1251121917985 | AF27: =VLOOKUP('Theo dõi thực tế'!AD27,'ort9'!A:B,2,0) -> #N/A | AG27: =VLOOKUP(AD27,'ort9'!D:E,2,0) -> #N/A | AI27: =(AC27-AB27)/2 -> 4.0816327 | AJ27: ± | AK27: =ROUND(AI27,0) -> 4 | AL27: =AJ27&AK27 -> ±4
A28: =ROW()-9 -> 19 | C28: 2.00x125X | D28: SAE1006 | E28: 0 | F28: 2000 | G28: =+AA28 -> 81.632653 | H28: ±8 | N28: - | O28: - | P28: - | Q28: ≤65 | R28: SAE1006-Al | S28: 85x1260 | U28: =+AF28 -> #N/A | V28: =+AG28 -> #N/A | W28: 21-25 | X28: Ống-Qua cán nguội | Z28: =RIGHT(W28,2)-0.5 -> 24.5 | AA28: =SUM(E28:F28)/Z28 -> 81.632653 | AB28: =SUM(E28:F28)*0.9/Z28 -> 73.469388 | AC28: =SUM(E28:F28)*1.1/Z28 -> 89.795918 | AD28: ="Thép cuộn cán nóng "&C28&" "&D28 -> Thép cuộn cán nóng 2.00x125X SAE1006 | AE28: =VLOOKUP(AD28,mvt!A:D,4,0) -> 1251121917961 | AF28: =VLOOKUP('Theo dõi thực tế'!AD28,'ort9'!A:B,2,0) -> #N/A | AG28: =VLOOKUP(AD28,'ort9'!D:E,2,0) -> #N/A | AI28: =(AC28-AB28)/2 -> 8.1632653 | AJ28: ± | AK28: =ROUND(AI28,0) -> 8 | AL28: =AJ28&AK28 -> ±8
A29: =ROW()-9 -> 20 | C29: 3.95x123X | D29: SAE1006 | E29: 200 | F29: 0 | G29: =+AA29 -> 8.8888889 | H29: ±1 | N29: - | O29: - | P29: - | Q29: ≤65 | R29: SAE1006-Al | S29: 85x1240 | U29: =+AF29 -> #N/A | V29: =+AG29 -> #N/A | W29: ≤23 | X29: Tôn-Qua cán nguội | Z29: =RIGHT(W29,2)-0.5 -> 22.5 | AA29: =SUM(E29:F29)/Z29 -> 8.8888889 | AB29: =SUM(E29:F29)*0.9/Z29 -> 8 | AC29: =SUM(E29:F29)*1.1/Z29 -> 9.7777778 | AD29: ="Thép cuộn cán nóng "&C29&" "&D29 -> Thép cuộn cán nóng 3.95x123X SAE1006 | AE29: =VLOOKUP(AD29,mvt!A:D,4,0) -> 1251121938942 | AF29: =VLOOKUP('Theo dõi thực tế'!AD29,'ort9'!A:B,2,0) -> #N/A | AG29: =VLOOKUP(AD29,'ort9'!D:E,2,0) -> #N/A | AI29: =(AC29-AB29)/2 -> 0.88888889 | AJ29: ± | AK29: =ROUND(AI29,0) -> 1 | AL29: =AJ29&AK29 -> ±1
A30: =ROW()-9 -> 21 | C30: 3.95x123X | D30: SAE1006 | E30: 200 | F30: 0 | G30: =+AA30 -> 57.142857 | H30: ±6 | N30: - | O30: - | P30: - | Q30: ≤65 | R30: SAE1006-Al | S30: 85x1240 | U30: =+AF30 -> #N/A | V30: =+AG30 -> #N/A | W30: 18-24 | X30: Tôn-Qua cán nguội | Z30: =RIGHT(W30,2)-0.5 -> 3.5 | AA30: =SUM(E30:F30)/Z30 -> 57.142857 | AB30: =SUM(E30:F30)*0.9/Z30 -> 51.428571 | AC30: =SUM(E30:F30)*1.1/Z30 -> 62.857143 | AD30: ="Thép cuộn cán nóng "&C30&" "&D30 -> Thép cuộn cán nóng 3.95x123X SAE1006 | AE30: =VLOOKUP(AD30,mvt!A:D,4,0) -> 1251121938942 | AF30: =VLOOKUP('Theo dõi thực tế'!AD30,'ort9'!A:B,2,0) -> #N/A | AG30: =VLOOKUP(AD30,'ort9'!D:E,2,0) -> #N/A | AI30: =(AC30-AB30)/2 -> 5.7142857 | AJ30: ± | AK30: =ROUND(AI30,0) -> 6 | AL30: =AJ30&AK30 -> ±6
A31: =ROW()-9 -> 22 | C31: 2.50x123X | D31: SAE1006 | E31: 0 | F31: 5900 | G31: =+AA31 -> 274.4186 | H31: ±27 | N31: - | O31: - | P31: - | Q31: ≤65 | R31: SAE1006-Al | S31: 85x1240 | U31: =+AF31 -> #N/A | V31: =+AG31 -> #N/A | W31: 19-22 | X31: Ống-Qua cán nguội | Z31: =RIGHT(W31,2)-0.5 -> 21.5 | AA31: =SUM(E31:F31)/Z31 -> 274.4186 | AB31: =SUM(E31:F31)*0.9/Z31 -> 246.97674 | AC31: =SUM(E31:F31)*1.1/Z31 -> 301.86047 | AD31: ="Thép cuộn cán nóng "&C31&" "&D31 -> Thép cuộn cán nóng 2.50x123X SAE1006 | AE31: =VLOOKUP(AD31,mvt!A:D,4,0) -> 1251121918081 | AF31: =VLOOKUP('Theo dõi thực tế'!AD31,'ort9'!A:B,2,0) -> #N/A | AG31: =VLOOKUP(AD31,'ort9'!D:E,2,0) -> #N/A | AI31: =(AC31-AB31)/2 -> 27.44186 | AJ31: ± | AK31: =ROUND(AI31,0) -> 27 | AL31: =AJ31&AK31 -> ±27
C32: 2.30x123X | D32: SAE1006 | E32: 50 | F32: 0 | G32: =+AA32 -> 2.2222222 | H32: ±0 | N32: - | O32: - | P32: - | Q32: ≤65 | R32: SAE1006-Al | S32: 85x1240 | T32: Trung gian (hạn chế) | U32: =+AF32 -> #N/A | V32: =+AG32 -> #N/A | W32: 18-23 | X32: Tôn-Qua cán nguội | Z32: =RIGHT(W32,2)-0.5 -> 22.5 | AA32: =SUM(E32:F32)/Z32 -> 2.2222222 | AB32: =SUM(E32:F32)*0.9/Z32 -> 2 | AC32: =SUM(E32:F32)*1.1/Z32 -> 2.4444444 | AD32: ="Thép cuộn cán nóng "&C32&" "&D32 -> Thép cuộn cán nóng 2.30x123X SAE1006 | AE32: =VLOOKUP(AD32,mvt!A:D,4,0) -> 1251121917640 | AF32: =VLOOKUP('Theo dõi thực tế'!AD32,'ort9'!A:B,2,0) -> #N/A | AG32: =VLOOKUP(AD32,'ort9'!D:E,2,0) -> #N/A | AI32: =(AC32-AB32)/2 -> 0.22222222 | AJ32: ± | AK32: =ROUND(AI32,0) -> 0 | AL32: =AJ32&AK32 -> ±0
A33: =ROW()-9 -> 24 | C33: 2.00x123X | D33: SAE1006 | E33: 715 | F33: 0 | G33: =+AA33 -> 31.086957 | H33: ±3 | N33: - | O33: - | P33: - | Q33: ≤65 | R33: SAE1006-Al | S33: 85x1240 | T33: Chú ý rỗ xước bề mặt | U33: =+AF33 -> #N/A | V33: =+AG33 -> #N/A | W33: 18-23 | X33: Tôn-Qua cán nguội | Z33: =RIGHT(W33,2) -> 23 | AA33: =SUM(E33:F33)/Z33 -> 31.086957 | AB33: =SUM(E33:F33)*0.9/Z33 -> 27.978261 | AC33: =SUM(E33:F33)*1.1/Z33 -> 34.195652 | AD33: ="Thép cuộn cán nóng "&C33&" "&D33 -> Thép cuộn cán nóng 2.00x123X SAE1006 | AE33: =VLOOKUP(AD33,mvt!A:D,4,0) -> 1251121917749 | AF33: =VLOOKUP('Theo dõi thực tế'!AD33,'ort9'!A:B,2,0) -> #N/A | AG33: =VLOOKUP(AD33,'ort9'!D:E,2,0) -> #N/A | AI33: =(AC33-AB33)/2 -> 3.1086957 | AJ33: ± | AK33: =ROUND(AI33,0) -> 3 | AL33: =AJ33&AK33 -> ±3
A34: =ROW()-9 -> 25 | C34: 3.00x122X | D34: SAE1006 | E34: 0 | F34: 2322 | G34: =+AA34 -> 96.75 | H34: ±10 | N34: - | O34: - | P34: - | Q34: ≤65 | R34: SAE1006-Al | S34: 85x1230 | T34: Không sản xuất vượt khối lượng | U34: =+AF34 -> #N/A | V34: =+AG34 -> #N/A | W34: 21-24 | X34: Ống -Qua cán nguội | Z34: =RIGHT(W34,2) -> 24 | AA34: =SUM(E34:F34)/Z34 -> 96.75 | AB34: =SUM(E34:F34)*0.9/Z34 -> 87.075 | AC34: =SUM(E34:F34)*1.1/Z34 -> 106.425 | AD34: ="Thép cuộn cán nóng "&C34&" "&D34 -> Thép cuộn cán nóng 3.00x122X SAE1006 | AE34: =VLOOKUP(AD34,mvt!A:D,4,0) -> 1251121939512 | AF34: =VLOOKUP('Theo dõi thực tế'!AD34,'ort9'!A:B,2,0) -> #N/A | AG34: =VLOOKUP(AD34,'ort9'!D:E,2,0) -> #N/A | AI34: =(AC34-AB34)/2 -> 9.675 | AJ34: ± | AK34: =ROUND(AI34,0) -> 10 | AL34: =AJ34&AK34 -> ±10
A35: =ROW()-9 -> 26 | C35: 3.00x122X | D35: SAE1006 | E35: 0 | F35: 1900 | G35: =+AA35 -> 79.166667 | H35: ±8 | N35: - | O35: - | P35: - | Q35: ≤65 | R35: SAE1006-Al | S35: 85x1230 | T35: Không sản xuất vượt khối lượng | U35: =+AF35 -> #N/A | V35: =+AG35 -> #N/A | W35: 21-24 | X35: Ống -Qua cán nguội | Z35: =RIGHT(W35,2) -> 24 | AA35: =SUM(E35:F35)/Z35 -> 79.166667 | AB35: =SUM(E35:F35)*0.9/Z35 -> 71.25 | AC35: =SUM(E35:F35)*1.1/Z35 -> 87.083333 | AD35: ="Thép cuộn cán nóng "&C35&" "&D35 -> Thép cuộn cán nóng 3.00x122X SAE1006 | AE35: =VLOOKUP(AD35,mvt!A:D,4,0) -> 1251121939512 | AF35: =VLOOKUP('Theo dõi thực tế'!AD35,'ort9'!A:B,2,0) -> #N/A | AG35: =VLOOKUP(AD35,'ort9'!D:E,2,0) -> #N/A | AI35: =(AC35-AB35)/2 -> 7.9166667 | AJ35: ± | AK35: =ROUND(AI35,0) -> 8 | AL35: =AJ35&AK35 -> ±8
A36: =ROW()-9 -> 27 | C36: 2.75x122X | D36: SAE1006 | E36: 0 | F36: 1500 | G36: =+AA36 -> 62.5 | H36: ±6 | N36: - | O36: - | P36: - | Q36: ≤65 | R36: SAE1006-Al | S36: 85x1230 | T36: Không sản xuất vượt khối lượng | U36: =+AF36 -> #N/A | V36: =+AG36 -> #N/A | W36: 21-24 | X36: Ống -Qua cán nguội | Z36: =RIGHT(W36,2) -> 24 | AA36: =SUM(E36:F36)/Z36 -> 62.5 | AB36: =SUM(E36:F36)*0.9/Z36 -> 56.25 | AC36: =SUM(E36:F36)*1.1/Z36 -> 68.75 | AD36: ="Thép cuộn cán nóng "&C36&" "&D36 -> Thép cuộn cán nóng 2.75x122X SAE1006 | AE36: =VLOOKUP(AD36,mvt!A:D,4,0) -> 1251121976814 | AF36: =VLOOKUP('Theo dõi thực tế'!AD36,'ort9'!A:B,2,0) -> #N/A | AG36: =VLOOKUP(AD36,'ort9'!D:E,2,0) -> #N/A | AI36: =(AC36-AB36)/2 -> 6.25 | AJ36: ± | AK36: =ROUND(AI36,0) -> 6 | AL36: =AJ36&AK36 -> ±6
A37: =ROW()-9 -> 28 | C37: 2.75x122X | D37: SAE1006 | E37: 0 | F37: 1000 | G37: =+AA37 -> 41.666667 | H37: ±4 | N37: - | O37: - | P37: - | Q37: ≤65 | R37: SAE1006-Al | S37: 85x1230 | T37: Không sản xuất vượt khối lượng | U37: =+AF37 -> #N/A | V37: =+AG37 -> #N/A | W37: 21-24 | X37: Ống -Qua cán nguội | Z37: =RIGHT(W37,2) -> 24 | AA37: =SUM(E37:F37)/Z37 -> 41.666667 | AB37: =SUM(E37:F37)*0.9/Z37 -> 37.5 | AC37: =SUM(E37:F37)*1.1/Z37 -> 45.833333 | AD37: ="Thép cuộn cán nóng "&C37&" "&D37 -> Thép cuộn cán nóng 2.75x122X SAE1006 | AE37: =VLOOKUP(AD37,mvt!A:D,4,0) -> 1251121976814 | AF37: =VLOOKUP('Theo dõi thực tế'!AD37,'ort9'!A:B,2,0) -> #N/A | AG37: =VLOOKUP(AD37,'ort9'!D:E,2,0) -> #N/A | AI37: =(AC37-AB37)/2 -> 4.1666667 | AJ37: ± | AK37: =ROUND(AI37,0) -> 4 | AL37: =AJ37&AK37 -> ±4
A38: =ROW()-9 -> 29 | C38: 2.50x122X | D38: SAE1006 | E38: 0 | F38: 500 | G38: =+AA38 -> 20.833333 | H38: ±2 | N38: - | O38: - | P38: - | Q38: ≤65 | R38: SAE1006-Al | S38: 85x1230 | T38: Không sản xuất vượt khối lượng | U38: =+AF38 -> #N/A | V38: =+AG38 -> #N/A | W38: 21-24 | X38: Ống -Qua cán nguội | Z38: =RIGHT(W38,2) -> 24 | AA38: =SUM(E38:F38)/Z38 -> 20.833333 | AB38: =SUM(E38:F38)*0.9/Z38 -> 18.75 | AC38: =SUM(E38:F38)*1.1/Z38 -> 22.916667 | AD38: ="Thép cuộn cán nóng "&C38&" "&D38 -> Thép cuộn cán nóng 2.50x122X SAE1006 | AE38: =VLOOKUP(AD38,mvt!A:D,4,0) -> 1251121954737 | AF38: =VLOOKUP('Theo dõi thực tế'!AD38,'ort9'!A:B,2,0) -> #N/A | AG38: =VLOOKUP(AD38,'ort9'!D:E,2,0) -> #N/A | AI38: =(AC38-AB38)/2 -> 2.0833333 | AJ38: ± | AK38: =ROUND(AI38,0) -> 2 | AL38: =AJ38&AK38 -> ±2
A39: =ROW()-9 -> 30 | C39: 2.50x122X | D39: SAE1006 | E39: 0 | F39: 1500 | G39: =+AA39 -> 62.5 | H39: ±6 | N39: - | O39: - | P39: - | Q39: ≤65 | R39: SAE1006-Al | S39: 85x1230 | T39: Không sản xuất vượt khối lượng | U39: =+AF39 -> #N/A | V39: =+AG39 -> #N/A | W39: 21-24 | X39: Ống -Qua cán nguội | Z39: =RIGHT(W39,2) -> 24 | AA39: =SUM(E39:F39)/Z39 -> 62.5 | AB39: =SUM(E39:F39)*0.9/Z39 -> 56.25 | AC39: =SUM(E39:F39)*1.1/Z39 -> 68.75 | AD39: ="Thép cuộn cán nóng "&C39&" "&D39 -> Thép cuộn cán nóng 2.50x122X SAE1006 | AE39: =VLOOKUP(AD39,mvt!A:D,4,0) -> 1251121954737 | AF39: =VLOOKUP('Theo dõi thực tế'!AD39,'ort9'!A:B,2,0) -> #N/A | AG39: =VLOOKUP(AD39,'ort9'!D:E,2,0) -> #N/A | AI39: =(AC39-AB39)/2 -> 6.25 | AJ39: ± | AK39: =ROUND(AI39,0) -> 6 | AL39: =AJ39&AK39 -> ±6
A40: =ROW()-9 -> 31 | B40: Tổng | E40: =SUM(E10:E39) -> 14365 | F40: =SUM(F10:F39) -> 22232 | G40: =SUM(G10:G39) -> 1646.7871 | H40: =SUM(H10:H39) -> 0 | AD40: ="Thép cuộn cán nóng "&C40&" "&D40 -> Thép cuộn cán nóng | AE40: =VLOOKUP(AD40,mvt!A:D,4,0) -> #N/A | AF40: =VLOOKUP('Theo dõi thực tế'!AD40,'ort9'!A:B,2,0) -> #N/A | AG40: =VLOOKUP(AD40,'ort9'!D:E,2,0) -> #N/A
A41: Ghi chú: - Cho phép cán lại phôi hồi lò đạt TPHH và không có các khuyết tật đúc nghiêm trọng như: ngậm xỉ sâu, nứt ngang, cong vênh ... - Các chỉ tiêu chất lượng khác đánh giá theo TCNB. MẶC ĐỊNH GIÁ TRỊ X=2, Y=7. - Các sản phẩm với mục đích làm Tôn,ống-không cán lại, Ống Gi sản xuất đủ loại I theo LSX. Phân loại chất lượng sản phẩm theo phiếu YCCN số 264.2024 NM.HRC1./. - Các sản phẩm với mục đích làm Cut sheet, kết cấu sản xuất đủ loại I theo LSX. Phân loại chất lượng sản phẩm theo phiếu YCCN số 248.2024 NM.HRC1./.
...

Sheet PXC 05.10.25
P1: BM.04D/QT.05 Ngày hiệu lực: 06/06/2025 Lần sửa đổi: 02
B3: Số: 05.10.2025/LSX-XC-NM.HRC1
A4: LỆNH SẢN XUẤT
A5: - Bộ phận thực hiện: XC-NM.HRC1
A6: - Thời gian hiệu lực: Từ 08h00, ngày 23/10/2025 đến 08h00, ngày 30/10/2025
A7: TT | B7: Thời gian dự kiến SX Time/Date | C7: Sản phẩm/Product | M7: Phôi cán/Slab | O7: Yêu cầu đặc biệt | P7: Số Order number | Q7: Số lô/ Batch | R7: KL Cuộn (Tấn) | S7: Mục đích sử dụng | T7: KHÁCH HÀNG
C8: Kích cỡ Dimension T x W (mmxmm) | D8: Mác thép Steel grade | E8: Sản lượng Quantity (tấn) | G8: Sản lượng Quantity (cuộn) | I8: Cơ tính/Mechanical properties
E9: 1A | F9: 1B | G9: Yêu cầu | H9: Dung sai | I9: GHC Re (MPa) | J9: GHB Rm (Mpa) | K9: Giãn dài El (%) | L9: Độ cứng Hardnes (HRB) | M9: Mác phôi Steel grade | N9: Kích thước (mmxmm)
A10: 1
A11: =ROW()-9 -> 2 | B11: Tổng | E11: =SUM(E10:E10) -> 0 | F11: =SUM(F10:F10) -> 0 | G11: =SUM(G10:G10) -> 0
N13: Quảng Ngãi, ngày 22 tháng 10 năm 2025
E14: BGĐ | O14: T/P P.KH
A15: Nơi nhận:
A16: - BGĐ (thay BC);
A17: - Các BP/NM;
A18: - Lưu P.KH (EO).

Sheet Order
E1: =MAX(H:H) -> 2125100135
A3: =B3*1000 -> 1600000 | B3: 1600 | C3: ỐNG THÉP HƯNG YÊN | D3: 582A.T09.2025/HPDQ-OTHY-KH | I3: 1251121958797 | J3: Thép cuộn cán nóng 2.95x123X SAE1006
A4: =B4*1000 -> 200000 | B4: 200 | C4: ỐNG THÉP HƯNG YÊN | D4: 582A.T09.2025/HPDQ-OTHY-KH | I4: 1251121959053 | J4: Thép cuộn cán nóng 3.15x123X SAE1006
A5: =B5*1000 -> 700000 | B5: 700 | C5: ỐNG THÉP BÌNH DƯƠNG | D5: 582D.T09.2025/HPDQ-OTBD-KH | I5: 1251121917787 | J5: Thép cuộn cán nóng 2.45x123X SAE1006
A6: =B6*1000 -> 700000 | B6: 700 | C6: ỐNG THÉP BÌNH DƯƠNG | D6: 582D.T09.2025/HPDQ-OTBD-KH | I6: 1251121920268 | J6: Thép cuộn cán nóng 2.45x126X SAE1006
A7: =B7*1000 -> 800000 | B7: 800 | C7: ỐNG THÉP BÌNH DƯƠNG | D7: 582D.T09.2025/HPDQ-OTBD-KH | I7: 1251121934975 | J7: Thép cuộn cán nóng 2.75x123X SAE1006
A8: =B8*1000 -> 860000 | B8: 860 | C8: ỐNG THÉP BÌNH DƯƠNG | D8: 582D.T09.2025/HPDQ-OTBD-KH | I8: 1251121928226 | J8: Thép cuộn cán nóng 2.75x125X SAE1006
A9: =B9*1000 -> 800000 | B9: 800 | C9: ỐNG THÉP BÌNH DƯƠNG | D9: 582D.T09.2025/HPDQ-OTBD-KH | I9: 1251121958797 | J9: Thép cuộn cán nóng 2.95x123X SAE1006
A10: =B10*1000 -> 520000 | B10: 520 | C10: ỐNG THÉP BÌNH DƯƠNG | D10: 582D.T09.2025/HPDQ-OTBD-KH | I10: 1251121924655 | J10: Thép cuộn cán nóng 3.00x125X SAE1006
A11: =B11*1000 -> 700000 | B11: 700 | C11: ỐNG THÉP BÌNH DƯƠNG | D11: 582D.T09.2025/HPDQ-OTBD-KH | I11: 1251121959053 | J11: Thép cuộn cán nóng 3.15x123X SAE1006
A12: =B12*1000 -> 350000 | B12: 350 | C12: ỐNG THÉP BÌNH DƯƠNG | D12: 582D.T09.2025/HPDQ-OTBD-KH | I12: 1251121924518 | J12: Thép cuộn cán nóng 3.45x125X SAE1006
