Workbook

Sheet KH
A1: Từ ngày 1-10 (Nhịp 1), từ ngày 11-21 (Nhịp 2), từ ngày 22 - hết tháng (nhịp 3)
A2: Tháng | B2: 1 | C2: 2 | D2: 3 | E2: Tổng | F2: Kế hoạch update 03/06 | G2: SLG update NGÀY 12/6 | H2: Tồn kho đầu kỳ | I2: SLSX HRC KH | J2: SLSX thực tế | K2: Tồn kho cuối kỳ | L2: Mục tiêu QT25
A3: 45809 | B3: =SUMIF('LỊCH TÀU - 06.2025'!$P$3:$P$1048576,KH!B$2,'LỊCH TÀU - 06.2025'!$L$3:$L$1048576) -> 92478 | C3: =SUMIF('LỊCH TÀU - 06.2025'!$P$3:$P$1048576,KH!C$2,'LỊCH TÀU - 06.2025'!$L$3:$L$1048576) -> 178358 | D3: =SUMIF('LỊCH TÀU - 06.2025'!$P$3:$P$1048576,KH!D$2,'LỊCH TÀU - 06.2025'!$L$3:$L$1048576) -> 110506 | E3: =SUM(B3:D3) -> 381342 | F3: 390000 | G3: 370000 | H3: 185000 | I3: 341401 | J3: 341401 | K3: =+H3+J3-E3 -> 145059
A4: 45839 | B4: =SUMIF('LỊCH TÀU - 07.2025'!$P$3:$P$1048576,KH!B$2,'LỊCH TÀU - 07.2025'!$L$3:$L$1048576) -> 100700 | C4: =SUMIF('LỊCH TÀU - 07.2025'!$P$3:$P$1048576,KH!C$2,'LỊCH TÀU - 07.2025'!$L$3:$L$1048576) -> 119259.3 | D4: =SUMIF('LỊCH TÀU - 07.2025'!$P$3:$P$1048576,KH!D$2,'LỊCH TÀU - 07.2025'!$L$3:$L$1048576) -> 141721 | E4: =SUM(B4:D4) -> 361680.3 | F4: 430000 | G4: 440000 | H4: =+K3 -> 145059 | I4: 389769 | J4: 389769 | K4: =+H4+J4-E4 -> 173147.7
A5: 45870 | B5: =SUMIF('LỊCH TÀU - 08.2025'!$P$3:$P$1048576,KH!B$2,'LỊCH TÀU - 08.2025'!$L$3:$L$1048576) -> 156170 | C5: =SUMIF('LỊCH TÀU - 08.2025'!$P$3:$P$1048576,KH!C$2,'LỊCH TÀU - 08.2025'!$L$3:$L$1048576) -> 86076 | D5: =SUMIF('LỊCH TÀU - 08.2025'!$P$3:$P$1048576,KH!D$2,'LỊCH TÀU - 08.2025'!$L$3:$L$1048576) -> 171210 | E5: =SUM(B5:D5) -> 413456 | F5: 490000 | G5: 490000 | H5: =+K4 -> 173147.7 | I5: 446244 | J5: 446244 | K5: 212294 | L5: 450000
A6: 45901 | B6: =SUMIF('LỊCH TÀU - 09.2025 '!$R$4:$R$1048576,KH!B$2,'LỊCH TÀU - 09.2025 '!$M$4:$M$1048576) -> 136695 | C6: =SUMIF('LỊCH TÀU - 09.2025 '!$R$4:$R$1048576,KH!C$2,'LỊCH TÀU - 09.2025 '!$M$4:$M$1048576) -> 188929 | D6: =SUMIF('LỊCH TÀU - 09.2025 '!$R$4:$R$1048576,KH!D$2,'LỊCH TÀU - 09.2025 '!$M$4:$M$1048576) -> 164256 | E6: =SUM(B6:D6) -> 489880 | F6: 563000 | G6: 573000 | H6: =+K5 -> 212294 | I6: 547068 | J6: 547068 | K6: 277495 | L6: 525000 | M6: =L6/3 -> 175000
A7: 45931 | B7: =SUMIF('LỊCH TÀU - 10.2025 '!$Q$7:$Q$1048576,KH!B$2,'LỊCH TÀU - 10.2025 '!$M$7:$M$1048576) -> 163875 | C7: =SUMIF('LỊCH TÀU - 10.2025 '!$Q$7:$Q$1048576,KH!C$2,'LỊCH TÀU - 10.2025 '!$M$7:$M$1048576) -> 166380 | D7: =SUMIF('LỊCH TÀU - 10.2025 '!$Q$7:$Q$1048576,KH!D$2,'LỊCH TÀU - 10.2025 '!$M$7:$M$1048576) -> 195739 | E7: =SUM(B7:D7) -> 525994 | F7: 605000 | G7: 605000 | H7: =+K6 -> 277495 | I7: 559711 | K7: 216097 | L7: 556000 | M7: =L7*85% -> 472600
A8: 45962 | B8: =SUMIF('LỊCH TÀU - 11.2025'!$Q4:$Q9855,KH!B2,'LỊCH TÀU - 11.2025'!$M$4:$M$9855) -> 113237 | C8: =SUMIF('LỊCH TÀU - 11.2025'!$Q4:$Q9855,KH!C2,'LỊCH TÀU - 11.2025'!$M$4:$M$9855) -> 154426 | D8: =SUMIF('LỊCH TÀU - 11.2025'!$Q4:$Q9855,KH!D2,'LỊCH TÀU - 11.2025'!$M$4:$M$9855) -> 217418 | E8: =SUM(B8:D8) -> 485081 | F8: 648000 | G8: 648000 | H8: =+K7 -> 216097 | I8: 540000 | K8: =+H8+I8-E8 -> 271016
A9: 45992 | F9: 657000 | G9: 657000 | H9: =+K8 -> 271016 | I9: 650000 | K9: =+H9+I9-E9 -> 921016
A10: 46023
A11: 46054
A12: 46082
A13: 46113
A14: 46143
A15: 46174
B18: 45839 | D18: 45870 | F18: 45901 | H18: 45901 | J18: 45931 | L18: 45986
A19: Đại lý | B19: Sản lượng | C19: Tỉ lệ | D19: Sản lượng | E19: Tỉ lệ | F19: Sản lượng | G19: Tỉ lệ | H19: Sản lượng | I19: Tỉ lệ | J19: Sản lượng | K19: Tỉ lệ | L19: Sản lượng | M19: Tỉ lệ | N19: =SUM(N20:N26) -> 540000 | O19: 0.85
A20: HPS | B20: =SUMIF('LỊCH TÀU - 07.2025'!$F:$F,$A20,'LỊCH TÀU - 07.2025'!$L:$L) -> 144284.3 | C20: =B20/$B$27 -> 0.45779353 | D20: =SUMIF('LỊCH TÀU - 08.2025'!$F:$F,$A20,'LỊCH TÀU - 08.2025'!$L:$L) -> 111486 | E20: =D20/$D$27 -> 0.30764518 | H20: =SUMIF('LỊCH TÀU - 09.2025 '!$F:$F,A20,'LỊCH TÀU - 09.2025 '!$M:$M) -> 124874 | I20: =H20/$H$27 -> 0.28546478 | J20: =SUMIFS('LỊCH TÀU - 10.2025 '!M:M,'LỊCH TÀU - 10.2025 '!F:F,KH!A20) -> 124780 | K20: =J20/$J$27 -> 0.25914527 | L20: =SUMIF('LỊCH TÀU - 11.2025'!$F:$F,KH!A20,'LỊCH TÀU - 11.2025'!$M:$M) -> 130272 | M20: =L20/$L$27 -> 0.32176254 | N20: 140000 | O20: =N20*0.85 -> 119000 | P20: =O20/3 -> 39666.667 | Q20: =O20/$O$27 -> 0.25925926 | R20: =O20-64800 -> 54200 | S20: =O20-L20 -> -11272 | T20: =48200+5900 -> 54100 | U20: =S20-T20 -> -65372 | V20: ok
A21: Việt Thành | B21: =SUMIF('LỊCH TÀU - 07.2025'!$F:$F,$A21,'LỊCH TÀU - 07.2025'!$L:$L) -> 91288 | C21: =B21/$B$27 -> 0.28964383 | D21: =SUMIF('LỊCH TÀU - 08.2025'!$F:$F,$A21,'LỊCH TÀU - 08.2025'!$L:$L) -> 121126 | E21: =D21/$D$27 -> 0.33424673 | H21: =SUMIF('LỊCH TÀU - 09.2025 '!$F:$F,A21,'LỊCH TÀU - 09.2025 '!$M:$M) -> 141846 | I21: =H21/$H$27 -> 0.32426316 | J21: =SUMIFS('LỊCH TÀU - 10.2025 '!M:M,'LỊCH TÀU - 10.2025 '!F:F,KH!A21) -> 166654 | K21: =J21/$J$27 -> 0.34610991 | L21: =SUMIF('LỊCH TÀU - 11.2025'!$F:$F,KH!A21,'LỊCH TÀU - 11.2025'!$M:$M) -> 152869 | M21: =L21/$L$27 -> 0.37757552 | N21: 185000 | O21: =N21*0.85 -> 157250 | P21: =O21/3 -> 52416.667 | Q21: =O21/$O$27 -> 0.34259259 | S21: =O21-L21 -> 4381 | U21: =S21-T21 -> 4381
A22: Thiên Phúc | B22: =SUMIF('LỊCH TÀU - 07.2025'!$F:$F,$A22,'LỊCH TÀU - 07.2025'!$L:$L) -> 14490 | C22: =B22/$B$27 -> 0.045974707 | D22: =SUMIF('LỊCH TÀU - 08.2025'!$F:$F,$A22,'LỊCH TÀU - 08.2025'!$L:$L) -> 30528 | E22: =D22/$D$27 -> 0.084241897 | H22: =SUMIF('LỊCH TÀU - 09.2025 '!$F:$F,A22,'LỊCH TÀU - 09.2025 '!$M:$M) -> 39478 | I22: =H22/$H$27 -> 0.090247599 | J22: =SUMIFS('LỊCH TÀU - 10.2025 '!M:M,'LỊCH TÀU - 10.2025 '!F:F,KH!A22) -> 50053 | K22: =J22/$J$27 -> 0.10395094 | L22: =SUMIF('LỊCH TÀU - 11.2025'!$F:$F,KH!A22,'LỊCH TÀU - 11.2025'!$M:$M) -> 35062 | M22: =L22/$L$27 -> 0.086600637 | N22: 55000 | O22: =N22*0.85 -> 46750 | P22: =O22/3 -> 15583.333 | Q22: =O22/$O$27 -> 0.10185185 | S22: =O22-L22 -> 11688 | T22: 16000 | U22: =S22-T22 -> -4312
A23: VTB Hải Dương | B23: =SUMIF('LỊCH TÀU - 07.2025'!$F:$F,$A23,'LỊCH TÀU - 07.2025'!$L:$L) -> 33435 | C23: =B23/$B$27 -> 0.1060845 | D23: =SUMIF('LỊCH TÀU - 08.2025'!$F:$F,$A23,'LỊCH TÀU - 08.2025'!$L:$L) -> 27927 | E23: =D23/$D$27 -> 0.077064448 | H23: =SUMIF('LỊCH TÀU - 09.2025 '!$F:$F,A23,'LỊCH TÀU - 09.2025 '!$M:$M) -> 40647 | I23: =H23/$H$27 -> 0.092919959 | J23: =SUMIFS('LỊCH TÀU - 10.2025 '!M:M,'LỊCH TÀU - 10.2025 '!F:F,KH!A23) -> 47802 | K23: =J23/$J$27 -> 0.099276021 | L23: =SUMIF('LỊCH TÀU - 11.2025'!$F:$F,KH!A23,'LỊCH TÀU - 11.2025'!$M:$M) -> 23394 | M23: =L23/$L$27 -> 0.05778151 | N23: 55000 | O23: =N23*0.85 -> 46750 | P23: =O23/3 -> 15583.333 | Q23: =O23/$O$27 -> 0.10185185 | S23: =O23-L23 -> 23356 | U23: =S23-T23 -> 23356
A24: MT Hà Nội | B24: =SUMIF('LỊCH TÀU - 07.2025'!$F:$F,$A24,'LỊCH TÀU - 07.2025'!$L:$L) -> 24187 | C24: =B24/$B$27 -> 0.076741908 | D24: =SUMIF('LỊCH TÀU - 08.2025'!$F:$F,$A24,'LỊCH TÀU - 08.2025'!$L:$L) -> 32196 | E24: =D24/$D$27 -> 0.088844737 | H24: =SUMIF('LỊCH TÀU - 09.2025 '!$F:$F,A24,'LỊCH TÀU - 09.2025 '!$M:$M) -> 43326 | I24: =H24/$H$27 -> 0.099044214 | J24: =SUMIFS('LỊCH TÀU - 10.2025 '!M:M,'LỊCH TÀU - 10.2025 '!F:F,KH!A24) -> 42553 | K24: =J24/$J$27 -> 0.088374807 | L24: =SUMIF('LỊCH TÀU - 11.2025'!$F:$F,KH!A24,'LỊCH TÀU - 11.2025'!$M:$M) -> 33320 | M24: =L24/$L$27 -> 0.082298022 | N24: 55000 | O24: =N24*0.85 -> 46750 | P24: =O24/3 -> 15583.333 | Q24: =O24/$O$27 -> 0.10185185 | S24: =O24-L24 -> 13430 | T24: 12900 | U24: =S24-T24 -> 530 | V24: 29
A25: Mặt Trời | B25: =SUMIF('LỊCH TÀU - 07.2025'!$F:$F,$A25,'LỊCH TÀU - 07.2025'!$L:$L)-SUMIF('LỊCH TÀU - 07.2025'!$C:$C,"Đường bộ",'LỊCH TÀU - 07.2025'!$L:$L) -> 7489 | C25: =B25/$B$27 -> 0.023761531 | D25: =(SUMIF('LỊCH TÀU - 08.2025'!$F:$F,$A25,'LỊCH TÀU - 08.2025'!$L:$L)-SUMIF('LỊCH TÀU - 08.2025'!$C:$C,"Đường bộ",'LỊCH TÀU - 08.2025'!$L:$L)) -> 22329 | E25: =D25/$D$27 -> 0.061616789 | H25: =SUMIF('LỊCH TÀU - 09.2025 '!$F:$F,A25,'LỊCH TÀU - 09.2025 '!$M:$M) -> 25638 | I25: =H25/$H$27 -> 0.058609047 | J25: =SUMIFS('LỊCH TÀU - 10.2025 '!M:M,'LỊCH TÀU - 10.2025 '!F:F,KH!A25) -> 27618 | K25: =J25/$J$27 -> 0.057357541 | L25: =SUMIF('LỊCH TÀU - 11.2025'!$F:$F,KH!A25,'LỊCH TÀU - 11.2025'!$M:$M) -> 12018 | M25: =L25/$L$27 -> 0.029683602 | N25: 25000 | O25: =N25*0.85 -> 21250 | P25: =O25/3 -> 7083.3333 | Q25: =O25/$O$27 -> 0.046296296 | S25: =O25-L25 -> 9232 | T25: 10790 | U25: =S25-T25 -> -1558
A26: Nam Phát | C26: =B26/$B$27 -> 0 | D26: =(SUMIF('LỊCH TÀU - 08.2025'!$F:$F,$A26,'LỊCH TÀU - 08.2025'!$L:$L)) -> 16793 | E26: =D26/$D$27 -> 0.046340218 | H26: =SUMIF('LỊCH TÀU - 09.2025 '!$F:$F,A26,'LỊCH TÀU - 09.2025 '!$M:$M) -> 21632 | I26: =H26/$H$27 -> 0.04945124 | J26: =SUMIFS('LỊCH TÀU - 10.2025 '!M:M,'LỊCH TÀU - 10.2025 '!F:F,KH!A26) -> 22046 | K26: =J26/$J$27 -> 0.045785515 | L26: =SUMIF('LỊCH TÀU - 11.2025'!$F:$F,KH!A26,'LỊCH TÀU - 11.2025'!$M:$M) -> 17935 | M26: =L26/$L$27 -> 0.04429817 | N26: 25000 | O26: =N26*0.85 -> 21250 | P26: =O26/3 -> 7083.3333 | Q26: =O26/$O$27 -> 0.046296296 | S26: =O26-L26 -> 3315 | U26: =S26-T26 -> 3315
A27: TỔNG | B27: =SUM(B20:B26) -> 315173.3 | D27: =SUM(D20:D26) -> 362385 | H27: =SUM(H20:H26) -> 437441 | J27: =SUM(J20:J26) -> 481506 | L27: =SUM(L20:L26) -> 404870 | N27: =SUM(N20:N26) -> 540000 | O27: =SUM(O20:O26) -> 459000 | S27: =SUM(S20:S26) -> 54130
A28: Age-line | B28: =SUMIF('LỊCH TÀU - 07.2025'!$F:$F,$A28,'LỊCH TÀU - 07.2025'!$L:$L) -> 18782 | D28: =SUMIF('LỊCH TÀU - 08.2025'!$F:$F,$A28,'LỊCH TÀU - 08.2025'!$L:$L) -> 10275
A29: Benline | B29: =SUMIF('LỊCH TÀU - 07.2025'!$F:$F,$A29,'LỊCH TÀU - 07.2025'!$L:$L) -> 0 | D29: =SUMIF('LỊCH TÀU - 08.2025'!$F:$F,$A29,'LỊCH TÀU - 08.2025'!$L:$L) -> 35000
A30: ATTA/PTSC | B30: =SUMIF('LỊCH TÀU - 07.2025'!$F:$F,$A30,'LỊCH TÀU - 07.2025'!$L:$L) -> 6866 | D30: =SUMIF('LỊCH TÀU - 08.2025'!$F:$F,$A30,'LỊCH TÀU - 08.2025'!$L:$L) -> 0
A31: TỔNG | B31: =SUM(B27:B30) -> 340821.3 | C31: =B31/$B$31 -> 1 | D31: =SUM(D27:D30) -> 407660 | E31: =SUM(E20:E30) -> 1 | H31: =SUM(H27:H30) -> 437441 | J31: =SUM(J27:J30) -> 481506 | L31: =SUM(L27:L30) -> 404870 | S31: Chắc chắn | T31: Chờ Minh Phú
R32: Bắc | S32: 50000 | T32: 14000 | U32: =S32+T32 -> 64000 | V32: 48200 | W32: =U32-V32 -> 15800 | X32: 20000 | Y32: trước 25/11
R33: Nam cũ | S33: =68000-18500-11900-11700 -> 25900 | T33: 20000 | U33: =S33+T33 -> 45900 | V33: =5900+12900 -> 18800 | W33: =U33-V33 -> 27100
R34: Nam bổ sung | S34: 50000 | U34: =S34+T34 -> 50000 | W34: =U34-V34 -> 50000
R35: Tổng | S35: =SUM(S32:S34) -> 125900 | T35: =SUM(T32:T34) -> 34000 | U35: =S35+T35-83000 -> 76900 | W35: =SUM(W32:W34) -> 92900

Sheet LỊCH TÀU - 10.2023
A2: CẬP NHẬT TÌNH HÌNH XUẤT HÀNG HRC THÁNG 10/2023
C4: =SUBTOTAL(9,C9:C43) -> 263630 | J4: =TODAY() -> 45987
A5: STT | B5: TÀU | C5: KHỐI LƯỢNG | D5: CẬP NHẬT TÌNH HÌNH/ETA | E5: ĐẠI LÝ | F5: CẬP NHẬT ETB | G5: THỜI GIAN YÊU CẦU LÀM HÀNG | H5: CẢNG XẾP | I5: CẢNG ĐẾN | J5: LỆNH XUẤT HÀNG | K5: GHI CHÚ | L5: Thời gian DQ đáp ứng | M5: Mức độ | N5: =SUM(#REF!) -> #REF!
A6: {=_xlfn.SEQUENCE(45,1,1)} -> 1 | B6: THẮNG LỢI 568 | C6: 4000 | D6: 29.09.2023 NEO | E6: Thiên Phúc | F6: 13H00 ngày 02/10 Bến 3 | G6: Xong tàu | H6: Dung Quất | I6: Nghi Sơn | J6: 2000001895 - HS - 4000T (Hàng hóa ok) chỉ xuất khổ 1260 | M6: .
A7: 2 | B7: MINAMOTO | C7: 11500 | D7: 26.09.2023 | E7: Age-line | F7: 02/10 Bến 4/6 | G7: LSD: 5 Oct => cần xong ngày hôm nay Đang làm hàng | H7: Dung Quất | I7: Malaysia | J7: 2400000342 - 162.2023/HPDQ-GS (ALPINE) (S275JR) (Hàng hóa ok) 2400000343 - 162.2023/HPDQ-GS (ALPINE) (SPHC) (Hàng hóa ok) 2400000319 - 163.2023/HPDQ-GS (CHYEKEONG) (Hàng hóa ok) 2400000332 - 164.2023/HPDQ-GS LOT 01 (SPHC) (Hàng hóa ok) 2400000333 - 164.2023/HPDQ-GS LOT 01 (S275JR+AR) (Hàng hóa ok) 2400000335 - 164.2023/HPDQ-GS LOT 2 (SPHC) (Hàng hóa ok) 2400000360 - 164.2023/HPDQ-GS LOT 2 (S275JR) (Hàng hóa ok) 2400000356- 164.2023/HPDQ-GS LOT 2 (S275JR-11.70) (Hàng hóa ok) 2400000322 - 165.2023/HPDQ-GS (MKPC) (Hàng hóa ok) 2400000323 - 166.2023/HPDQ-GS (PE) (Hàng hóa ok) 2400000324 - 167.2023/HPDQ-GS (PRESTARP) (Hàng hóa ok)
A8: 3 | B8: VIỆT PHÚC 05 | C8: 3900 | D8: 01.10.2023 NEO | E8: Thiên Phúc | F8: 03/10 Bến 2 | G8: Xong tàu | H8: Dung Quất | I8: Tân Thuận/ Phú Mỹ | J8: 2000001908 - 2000T - 174.2023/HPDQ-TDA-Phú Mỹ (Chiều 3/10 NK) 2200001422 - OTHY (Cargill) - 800T (Hàng hóa ok) 2000001901 - Citicom - 150T - Tân Thuận (Háng hóa sáng 4/NK) - 4/10 DUYỆT LỆNH 2000001906 // 2000001907 - Tiến Lên - 280T - Tân Thuận (Háng hóa ok) 2200001421 - OTBD 38T (Hàng hóa ok) 2200001434 - OTBD 41T (Hàng hóa ok) 2200001437 - OTBD 559T cân tải (Hàng hóa ok) | M8: .
A9: 4 | B9: FENG XIU HAI | C9: 17200 | D9: 03.10.2023 | E9: PACIFIC | F9: 22h 03/10 Bến 11 | G9: Đang làm hàng LSD: 10 Oct | H9: Dung Quất | I9: Ravenna | J9: 2400000321 - 141A.2023 HPDQ-HS (Hàng hóa ok) 2400000301 - 141B.2023/HPDQ-HS (Hàng hóa ok) 2400000340 - 147.2023 HPDQ-GS (Hàng hóa ok) 2400000331 - 153.2023 HPDQ-CHROMIUM (S235JR) (Hàng hóa ok) 2400000369 - 153.2023 HPDQ-CHROMIUM (S355JR) (Hàng hóa ok) 2500000006 - 154.2023 HPDQ-HPI (Đã MAP 6640t + 2kt sáng mùng 2/10) 2400000309 - 159.2023/HPDQ-HYUNDAI (Hàng hóa ok)
A10: 5 | B10: VIỆT THUẬN QN-01 | C10: 6000 | D10: 01.10.2023 NEO | E10: Mạnh Thắng | F10: 04/10 Bến 1 | G10: Xong tàu | H10: Dung Quất | I10: Tân Thuận/Phú Mỹ | J10: 2000001911 - 1000T- JFE- Phú Mỹ (Hàng hóa ok) 2000001909 - 2800T-TDA-Tân Thuận (Hàng hóa ok) 2000001910 - TDA - 2200T - Tân Thuận (Hàng hóa ok) | M10: .
A11: 6 | B11: VIỆT THUẬN 045-01 | C11: 4250 | D11: 19H00 04.10.2023 | E11: Mạnh Thắng | F11: 05/10 Bến 3 | G11: Xong tàu | H11: Dung Quất | I11: Hải Phòng | J11: 2200001399 - 300T - THP (Hàng hóa ok) 2200001414 - 3,860T - THP (Hàng hóa ok) 2200001424 - 1,850T - THP cân tải (Hàng hóa ok) | M11: .
A12: 7 | B12: PHƯƠNG NAM 98 | C12: 4700 | D12: 05.10.2023 Neo | E12: Nam Phát | F12: 07/10 Bến 1 | G12: Xong tàu | H12: Dung Quất | I12: Cẩm Nguyên/ Phú Mỹ | J12: 2000001905 - Vina One - 1.800 T (SPOT) - lệnh ok - Cẩm Nguyên (Hàng hóa ok) 2000001903 - SMCCK - 3.000T - Phú Mỹ (Hàng hóa ok) Lên hàng của SMCCK sau để dỡ trước | K12: SMCKK cắt hàng để xuất hóa đơn ngày 9/10 | M12: .
A13: 8 | B13: THANH LOAN 28 | C13: 3300 | D13: 06.10.2023 | E13: VTB Hải Dương | F13: 07/10 Bến 2 | G13: Xong tàu | H13: Dung Quất | I13: Tân Thuận | J13: 2000001912 - Nam Kim - 3.300T (Hàng hóa ok) | K13: Nam Kim xuất 620MT Thép cuộn cán nóng 4.00 x 1125 SAE1006 2,680MT Thép cuộn cán nóng 2.50 x 1158 SAE1006 | M13: .
A14: 9 | B14: Seacon Manila | C14: 17000 | D14: 30.09 - 03.10.2023 | E14: Age-line | F14: 2h 06/10 Bến 6 05.10 bắt đầu load hàng | G14: Xong tàu | H14: Dung Quất | I14: Jakarta, Indonesia | J14: 2400000376 - 185.2023/HPDQ-AMI (SAE1006)(Hàng hóa ok) 2400000377 - 185.2023/HPDQ-AMI (S275JR) (Hàng hóa ok)
A15: 10 | B15: PHƯƠNG NAM 46 | C15: 3700 | D15: 04.10.2023 NEO | E15: Nam Phát | F15: 07/10 Bến 3 | G15: Xong tàu | H15: Dung Quất | I15: Cẩm Nguyên | J15: 2000001905 - Vina One - 3.700 T (SPOT) - lệnh ok - Cẩm Nguyên - (Hàng hóa ok) | M15: .
A16: 11 | B16: GLORY FORWARDER | C16: 9600 | D16: 06.10.2023 | E16: HOYER | F16: 11h 7/10 Bến 5/10 | G16: Xong tàu | H16: Dung Quất | I16: port klang, malay | J16: 2400000339 - 173.2023 HPDQ-SS (Hàng hóa ok) 2400000336 - 168.2023/HPDQ-HWA (Hàng hóa ok) 2400000337 - 169.2023 HPDQ MTS (Hàng hóa ok) 2400000338 - 170.2023/HPDQ-NIPPON (Hàng hóa ok) 2400000345 - 179.2023/HPDQ-NIPPON (SPHC) (Hàng hóa ok) 2400000346 - 179.2023/HPDQ-NIPPON (SPHT1) (Hàng hóa ok) 2400000347 - 179.2023/HPDQ-NIPPON (S275JR) (Hàng hóa ok) 2400000361 - 179.2023/HPDQ-NIPPON (SPHT3) (Hàng hóa ok) 2400000349 - 186.2023/HPDQ-LF (Hàng hóa ok) 2400000350 - 201.2023/HPDQ-LF (Hàng hóa ok) 2400000354 - 188.2023/HPDQ-JFE (HH) (Hàng hóa ok) 2400000365 - 200.2023/HPDQ-MI (TSK) (Hàng hóa ok) 2400000367 - 187.2023/HPDQ-MI (OTS) (Hàng hóa ok) 2400000375 - 190.2023/HPDQ-NI Lệnh 375 CHỨ (Hàng hóa ok) 2400000351 - 191.2023/HPDQ-NI (S275JR) (Hàng hóa ok) 2400000352 - 191.2023/HPDQ-NI (SPHT3) (Hàng hóa ok) 2400000353 - 191.2023/HPDQ-NI (SPHC) (Hàng hóa ok) 2400000368 - 189.2023/HPDQ-MTS (Hàng hóa ok) 2400000366 - 199.2023/HPDQ-GS (Hàng hóa ok) 2400000362 - 204.2023/HPDQ-HWA (Hàng hóa ok) 2400000355 - 205.2023/HPDQ-HWA (Hàng hóa ok) | K16: Tàu cũ: HUI SHUN NO. 1
A17: 12 | B17: MT HÀ NỘI 39 | C17: 4300 | D17: 07.10.2023 | E17: MT Hà Nội | F17: 20h 08/10 Bến 1 | G17: Xong tàu | H17: Dung Quất | I17: Hải Phòng | J17: 2000001913 - 1.200T - Thép Chính Đại (Sáng mùng 8/10 NK) 2000001876 - 300T - Trường Thành (Đã MAP 212T lương còn lại sáng mùng 8 NK) 2000001893 - OT190 - 300 tấn - cho đi hết hàng còn lại (Hàng hóa ok) 2200001436 - OTHY - 2.200T 2200001424 - THP cân tải | M17: .
A18: 13 | B18: HÀ DƯƠNG 58 | C18: 3080 | D18: 09-10.10.2023 Dỡ quặng | E18: Mặt Trời | F18: 09/10 Bến 3 | G18: Xong tàu | H18: Dung Quất | I18: Tân Thuận/Phú Mỹ | J18: 2400000379 - 1500mt - Phú Mỹ - Chuyển tải Xuất khẩu (206.2023/HWA) - Hàng hóa ok 2000001912 - Nam Kim - 1.500T - Tân Thuận - (Hàng hóa ok) Lên hàng Nam Kim sau, dỡ trước | K18: ETA/ ETD Phumy: 13 Oct 2023 (MV. KM Jakarta) Muộn nhất 10/10 tàu phải làm xong rời bến Nam kim xuát 1,500 MT Thép cuộn cán nóng 2.5x1158 SAE1006 | M18: .
A19: 14 | B19: MT HÀ NỘI 07 | C19: 2950 | D19: 08.10.2023 | E19: MT Hà Nội | F19: 09/10 Bến 3 | G19: Xong tàu | H19: Dung Quất | I19: Cẩm Nguyên/ Tân Thuận | J19: 2000001899 - VISA - 2000T (lệnh ok) - cân tải - Cẩm Nguyên (Chiều mùng 8 NK) 2000001912 - Nam Kim - 940T - Tân Thuận (6/10 NK) (Hàng hóa ok) Lên hàng Nam Kim sau để dỡ trước, tàu đi Tân Thuận trước | K19: Nam kim xuất 940mt Thép cuộn cán nóng 4.00 x 1125 SAE1006 | M19: .
A20: 15 | B20: HÀ DƯƠNG 68 | C20: 4400 | D20: 08-09.10.2023 | E20: Mặt Trời | F20: Tối 09/10 Bến 2 | G20: Xong tàu | H20: Dung Quất | I20: Long Bình | J20: 22000001439 - OTBD 2100T (Hàng hóa ok) 22000001441 - OTBD 2500T (Hàng hóa đã MAP 2487 TẤN) | K20: Thép cuộn cán nóng 2.20x1250 SAE1006 (Lệnh 1441) thiếu min (hết tồn) | M20: .
A21: 16 | B21: YASA MIMOSA | C21: 7000 | D21: 2h 11.10.2023 | E21: MORRIS | F21: 2h 11/10 Bến 6/11 | G21: LSD: 10 Oct | H21: Dung Quất | I21: Bilbao, Spain | J21: 2400000299 - 139.2023/HPDQ-THYSSEN - (Hàng hóa ok) x 2400000300 - 140.2023/HPDQ-CASSL - (Hàng hóa ok)x 2400000358 - 148.2023/HPDQ-GS (S275JR) - (Hàng hóa ok) x 2400000359 - 148.2023/HPDQ-GS (S235JR) - (Hàng hóa ok) x 2400000314 - 144.2023/HPDQ-PRIMEX - (Hàng hóa ok) x - GIANG 2400000302 - 143.2023/HPDQ-MSN - (Hàng hóa ok) x 2400000357 - 142.2023/HPDQ-INTERTRADE - (Hàng hóa ok) x 2400000383 - 151.2023/HPDQ-EUSIDER (S235JR) - (Hàng hóa ok) X 2400000380 - 151.2023/HPDQ-EUSIDER (S275JR) X 2400000306 - 152.2023 HPDQ-CASSL (Hàng hóa ok) x 2400000307 - 156.2023/HPDQ-TRASTEEL(S275JR) (Hàng hóa ok) x 2400000363- 156.2023/HPDQ-TRASTEEL (S235JR) (Hàng hóa ok) x 2400000364 - 156.2023/HPDQ-TRASTEEL (DD11) (Hàng hóa ok) x 2400000378 - 160.2023/HPDQ-HYUNDAI (Đổi từ lệnh 310 sang) | K21: TÀU CŨ: ROTTERDAM PEARL
A22: 17 | B22: GIA LĨNH 268 | C22: 11000 | D22: 08.10.2023 | E22: MT Hà Nội | F22: 11/10 Bến 5/10 | G22: Xong tàu | H22: Dung Quất | I22: Nghi Sơn/ Hải Phòng | J22: 20*1894, 1895 - Hoa Sen - 5.500T Nghi Sơn 2200001424 - THP 1500T (HP) làm trước dỡ sau (Hàng hóa ok) 2200001438 - THP 3050T (HP) làm trước dỡ sau (Hàng hóa ok) | K22: Tàu đi thiếu tải, xuất min 10kt | M22: .
A23: 18 | B23: MẠNH THẮNG 68 | C23: 4000 | D23: 12.10.2023 | E23: MT Hà Nội | F23: 12/10 Bến 1 | G23: Xong tàu | H23: Dung Quất | I23: Hải Phòng | J23: 2200001447 - THP đi hết | M23: .
A24: 19 | B24: VIỆT THUẬN QN-01 | C24: 6000 | D24: 13.10.2023 | E24: Mạnh Thắng | F24: 13/10 Bến 1 | G24: Xong tàu | H24: Dung Quất | I24: Phú Mỹ | J24: 2000001896 - Hoa Sen - 5.500 T (Hàng hóa ok) | K24: Tàu đi thiếu tải | M24: .
A25: 20 | B25: XIN HAI TONG 27 | C25: 700 | D25: 14.10.2023 | E25: Age-line | F25: 14/10 Bến 6/11 | G25: Xong tàu | H25: Dung Quất | I25: Belgium | J25: 2400000390 - P08863: 700mt to Belgium (lot 2) (Hàng hóa ok)
A26: 21 | B26: GLORY DYNASTY | C26: 5000 | D26: 11.10.2023 | E26: HOYER | F26: 20h 11/10 Bến 6 | G26: Xong tàu | H26: Dung Quất | I26: Surabaya, Indonesia | J26: 2400000385 - 206.2023 HPDQ-SI - 5kt (sunrise) (Hàng hóa ok)
A27: 22 | B27: VIỆT PHÚC 18 | C27: 3800 | D27: 16.10.2023 | E27: Mặt Trời | F27: 16/10 Bến 1 Làm từ từ cũng được | G27: Xong tàu | H27: Dung Quất | I27: Long Bình | J27: 2200001456 OTBD - 3.100T (Đã MAP 3.058 tấn) 2200001441 - OTBD 200T (Hàng hóa ok) | K27: Tàu đi thiếu tải | M27: .
A28: 23 | B28: VIỆT THUẬN 168 | C28: 16000 | D28: 15.10.2023 | E28: Mạnh Thắng | F28: 15/10 Bến 5 Phải xong hàng muộn nhất ngày 20/10 | G28: Xong tàu | H28: Dung Quất | I28: Tân Thuận/Phú Mỹ | J28: 2000001912 - Nam Kim - 10.000T - Tân Thuận (Đã MAP 9134 tấn) 2000001900 - TLPM - 1.500T - Phú Mỹ (lệnh ok) (Háng hóa ok) 2000001914 - PVX - 1.600t - Tân Thuận (Hàng hóa ok) Tàu đang còn thiếu tài 3kt, có hàng thì cho lên đây, không thì tàu chạy thiếu tải. | K28: Nam kim xuất 1,820mt Thép cuộn cán nóng 2.50 x 1158 SAE1006 và các size còn lại | M28: .
A29: 24 | B29: CHÍ DŨNG 68 | C29: 13000 | D29: 08.10.2023 | E29: Mặt Trời | F29: 20h00 17/10 Bến 6 | G29: Xong tàu Phải xong hàng muộn nhất ngày 20/10 | H29: Dung Quất | I29: Tân Thuận/Phú Mỹ | J29: 2000001915 - 171.2023 Posco - 3.600(3 lệnh) - Posco- tách 2 hóa đơn mác 2.3x1239 2000001923 - 171.2023 Posco - 1.000 (3 lệnh) - Posco (Hàng hóa ok) 2000001924 - 171.2023 Posco - 400 (3 lệnh) - Posco (Hàng hóa ok) 2000001916- TĐA - 5.000 T - Tân Thuận (Hàng hóa ok) 2000001917 - TĐA - 2.500 T - Phú Mỹ (Hàng hóa ok) Dỡ hàng như sau: Tân Thuận - Phú Mỹ - Posco | K29: LỆNH 2*1916 giữ hóa đơn về cảng TÂN THUẬN TOÀN BỘ HÓA ĐƠN CỦA TDA ĐỂ NGÀY HÓA ĐƠN muộn nhất là 20/10/2023 | M29: .
A30: 25 | B30: VIỄN ĐÔNG 88 | C30: 8300 | D30: 15.10.2023 | E30: Tuấn Cường | F30: 19/10 Bến 5 CTH | G30: Xong tàu Phải xong hàng muộn nhất ngày 20/10 | H30: CTH | I30: Hải Phòng/ Nghi Sơn | J30: Hàng gửi kho 585T (Liên hệ anh Danh) 2200001442,1443 OTHY 2200T (Đã MAP 2189 tấn + size 6.00x1500 SS400 II hết tồn) 2200001447 - THP (Đã MAP 3507 tấn) ưu tiên đi hết 2200001450 - NMCN 2800T (Đã MAP 2804 tấn) cân tải 2000001925 (SS400) - 2000001926 (SAE1006) KKBV - 950T (Hàng hóa ok) | K30: Tàu tây: GIORGOS DRACOPOULOS - Thanh Hóa 2400000325 - chưa xuất, chờ thông tin của PKD | M30: .
A31: 26 | B31: HOÀNG PHÚC 29 | C31: 3300 | D31: 14.10.2023 | E31: VTB Hải Dương | F31: 19/10 Bến 2 | G31: Xong tàu Phải xong hàng muộn nhất ngày 20/10 | H31: Dung Quất | I31: Phú Mỹ/ Thiên Lộc Thành | J31: 2000001920 - VNO - 1.000T - Thiên Lộc Thành (Đã MAP 788t + 200T 2.95x1200 chờ MAP) 2000001919 - Tây Nam - 1.000T - Thiên Lộc Thành (Hàng hóa ok) 2000001927 - PVX - 1.000T - Phú Mỹ (Hàng hóa ok) | K31: Tàu đi thiếu tải | M31: .
A32: 27 | B32: Glory Valor | C32: 4000 | D32: 22.10.2023 | E32: HOYER | F32: 17h 23/10 Bến 6 | G32: Xong tàu | H32: Dung Quất | I32: Kota Kinabalu Port | J32: 2400000387 -181.2023/HPDQ-MI (Hàng hóa ok) - lệnh ok 2400000386 -182.2023/HPDQ-MI (Hàng hóa ok) - lệnh chiều muộn 23 duyệt | K32: TÀU CŨ: GLORY VOYAGER/ GLory Pioneer Lưu ý: Load lệnh 2400000387 lên tàu trước -> Chốt BBGN trước để tàu ra Mate Receipt
A33: 28 | B33: MT HÀ NỘI 07 | C33: 3000 | D33: 23.10.2023 | E33: VTB Hải Dương | F33: 23/10 Bến 5 Phải xong hàng muộn nhất 30/10 | G33: Xong tàu | H33: Dung Quất | I33: Long Bình | J33: 2200001466 OTBD - 3.000T | M33: .
A34: 29 | B34: VIỆT THUẬN QN-01 | C34: 6000 | D34: Tối 23.10.2023 | E34: Mạnh Thắng | F34: Bến 5 Tàu về cần làm luôn | G34: Xong tàu | H34: Dung Quất | I34: Hải Phòng | J34: 2200001450 - NMCN 2800T (Hàng hóa ok) 2.30x1200/2.50x1200 thiếu min 2200001468 - OTHY 1270T (Chỉ MAP được 1223t) 2200001469 - OTHY cân tải (sáng 24/10 duyệt xong lệnh) 2400000325 120T - 174.2023 HPDQ-TRASTEEL - Hàng XK - Trả hàng ở Nghi Sơn, load hàng lên sau cùng để dỡ trước (Hàng hóa ok) | K34: Tàu tây: GIORGOS DRACOPOULOS - Thanh Hóa 2400000325 | M34: .
A35: 30 | B35: KOOKYANG EXPRESS | C35: 10000 | D35: 22.10.23 | E35: Age-line | F35: 26/10 Bến 6 | G35: Xong tàu | H35: Dung Quất | I35: Semarang, Indonesia | J35: 2400000395 - ARSEN.136 (Hàng hóa ok) 2400000388 - ARSEN.183 (BJPS) (Hàng hóa đã sx chờ MAP) 2400000392 - ARS.183 (BJPC)
A36: 31 | B36: VIỆT THUẬN 045-01 | C36: 4250 | D36: 26.10.2023 | E36: Mạnh Thắng | F36: 26/10 Bến 5 | G36: Xong tàu | H36: Dung Quất | I36: Cẩm Nguyên | J36: 2000001921 - TVP - 4.250T (Hàng hóa dự kiến chiều 25 NK) LỆNH TVP ĐÃ MAP TỔNG 10.144 TẤN | M36: .
A37: 32 | B37: GLORY JUSTICE | C37: 5000 | D37: 28.10.2023 | E37: HOYER | F37: 19h00 28/10 Bến 3/5 | G37: Xong tàu | H37: Dung Quất | I37: Surabaya, Indonesia | J37: 2400000391 - 207.2023 HPDQ-SI (Hàng hóa chỉ MAP được 4.704 tấn)
A38: 33 | B38: AMOY DREAM | C38: =35000+8500 -> 43500 | D38: 18h 22.10.2023 | E38: Age-line | F38: 2h 25/10 Bến 5/10 | G38: Xong tàu | H38: Dung Quất | I38: Marcegaglia's port, Italy | J38: 2400000389 - P09021 (LOT 1) - 8500mt -LSD 31/10 - đơn này chú ý điều chỉnh chỉ xuất 6500mt (Đã MAP 4k5 + 2kt đã sx chờ MAP ) 2400000381 - P08962 (S235JR) - 8400mt (có nhãn phụ) - LSD 31/10 (Đã MAP 7kT + 1K4 sáng 26 NK) 2400000382 - P08962 (SAE1006) - 26,600mt (Đã MAP 26K2) | K38: Có nhãn phụ + color mark - Dung sai: +/-5% (cả 3 lệnh)
A39: 34 | B39: VIỆT THUẬN 12-03 | C39: 12000 | D39: 26-27.10.2023 | E39: Mạnh Thắng | F39: 26/10 Bến 6 | G39: Phải xong hàng muộn nhất ngày 30/10 | H39: Dung Quất | I39: Hải Phòng | J39: 2000001902 - Phú Nam - 400 T - Hải Phòng (Hàng hóa ok) - Ra hàng muộn nhất 30/10 2000001925 (SS400) - 2000001926 (SAE1006) - KKBV - 1.000T (Hàng hóa ok) - Ra hàng muộn nhất 30/10 2000001930+2000001931: Thành Đạt T10 + 11 - 300T (Hàng hòa ok) - Ra hàng muộn nhất 30/10 2200001469 - OTHY 2700T (Đã MAP 4087 tấn) - Có thể ra hàng muộn nhất 31/10, không được muộn hơn 2200001448 - THP 790T (Hàng hóa ok) - Có thể ra hàng muộn nhất 31/10, không được muộn hơn 2200001463 - THP 3200T (Hàng hóa ok) - Có thể ra hàng muộn nhất 31/10, không được muộn hơn 2200001464 - THP 1000T (Đã MAP 1038) - Có thể ra hàng muộn nhất 31/10, không được muộn hơn 2200001465 - THP 2100T (Hàng hóa ok) cân tải- Có thể ra hàng muộn nhất 31/10, không được muộn hơn 2200001457 - OTHY 150T (Hàng hóa ok) - Có thể ra hàng muộn nhất 31/10, không được muộn hơn 2200001444/2200001473 - OTHY 1000T đi tối đa - Có thể ra hàng muộn nhất 31/10, không được muộn hơn (Dự kiến sáng 29 NK) | M39: .
A40: 35 | B40: PHƯƠNG NAM 98 | C40: 4700 | D40: 25.10.2023 Neo | E40: VTB Hải Dương | F40: 28/10 Bến 3 | G40: Phải xong hàng muộn nhất ngày 30/10 | H40: Dung Quất | I40: Thiên Lộc Thành | J40: 2000001929 - Tây Nam - 4.500T - Thiên Lộc Thành (Chiều 26 NK 3k8 + 700t sáng 27 NK) | M40: .
A41: 36 | B41: MT HÀ NỘI 39 | C41: 4300 | D41: 28.10.2023 | E41: MT Hà Nội | F41: Tối 29/10 Bến 5 | G41: Phải xong hàng muộn nhất 31/10 | H41: Dung Quất | I41: Tân Thuận/ Cẩm Nguyên | J41: 2200001458 OTHP (Cargill) - 1.000T - Tân Thuận (Hàng hóa ok) 2000001921 - TVP - 3.300T - cân tải (Chiều 24 NK) | K41: THAY THẾ TÀU VIỆT HÒA 68 | M41: .
A42: 37 | B42: GRAND FAMILY 18 | C42: 4300 | D42: 29.10.2023 | E42: Mạnh Thắng | F42: 30/10 Bến 5 | G42: Phải xong hàng muộn nhất 31/10 | H42: Dung Quất | I42: Cẩm Nguyên | J42: 2000001921 - TVP - 4.250T (Hàng hóa dự kiến chiều 25 NK) | K42: THAY THẾ TÀU VIỆT THUẬN 045-02 | M42: .
...

Sheet LỊCH TÀU - 03.2023
A2: CẬP NHẬT TÌNH HÌNH XUẤT HÀNG HRC THÁNG 03/2023
J3: =TODAY() -> 45987
A4: STT | B4: TÀU | C4: KHỐI LƯỢNG | D4: CẬP NHẬT TÌNH HÌNH/ETA | E4: ĐẠI LÝ | F4: CẬP NHẬT ETB | G4: Thời gian làm hàng dự kiến | H4: CẢNG XẾP | I4: CẢNG ĐẾN | K4: GHI CHÚ | L4: ĐẠI LÝ | M4: Thời gian DQ đáp ứng | N4: Mức độ | O4: =SUM(#REF!) -> #REF!
A5: {=_xlfn.SEQUENCE(30,1,1,)} -> #NAME? | B5: Phương nam 46 | C5: 3650 | D5: 13h00 02.03.23 Bến 2 | E5: NAM PHÁT | F5: Xong | H5: Dung Quất | I5: Cẩm Nguyên/Thiên Lộc Thành | J5: 2000001587 - TÂY NAM - 1800KT - 1/3 ĐỦ HÀNG - THIÊN LỘC THÀNH 2000001638 - TVP - CÂN TẢI TÀU - CẨM NGUYÊN
B6: PHƯƠNG NAM 98 | C6: 4620 | D6: 20h00 01.03.23 | E6: NAM PHÁT | F6: Xong | H6: Dung Quất | I6: Cẩm Nguyên | J6: 2000001638 - TVP - CÂN TẢI 2000001635 - MOV - 812T - 3/3 DUYỆT
B7: Viễn Đông 88 | C7: 8400 | D7: 04.03.23 Dỡ quặng | E7: Mặt Trời | F7: Xong | G7: GẤP | H7: Dung Quất | I7: Đà Nẵng | J7: 2200001245 OTĐN 108T 2200001255 OTĐN 2743T xuất âm 90% 2200001260 OTĐN 2700T 2200001264 OTĐN 1300T 2200001265 OTĐN cân tải SMC ĐN - 2000001639 - 950 tấn - xuất hết mapping 2000001636 - Thanh phú 208 MT | N7: Gấp
B8: Việt Thuận 168 | C8: 16300 | D8: 18h 06/03/2023 Bến 05 | E8: Mạnh Thắng | F8: Xong | G8: Cho tàu này vào làm trước VT12-03 | H8: Dung Quất | I8: HẢI PHÒNG | J8: 2200001254 - OTHY 3700T(Xuất âm khoảng 90%) 2200001248 - THP 3700T (Xuất âm khoảng 95%) 2200001268 - THP 7500T (Xuất âm khoảng 95%) cân tải 2200001263 - OTHY cân tải | K8: CỐ GẮNG CHO NHIỀU HÀNG ỐNG TÔN LÊN ĐỂ VỀ HOÀNG DIỆU | M8: =3700+3700+7000+2000*0.93 -> 16260
B9: Việt Thuận HN-01 | C9: 6000 | D9: 22h20 07.03.23 Bến 1 | E9: Mạnh Thắng | F9: Xong | G9: TẬP KẾT TỪ CA 2 NGÀY 07 | H9: Dung Quất | I9: Thiên Lộc Thành/CẨM NGUYÊN | J9: 2000001606 - METAL ONE - THIÊN LỘC THÀNH 2000001640 - MOV - THIÊN LỘC THÀNH 2000001646- MOV - THIÊN LỘC THÀNH 2000001638 - TVP - CÂN TẢI - 1200T - CẨM NGUYÊN - LÊN HÀNG SAU, DỠ TRƯỚC | K9: tổng 3 lệnh MOV lên đủ dung sai, ~95% | N9: =1000+2000+1500+500 -> 5000
B10: MT Hà Nội 07 | C10: 2950 | D10: 07.03.23 Dỡ phế > dỡ phế gấp để load hàng gấp lắm | E10: MT Hà Nội | F10: xong | G10: TẬP KẾT TỪ CA 2 NGÀY 08/03 ĐI Ạ | H10: Dung Quất | I10: Quy Nhơn | J10: 2000001660 - Hoa Sen 3000mt (lệnh mới)
B11: Việt Thuận 12-03 | C11: 12000 | D11: 20H30 ngày 08/03 Bến 5 | E11: Mạnh Thắng | F11: Xong | G11: CHẬM NHẤT SÁNG SỚM NGÀY 11/3 XONG | H11: Dung Quất | I11: Tân Thuận/Phú Mỹ | J11: 2000001652 - PVX 3000MT - PHÚ MỸ 2000001661 - PVX 2000MT - PHÚ MỸ 2000001650 - Phú Mỹ - Tấm Lá 1000MT 10/03 có hàng 2000001631 - Tôn Đông Á - 3000t PHÚ MỸ 2000001649 - THE ONE 660T PHÚ MỸ 2000001655 - POSCO - 300T - PHÚ MỸ - C OANH GỬI CHỨNG TỪ HỘ 2000001641 - JFE - 560T TÂN THUẬN 2000001654 - TĐA - 1500T - PHÚ MỸ 2200001274 - OTBD cân tải Tân Thuận | K11: Tàu này cuối ngày 07/03 cho vào làm hàng sẽ hợp lý DỠ Ở PHÚ MỸ TRƯỚC | M11: =3000+2000+1000+660+3000+560+1500 -> 11720
B12: Việt Thuận 12-02 | C12: 12300 | D12: 08:00 ngày 10.03 Bến 05 | E12: Thiên Phúc | F12: Xong | H12: Dung Quất | I12: HẢI PHÒNG | J12: 2000001617 - TVD 3000MT 2000001618 - OTVD - 3000MT 2000001643 - OT190 - 1100MT 10/3 duyệt 2000001644 - OT190 - 500MT 10/3 duyệt 2000001651 - Maru - Việt Nhật ngày 07/03 duyệt - 2000mt 2200001214 - OTHY hàng gửi kho 70T theo list hàng của PKD đi hết 2200001266 - OTHY 144T đi hết 2200001263 - OTHY (4300mt) (giao âm 90%) đi hết
B13: TRAWIND WISDOM | C13: 3000 | D13: 11.03.23 | E13: Việt Long | F13: Xong | G13: khoảng chiều/tối 13/03 làm xong hàng cho tàu rời cầu giúp em ạ. Phản hồi: Sáng 13/03 xong nha Lan Anh. Sớm để 215-06 vào. | H13: Dung Quất | I13: Port Klang | J13: Xuất như mapping 2400000032 - CIEC 750MT 2400000033 - CIEC 800MT 2400000034 - CIEC 850MT 2400000035 - CIEC 250MT 2400000036 - CIEC 200MT 2400000037 - CIEC 150MT | K13: có nhãn phụ. Khi nào xuất báo KCS
B14: Mạnh Thắng 68 | C14: 3940 | D14: 14:30 ngày 12/03 Bến 2 | E14: MT Hà Nội | F14: Xong | H14: Dung Quất | I14: TTL và TÂN THUẬN | J14: 2000001587 - TÂY NAM-2k9 2000001642 - Tiến Lên 1000MT 13/3 thanh toán - Tân Thuận | K14: =3000+863 -> 3863
B15: MT Hà Nội 39 | C15: 4250 | D15: 17:00 ngày 13/03 Bến 01 | E15: MT Hà Nội | F15: Xong | H15: Dung Quất | I15: HẢI PHÒNG | J15: 22*1271 - THP 187T 22*1270 - OTHP - 4100MT Ưu tiên 3.8-4.0
B16: MT Hà Nội 07 | C16: 2950 | D16: 13.03.23 Quay đầu nhận HRC | E16: MT Hà Nội | F16: Xong | H16: Dung Quất | I16: Cẩm Nguyên | J16: không hiểu duyên sự gì mà cái tàu này cứ bị xóa lệnh đi 2000001638 - TVP - CÂN TẢI 2000001657 - MOV (Toàn Thắng) - 144 mt
B17: Việt Thuận 215-06 | C17: 12800 | D17: 18:45 ngày 13/03 Bến 5 | E17: Mạnh Thắng | F17: Xong | H17: Dung Quất | I17: Tân Thuận/PHÚ MỸ | J17: 2000001662 - PVX T2 - 1700MT tân thuận - ngày 13/3 xử lý 2200001257 - OTHY 6700mt (xuất âm 95%) - tân thuận 2000001658 - Tôn Đông Á - 1470mt - Phú Mỹ + Tân Thuận 2200001214- OTHY 300T hàng gửi kho theo list hàng của anh Danh (Tân Thuận) 2200001274 - OTBD cân tải là 1800mt 2000001628 - SMCCK - XUẤT HẾT MAPPING - PHÚ MỸ 2000001655 - Posco 50MT - PHÚ MỸ - đã duyệt lệnh | K17: 2*1658: MÁC 2.80X1264 - 300T ĐI THÂN THUẬN, CÒN LẠI ĐI PHÚ MỸ | M17: =12800-1700-6700-1500-800-300 -> 1800
B18: Tay Son 1 | C18: 12000 | D18: 09:25 ngày 16/03 Bến 05/10 | E18: Age-line | F18: Xong | H18: Dung Quất | I18: Jakarta | J18: 2400000041 - AMI 12kt
B19: Việt Thuận 168 | C19: 16300 | D19: 13:00 ngày 16/03 Bến 05 | E19: Mạnh Thắng | F19: Xong | H19: Dung Quất | I19: HẢI PHÒNG | J19: 2200001268,1269 - THP 7300mt cân tải (lưu ý k xuất vượt 95%) 2200001275 - OTHY 5000T 2200001272 - NMCN 3000T 2200001276 - OTHY 1000T
B20: Hà Dương 58 | C20: 3080 | D20: 16:30 ngày 17/03 Bến 3 | E20: Mặt Trời | F20: Xong | H20: Dung Quất | I20: Đà Nẵng | J20: 2200001265 - OTĐN 2090T 2200001273 - OTĐN Cân tải
B21: Phương Nam 98 | C21: 4620 | D21: 19.03.2023 | E21: NAM PHÁT | F21: Xong | H21: Dung Quất | I21: HẢI PHÒNG | J21: 2200001262 - OTHY 1300T 2200001270 - OTHY 1200T cân tải 2200001214 - OTHY 397T hàng gửi kho liên hệ anh Danh 2200001263 - OTHY 2000T
B22: Hải Âu 28 | C22: 5000 | D22: 07:30 ngày 21/03 Bến 5 | E22: Mặt Trời | F22: Xong | H22: Dung Quất | I22: HẢI PHÒNG | J22: 2000001623 - HÙNG NGUYÊN 2000001674 - hùng nguyên -150 2200001277 - OTHY 4000T - CÂN TẢI 2000001618 - TVD 300MT (chiều 21/03 nhập kho)
B23: Hà Dương 58 | C23: 3100 | D23: 13:45 ngày 22/03 Bến 3 | E23: Mặt Trời | F23: XOng | H23: Dung Quất | I23: Hải Phòng | J23: 2200001275 - OTHY 1000T cân tải 2200001268,1269 - THP 900T 2000001672 - Phú Nam - 1450MT 22-23/3 nhập kho 2000001673 - Trường Thành 475MT - 375MT sáng 23/3 nhập kho
B24: Hải Dương 99 | C24: 3950 | D24: 03:50 ngày 23/03 Bến 1 | E24: MT Hà Nội | F24: XOng | G24: Ưu tiên dỡ hàng để vào làm HRC sớm | H24: Dung Quất | I24: Đà Nẵng | J24: 2200001214 - OTHY 875MT (HÀNG GỬI KHO) 2200001273 - OTDN 3820MT CÂN TẢI
B25: UNISON | C25: 11350 | D25: 08h30 ngày 23/03 Bến 05 | E25: CLIO | F25: XOng | H25: Dung Quất | I25: Jakarta/Surabaya | J25: Steel-Invest 2400000050 - Surabaya 2400000049 - Jakarta 2400000048 - Jakarta 2400000047 - Surabaya 2400000046 - Jakarta 2400000045 - Surabaya 2400000044 - Jakarta 2400000043 - Jakarta 2400000042 - Jakarta xếp riêng 1 LOT để dỡ hàng riêng 2400000051 - Surabaya | K25: Không cần phân biệt lệnh ABC và hầm XYZ. Chỉ cần phân bổ theo đúng cảng dỡ. Tuy nhiên, riêng lệnh 24*42 cần gom lại 1 hầm để dỡ hàng
B26: Việt Thuận 12-01 | C26: 10670 | D26: Neo | E26: Mạnh Thắng | F26: Xong tàu | H26: Dung Quất | I26: Hải Phòng | J26: 2200001275 - OTHY đi hết 2000001686 - Tấn Phát - 1000MT (26 NK) 2000001678 - Nhật Quang - 980MT 22-23/3 nhập kho 2000001644 - OT190 - 950MT 2000001683 - NIPPON - 200T 2000001647 - KKBV 7000MT - cân tải | K26: =10670-1000-980-950-200 -> 7540
B27: MT Hà Nội 39 | C27: 4250 | D27: 26.03.2023 | E27: MT Hà Nội | F27: Xong tàu | G27: Xong tàu | H27: Dung Quất | I27: Phú Mỹ | J27: 2000001684 - JFE - PHÚ MỸ - 500 (Hàng hóa ok) 2000001685 - TDA - PHÚ MỸ - 700 (Hàng hóa ok) 2000001702 - KN 1000MT - phú mỹ (Hàng hóa ok) 200001676 và 200001628 (xuất nốt lượng còn lại) - SMCCK (Hàng hóa ok) - PHÚ MỸ 2000001696 - TĐA - PHÚ MỸ - 1000 (Hàng hóa ok) | K27: =4250-1180-980-1080 -> 1010
B28: Việt Thuận 215-06 | C28: 12800 | D28: Neo | E28: Mạnh Thắng | F28: Xong tàu | H28: Dung Quất | I28: Hải Phòng | J28: 2000001647 - KKBV (Hàng hóa ok) đã duyệt lệnh - lưu ý tách hóa đơn với tàu VT12-01 2000001691 - OTVD 2000MT (Đã MAP đủ hàng) 2000001680 - Nam Phát 4000mt (Hàng hóa ok) - đã duyệt lệnh 2000001690 - TMP 1000MT (đã duyệt lệnh, đã MAP đủ hàng) 2200001282 - OTHY 400T (Hàng hóa ok) - đã duyệt lệnh 2200001270 - OTHY 220T - đã duyêt lệnh 2000001682 - VINAS - 700T (Hàng hóa ok) 22*1268 + 22*1269 - THP cân tải
B29: Phương Nam 98 | C29: 4620 | D29: 08h00 27.03.2023 | E29: NAM PHÁT | F29: Xong tàu | H29: Dung Quất | I29: Long Bình/Cẩm Nguyên | J29: 2200001274 - OTBD 928T (Hàng hóa ok) - LONG BÌNH 2000001687 - VISA 400MT chiều muộn 27/3 duyệt - Cẩm Nguyên (Hàng sẵn trong kho rồi) 2000001704- VISA - 600T - Cẩm Nguyên 9-10h sáng 29/03 duyệt lệnh 2200001284 - OTBD - LONG BÌNH cân tải ~ 2700T (Hàng hóa ok) | K29: =C29-928-900 -> 2792
B30: Việt Thuận HN-01 | C30: 6000 | D30: 23h00 26.03.2023 | E30: Mạnh Thắng | F30: Xong tàu | H30: Dung Quất | I30: Tân Thuận | J30: 2000001613 - CTC 1500MT (Hàng hóa ok) 2000001693 - Kỳ Đồng: 1000mt (Hàng hóa ok) 2000001694 - JFE - 27/3 DUYỆT -2500 (Hàng hóa ok) 2000001695 - TĐA - 27/3 duyệt lệnh -1000 (Còn thiếu 200t chiều nay NK đủ) 2200001284 - OTBD - TÂN THUẬN - cân tải (Hàng hóa ok)
B31: Hải Dương 99 | C31: 3950 | D31: 09H00 29.03.2023 | E31: MT Hà Nội | F31: Xong tàu | H31: Dung Quất | I31: Quy Nhơn | J31: 2000001653 - Hoa Sen 8000mt - Ưu tiên sản xuất đơn của Hoa Sen nhé a Được (Đã MAP được 5kt LƯỢNG + 2.5KT còn lại sáng 30 NK đủ)
B32: Mạnh Thắng 68 | C32: 3950 | D32: 14H00 29.03.23 | E32: MT Hà Nội | F32: Xong tàu | H32: Dung Quất | I32: Quy Nhơn | J32: 2000001653 - Hoa Sen 8000mt - Ưu tiên sản xuất đơn của Hoa Sen nhé a Được (Đã MAP được 5kt LƯỢNG + 2.5KT còn lại sáng 30 NK đủ)
B33: MT Hà Nội 07 | C33: 2950 | D33: RA HẾT LƯỢNG TÀU NÀY ĐỂ CHỐT TRONG THÁNG 3 | E33: MT Hà Nội | F33: Xong tàu | H33: Dung Quất | I33: Tân Thuận/ PHÚ MỸ | J33: 2000001697 - Nam Kim 2800mt - tân thuận (Chiều 30 NK 2K4 + 400T sáng 31 NK) - Cân tải 2000001663 - SMCGCT - 700MT - đi Phú Mỹ (Hàng hóa ok) - lệnh ok - ĐI PHÚ MỸ
A34: 32 | B34: TTP 89 | C34: 6400 | D34: 12h30 31.03 | E34: Sunrise | F34: Xong tàu | H34: Dung Quất | I34: Klang Port | J34: 2400000052 - GS (Hàng hóa ok) 2400000053 - GS (Hàng hóa ok) 2400000054 (Hàng hóa ok) 2400000055 (Hàng hóa ok) | K34: Lệnh có nhãn phụ báo KCS dán giúp e ạ
D35: CHÚ Ý, TẤT CẢ CÁC LỆNH ĐỀU PHẢI GIAO HÀNG ÂM TỐI ĐA GIAO ÂM TỨC LÀ GIAO THẤP HƠN SO VỚI LƯỢNG TRÊN LỆNH KHÔNG PHẢI CẮT HÀNG ÂM TRÊN BK ĐÂUUUU
J40: VINAS 2000MT 2000001648 - KKBV 1500MT

Sheet LỊCH TÀU - 12.2022
A2: CẬP NHẬT TÌNH HÌNH XUẤT HÀNG HRC THÁNG 12/2022
C3: =SUBTOTAL(9,C5:C288) -> 139861 | J3: =TODAY() -> 45987
A4: STT | B4: Tàu | C4: KHỐI LƯỢNG | D4: CẬP NHẬT TÌNH HÌNH/ETA | E4: CẬP NHẬT ETB | F4: Thời gian làm hàng dự kiến | G4: CẢNG XẾP | H4: CẢNG ĐẾN | I4: LỆNH XUẤT HÀNG | J4: GHI CHÚ | K4: Mức độ | L4: ĐẠI LÝ | M4: KL | N4: TỔNG HỢP | O4: =SUM(#REF!) -> #REF!
A5: {=_xlfn.SEQUENCE(30,1,1,)} -> 1 | B5: Viễn Đông 88 | C5: 8075 | D5: Xong | E5: 20h00 ngày 30/11 Bến 5 | G5: Dung Quất | H5: Hải Phòng | I5: 2000001406 - CTC 1500MT 2000001501 - MI (TP) 1800MT (1/12 duyệt) 2000001479 - HÙNG NGUYÊN 2000001419 - HÙNG NGUYÊN 2200001205 - NMCN 475MT 2000001448 - TMN cân tải (2000mt) (1/12 duyệt) 2000001464 - NIPPON - T6 DUYỆT 2000001504 - VINAS - 150T | L5: Mặt Trời | N5: =8075-1500-1800-2000-475-200-150 -> 1950
A6: 2 | B6: MT Hà Nội 07 | C6: 3000 | D6: Xong | E6: 20h00 ngày 01/12 Bến 2 | G6: Dung Quất | H6: Long An/Long Bình | I6: 2000001491 - MITSUI (LONG AN) 2200001196 - OTBD 1770T (LONG BÌNH) 2200001204 - OTBD cân tải (LONG BÌNH) | L6: MT Hà Nội
A7: 3 | B7: MT Hà Nội 39 | C7: 4250 | D7: Xong | E7: 14h00 ngày 02/12 Bến 1 | G7: Dung Quất | H7: Tân Thuận | I7: 2000001506 - JFE - đi hết mapping 2000001502 - TĐA - lấy hàng 2.00x1254 cân tải | J7: HÀNG MỚI SẢN XUẤT CHƯA LÀM ĐƯỢC, THỨ 6 LÀM | L7: MT Hà Nội
A8: 4 | B8: Mạnh Thắng 68 | C8: 3940 | D8: Xong | E8: ngày 04/12 Bến 2 | G8: Dung Quất | H8: Hải Phòng | I8: 2000001448 - TMN cân tải | L8: MT Hà Nội
A9: 5 | B9: Việt Thuận 12-01 | C9: 11800 | D9: Đang làm hàng | E9: 13h30 ngày 06/12 Bến 5 | G9: Dung Quất | H9: Hải Phòng | I9: 2000001448 - TMN 3850MT 2000001518 - PVX 5000MT 2000001519 - KN 195MT 2000001508 - PVX 650MT 2000001400 - Trường Thành 275MT 2000001522 - Phúc Viên Xuân 950MT 2000001521 -VINAS - 300T - lên hàng cuối cùng để dỡ hàng trước 2000001522 - PVX - 1000MT 2200001207 - NMCN cân tải | L9: Mạnh Thắng | N9: =C9-5000-3850-650-275 -> 2025
A10: 6 | B10: JIN DE 5 | C10: 5500 | D10: Xong | E10: 08h20 ngày 10/12 Bến 5 | G10: Dung Quất | H10: Jakarta | I10: 2400000027 - Samsung | J10: Có ghép WRHC | L10: CLIO
A11: 7 | B11: Việt Thuận HN-01 | C11: 6000 | D11: Xong | E11: 20h00 ngày 10/12 bến 1 | G11: Dung Quất | H11: Hải Phòng | I11: Đi hết lượng hàng gửi kho của OTHP (khoảng 5800T) Thiếu tải thì đi lệnh 2200001207 - NMCN cân tải | L11: THIÊN PHÚC
A12: 8 | B12: MT HÀ NỘI 39 | C12: 4250 | D12: Xong | E12: 10h10 ngày 11/12 Bến 2 | G12: Dung Quất | H12: LONG BÌNH | I12: 2200001204 - OTBD 1200T 2200001209 - OTBD cân tải - ưu tiên đi hàng tháng 05,06,07,08 trước | L12: MT Hà Nội
A13: 9 | B13: Việt Thuận 11-02 | C13: 10200 | D13: Xong | E13: 16h00 ngày 07/12 Bến 3 | G13: Dung Quất | I13: 2000001442- Citicom 600mt - tân thuận 2000001498 - Sunsco 300mt - tân thuận 2000001502 - TĐA 250MT - tân thuận 2000001490 - Tiến Lên 500Mt - tân thuận 2000001415 - quang mười 1000t - tân thuận 2200001202 - OTHY 1650T Tân Thuận chờ KCS gỡ map đủ lượng như trên mới xuất 2200001206 - OTHY 550T Tân thuận 2000001513 - SMC - PHÚ MỸ 2000001516 - QM 1200t - 2000001525 - SMCCK 400mt (gấp hơn) 2000001524 - SMCCK 2300mt (CÂN TẢI) | J13: =600+300+250+500+1000+2200+1200+800 -> 6850 | L13: Mạnh Thắng
A14: 10 | B14: HẢI AN 68 | C14: 4320 | D14: Xong | E14: 02h00 ngày 16/12 Bến 1 | G14: Dung Quất | H14: Long Bình | I14: 2200001209 - OTBD 2400T 2200001210 - OTBD 190T 2200001213 - OTBD cân tải | J14: BÊN | L14: Mặt Trời
A15: 11 | B15: Việt Thuận 215-06 | C15: 16000 | D15: Xong | E15: 08h00 ngày 13/12 Bến 05 | G15: Dung Quất | H15: Hải Phòng | I15: 2200001207 - NMCN 2000001511 - VINAS - 500T 2200001208 - OTHY - cân tải | L15: Mạnh Thắng
A16: 12 | B16: Trường Hưng 556 | C16: 11050 | D16: Xong | E16: 17h00 ngày 20/12 Bến 05 | G16: Dung Quất | H16: Hải Phòng | I16: 2000001500 - CTC 1500MT 2200001217 - THP 5100T 2200001216 - THP cân tải 2000001463 - HÙNG NGUYÊN - 300T (chiều mai) 2000001510 - Việt Đức 2000mt | L16: Nam Phát
A17: 13 | B17: Mạnh Thắng 68 | C17: 3750 | D17: Xong | E17: 17h00 ngày 20/12 Bến 2 | G17: Dung Quất | H17: Long Bình | I17: 2200001209 - OTBD 400T 2200001213 - OTBD cân tải ghép hàng WR CLC - Đăng | L17: MT Hà Nội
A18: 14 | B18: Việt Thuận 215-01 | C18: 15000 | D18: Xong | E18: 20h00 ngày 16/12 Bến 3 | G18: Dung Quất | H18: Hải Phòng | I18: 2200001212 - NMCN 2200001216 - THP cân tải 2000001526 - PVX 2000MT - chiều nay duyệt 2000001527 - KKBV 21/12 duyệt 2000001529 - KKBV 21/12 duyệt | L18: Mạnh Thắng
A19: 15 | B19: LIANSON DYNAMIC | C19: 6500 | D19: Xong | E19: 18h30 ngày 16/12 Bến 11 | G19: Dung Quất | H19: Jakarta | I19: 2400000028 - Samsung CnT - Lệnh dã duyệt | L19: Ageline
A20: 16 | B20: Hoàng Minh 68 | C20: 4000 | D20: Xong | E20: 20h00 ngày 22/12 Bến 1 | G20: Dung Quất | H20: Hải Phòng | I20: 2200001208 - OTHY 200T 2200001211 - OTHY 1670T 2200001218 - OTHY 140T 2200001216 - THP cân tải | L20: MT Hà Nội
A21: 17 | B21: VINACOMIN CẨM PHẢ | C21: 6770 | D21: Xong | E21: Thế lot VT215-01 (21/12) Bến 3 | G21: Dung Quất | H21: Phú Mỹ/Tân Thuận | I21: 2000001524 - SMCCK 2320mt 2000001453 - SMCCK 2000MT - sáng 22/12 duyệt 2200001213 - OTBD 280mt - Tân Thuận | K21: =2320+2000+280 -> 4600 | L21: THIÊN PHÚC
A22: 18 | B22: Việt Thuận 215 - 03 | C22: 1000 | D22: Xong | F22: Xong HRC trong 2022 | G22: Dung Quất | H22: Tân Thuận | I22: 2200001221 - OTBD Làm HRC chậm bị a Công chửi đấy | J22: Ghép cùng với thép XD Làm HRC nhanh để ko ảnh hưởng KH của thép XD | L22: Mạnh Thắng
A23: 19 | B23: MT Hà Nội 39 | C23: 4250 | D23: Xong | E23: 12h00 ngày 27/12 Bến 5 | G23: Dung Quất | H23: Thiên Lộc Thành | I23: 2000001475 - VNO - đi đủ dung sai các mác (~1680) 2000001530 - VNO - đi đủ dung sai các mác (~2389) 2000001476 - VNO - đi đủ dung sai (~158t) | K23: =1680+2390+158 -> 4228 | L23: MT Hà Nội
A24: 20 | B24: Viễn Đông 88 | C24: 7206 | D24: Xong | E24: 07h45 ngày 29/12 Bến 5 | F24: Xong trong 2022 | G24: Dung Quất | H24: Hải Phòng | I24: 2200001216 - THP 3106MT 2000001389 - THACO 1200MT 2200001220 - NMCN 2900T | J24: Lệnh hàng okay đẩy vô chốt năm 2022 đi các anh! | K24: =3106+1200+2900 -> 7206 | L24: Mặt Trời
A25: 21 | B25: MT Hà Nội 07 | C25: 3000 | D25: Xong | E25: 07H00 ngày 30/12 Bến 3 | F25: Xong trong 2022 | G25: Dung Quất | H25: Hải Phòng | I25: 2000001332 - OT190 1700MT 2200001219 - OTHY 400T | L25: MT Hà Nội
A26: 22
A27: 23
A28: 24
A29: 25
A30: 26 | I30: 2000001532 - THACO 875MT
A31: 27
A32: 28
A33: 29
A34: 30

Sheet LỊCH TÀU - 11.2022
A2: CẬP NHẬT TÌNH HÌNH XUẤT HÀNG HRC THÁNG 11/2022
C3: =SUBTOTAL(9,C5:C303) -> 195736 | J3: =TODAY() -> 45987
A4: STT | B4: Tàu | C4: KHỐI LƯỢNG | D4: CẬP NHẬT TÌNH HÌNH/ETA | E4: CẬP NHẬT ETB | F4: Thời gian làm hàng dự kiến | G4: CẢNG XẾP | H4: CẢNG ĐẾN | I4: LỆNH XUẤT HÀNG | J4: GHI CHÚ | K4: Mức độ | L4: ĐẠI LÝ | M4: KL | N4: TỔNG HỢP | O4: =SUM(#REF!) -> #REF!
A5: {=_xlfn.SEQUENCE(30,1,1,)} -> 1 | B5: GAILLARDIA SW | C5: 12000 | D5: Xong | E5: 06h25 ngày 28/10 Bến 05 | F5: 44572 | G5: Dung Quất | H5: Jakarta | I5: 2500000000 - HPI (Samsung CnT) | K5: BÌNH THƯỜNG | L5: Ageline
A6: 2 | B6: VIỆT THUẬN 235-01 | C6: 14370 | D6: Xong | E6: 19h30 ngày 30/10 Bến 05 | F6: Trưa 3/11/2022 | G6: Dung Quất | H6: Hải Phòng | I6: 2000001363 - Minh Ngọc 10kt 2000001444 - Nhật Quang 1000MT - chưa sản xuất đủ 2200001171 - NMCN 6100T cân tải | J6: HUY | K6: BÌNH THƯỜNG | L6: Mạnh Thắng
A7: 3 | B7: VIỆT THUẬN 11-01 | C7: 10200 | D7: Xong | E7: 6h20 ngày 02/11 Bến 03 | F7: dự kiến 03/11 | G7: Dung Quất | H7: Tân Thuận | I7: 2000001373 - Nam Kim - 5000t - 1/11 duyệt 2000001408 - VISA 3000T 2000001446 - Tiến Lên 2000MT chiều 2/11 duyệt | J7: =C7-5000-3000-2000 -> 200 | K7: BÌNH THƯỜNG | L7: Mạnh Thắng
A8: 4 | B8: Mạnh Thắng 68 | C8: 3940 | D8: Xong | E8: 17h30 ngày 02/11 Bến 1 | G8: Dung Quất | H8: Thiên Lộc Thành | I8: 2000001123 - VNO - 1000t - không vượt lệnh 2000001439 - VNO - 1000t - không vượt lệnh 2000001457 - VNO - 650t - không vượt lệnh 2000001429 - TÂY NAM - 1600 - cân tải đủ dung sai | K8: BÌNH THƯỜNG | L8: MT Hà Nội | N8: =C8-1000-800-650 -> 1490
A9: 5 | B9: MT Hà Nội 07 | C9: 3000 | D9: Xong | E9: 0h45 ngày 03/11 Bến 2 | G9: Dung Quất | H9: Long Bình | I9: 2200001160 - OTBD 430T 2200001180 - OTBD cân tải | K9: BÌNH THƯỜNG | L9: MT Hà Nội
A10: 6 | B10: Việt Thuận 215-06 | C10: 16000 | D10: Xong | E10: 16h30 ngày 03/11 Bến 05 | F10: Dự kiến 07/11 | G10: Dung Quất | H10: Hải Phòng | I10: 2000001430 - TMP 1900T 2000001455 - TMP 600T 2200001172 - NMCN 1500T 2200001171 - NMCN 2700T 2200001181 - OTHY 1800T 2000001450 - VINAS - không vượt lệnh 2000001432 - VINAS - không vượt lệnh 2000001467 - Trường Thành 25T 2000001468 - VINAS 2200001170 - THP cân tải (đi hết 2.45x1212, Không xuất 1052,1106) - 6200mt | J10: LỆNH VINAS, TRƯỜNG THÀNH LÊN CUỐI CÙNG ĐỂ DỠ HÀNG TRƯỚC | K10: NHANH CHÚT | L10: Mạnh Thắng | N10: =16000-1900-600-1500-2700-1800-800-600 -> 6100
A11: 7 | B11: VINACOMIN CẨM PHẢ | C11: 6770 | D11: Xong | E11: 17h40 ngày 05.11 Bến 5 | G11: Dung Quất | H11: Hải Phòng | I11: 2000001242 - OT190 - 3000MT 2200001182 - NMCN 1800MT 2200001170 - THP cân tải (Xuất hàng 1212) | J11: =6770-3000-1800 -> 1970 | K11: BÌNH THƯỜNG | L11: Thiên Phúc
A12: 8 | B12: MT Hà Nội 39 | C12: 4250 | D12: Xong | E12: 11h45 ngày 07/11 Bến 1 | G12: Dung Quất | H12: Long Bình | I12: 2200001186 - OTBD cân tải (Long Bình) | J12: Mọi người cân đối cho làm hàng | K12: BÌNH THƯỜNG | L12: MT Hà Nội
A13: 9 | B13: Việt Thuận 11-02 | C13: 10200 | D13: Xong | E13: 08h30 ngày 08/11 Bến 05 | F13: ngày 10/11 | G13: Dung Quất | H13: Hải Phòng | I13: 2000001407 - Phúc Tiến 1000MT 2200001171 - NMCN 70MT 2200001181 - OTHY 1828 MT - đã duyệt 2200001184 - NMCN Cân tải | J13: HUY CHECK LẠI PHÁT NHÉ | K13: BÌNH THƯỜNG | L13: Mạnh Thắng
A14: 10 | B14: MT Hà Nội 07 | C14: 3000 | D14: Xong | E14: 03h00 ngày 09/11 Bến 2 | G14: Dung Quất | H14: Tân Thuận,Long Bình | I14: 2200001178 - OTHY 2000T đi Tân Thuận 2000001362 - SUNSCO 300MT - chút duyệt 2200001186 - OTBD cân tải Đi Long Bình | J14: =3000-2000-300 -> 700 | K14: BÌNH THƯỜNG | L14: MT Hà Nội | N14: =3000-2000-560 -> 440
A15: 11 | B15: Việt Thuận HN-01 | C15: 6000 | D15: Xong | E15: 20h30 ngày 09/11 Bến 05 | G15: Dung Quất | H15: Hải Phòng | I15: 2000001217 - KKBV 2600MT (bỏ lại SAE1006) - chỉ xuất khoảng 2500mt thôi - 09.11 duyệt 2200001064 2.85x1500:22.544T, 5.7x1500:156.578T (Hàng gửi kho OTHP) 2200001085 5.6x1520:42.278T(Hàng gửi kho OTHP) 2200001072 4.2x1500:47.728T, 4.3x1500:23.864T (Hàng gửi kho OTHP) 2200001121 6.75x1500: 22.754T (ID: 71220705620) (Hàng gửi kho OTHP) 2200001184 - NMCN - Xuất hết mapping 2200001183 - OTHY - cân tải | J15: =6000-2500-293 -> 3207 | K15: BÌNH THƯỜNG | L15: Thiên Phúc
A16: 12 | B16: Mạnh Thắng 68 | C16: 3500 | D16: Xong | E16: 03h15 ngày 11/11 Bến 2 | G16: Dung Quất | H16: Long Bình | I16: 2200001180 - OTBD 560T 2200001186 - OTBD lượn còn lại 2000T 2200001190 - OTBD cân tải | K16: BÌNH THƯỜNG | L16: MT Hà Nội
A17: 13 | B17: Việt Thuận 215-06 | C17: 16000 | D17: Xong | E17: 10h50 ngày 12/11 Bến 05 | G17: Dung Quất | H17: Hải Phòng | I17: 2200001170 - THP 4400T 2000001465 - TCĐ 4080T 2200001189 - THP 1240T 2200001191 - OTHY 660T 2200001192 - NMCN 1900T 2000001417 - Mỹ Việt 3000mt T2 2000001451 - VINAS 2000001397 - VINAS - | K17: BÌNH THƯỜNG | L17: Mạnh Thắng | N17: =4400+4080+1240+660+1900+3000 -> 15280
A18: 14 | B18: MT HÀ NỘI 39 | C18: 4250 | D18: Xong | E18: 15h00 ngày 16/11 Bến 1 | G18: Dung Quất | H18: Long Bình | I18: 2200001190 - OTBD 2200001196 - OTBD | K18: BÌNH THƯỜNG | L18: MT Hà Nội
A19: 15 | B19: MT Hà Nội 07 | C19: 3000 | D19: Xong | E19: 02h15 ngày 18/11 Bến 01 | F19: Sáng ngày 19/11 | G19: Dung Quất | H19: Long Bình & Phú Mỹ | I19: 2200001196 - OTBD cân tải - (Long Bình) đã duyệt 2000001441 - SMCPM - 1000MT - Phú Mỹ 16.11 duyệt 2000001329 - POSCO 200MT - phú mỹ 17.11 duyệt 2000001434 - THE ONE 670T - phú mỹ 16.11 duyệt | J19: Dỡ Phú Mỹ trước, Tân Thuận sau => Xếp hàng OTBD trước | K19: HƠI GẤP | L19: MT Hà Nội
A20: 16 | B20: Hồng Lĩnh 01 | C20: 8000 | D20: Xong | E20: 01h30 ngày 17/11 Bến 05 | F20: Chiều ngày 19/11 | G20: Dung Quất | H20: Hải Phòng | I20: 2000001376 - NIPPON - 300T 2000001474 - nam phát 2000001473 - nam phát 2000001459 - nam phát 2200001183 - OTHY cân tải 1000mt | J20: cho tàu vào đi hôm nay đủ lệnh | K20: NHANH CHÚT | L20: Nam Phát
A21: 17 | B21: VINACOMIN CẨM PHẢ | C21: 6770 | D21: Xong | E21: 13h00 ngày18/11, Cập bến 3 | G21: Dung Quất | H21: Tân Thuận | I21: 2000001334 - SMCTT 2000MT (tân thuận) 2000001462 - NGUYỄN MINH - 1500T (tân thuận) 2000001483 - QH PLUS - 500T (tân thuận) 2200001200 - OTHY - 700T (Tân thuận) 2000001375 - ĐÔNG Á - 2000t 18.11 duyệt 2200001196 - OTBD cân tải 200mt - Tân Thuận | J21: cân đối vào làm trước 2900mt Lượng còn lại 17.11 duyệt | K21: HƠI GẤP | L21: Thiên Phúc | N21: =2000+2000+1000+200+670 -> 5870
A22: 18 | B22: Mạnh Thắng 68 | C22: 3940 | D22: Xong | E22: 12h40 ngày 21/11 Bến 1 | G22: Dung Quất | H22: Long An | I22: 2000001440 - VNO - 1500t - KHÔNG VƯỢT LỆNH 2000001485 - MOV 2000001486 - MOV 2000001476 - VNO - 700t - cân tải - CHỈ LÊN KHOẢNG 500T ĐỂ ĐỢI LỆNH MOV | J22: =C22-1500-1972 -> 468 | K22: CHẬM | L22: MT Hà Nội | N22: =1000+650+350+1500 -> 3500
A23: 19 | B23: Việt Thuận 11-02 | C23: 10200 | D23: xong | E23: 10h40 ngày 20/11 Bến 05 | G23: Dung Quất | H23: Hải Phòng | I23: 2000001454 - TVĐ 3800MT 21.11 duyệt 2000001487 - 800mt THACO 2000001478 - 1000T Thành Đạt 2200001197 - OTHY 500T 2200001194- NMCN cân tải | K23: BÌNH THƯỜNG | L23: Mạnh Thắng | N23: =3800+1300-10200 -> -5100
A24: 20 | B24: MT Hà Nội 39 | C24: 4250 | D24: Xong | E24: Ngày 23/11 Cập bến 1 | G24: Dung Quất | H24: Long Bình | I24: 2200001196 - OTBD | K24: BÌNH THƯỜNG | L24: MT Hà Nội
A25: 21 | B25: MT Hà Nội 07 | C25: 3000 | D25: Xong | E25: 14h00 25/11 Bến 1 | G25: Dung Quất | H25: Long Bình | I25: 2200001196 - OTBD | L25: MT Hà Nội
A26: 22 | B26: Việt Thuận 215-06 | C26: 16000 | D26: xong | E26: 07H30 24/11 cập cầu 5 | G26: Dung Quất | H26: Hải Phòng | I26: 2000001489 - THACO 500MT 2000001494 - KKBV 1300MT 2000001496 - KKBV - 200MT 2000001465 - TCĐ 1000MT 2200001193 - OTHY 3000T 2200001183 - OTHY 135T 2200001194 - NMCN 800T 2200001201 - THP 3000T 2200001203 - NMCN 4500T 2200001198 - OTHY 100T 2200001205 - NMCN - 2200T | J26: =500+1300+1000+3000+135+800+3000+4500+100+200 -> 14535 | L26: Mạnh Thắng
A27: 23 | B27: Hai Au 28 | C27: 5000 | D27: Xong | E27: kế hoạch 17h00 26/11 tàu cập câu 1 | G27: Dung Quất | H27: Jakarta/Subaraya | I27: 2400000023 - SI 3000MT (JKT) 2400000024 - SI 1000MT (Subaraya) 2400000025 - SI 500MT (Subaraya) 2400000026 - SI 500MT (JKT) | J27: Có nhãn phụ | K27: CHẬM | L27: Thái Sơn
A28: 24 | B28: VINACOMIN CẨM PHẢ | C28: 6771 | D28: xong | E28: 17h00 ngày 28/11 bến 5 | G28: Dung Quất | H28: Phú Mỹ | I28: 2000001370 - 6000MT CỦA SMCCK - cân tải 2000001433 - TLPM 1000MT chiều duyệt | L28: Thiên Phúc
A29: 25 | B29: Viễn Đông 88 | C29: 8075 | D29: Đang làm hàng | E29: 30/11 Bến 5 | G29: Dung Quất | H29: Hải Phòng | I29: 2000001406 - CTC 1500MT 2000001501 - MI (TP) 1800MT (1/12 duyệt) 2000001479 - HÙNG NGUYÊN 2000001419 - HÙNG NGUYÊN 2200001205 - NMCN 475MT 2000001464 - NIPPON - T6 DUYỆT 2000001504 - VINAS - 200t - mai duyệt 2000001448 - TMN cân tải (2000mt) (1/12 duyệt) - chưa Duyệt | L29: Mặt Trời | N29: =8075-1500-1800-2200-100-475 -> 2000
A30: 26 | B30: MT Hà Nội 07 | C30: 3000 | D30: Đang làm hàng | E30: 20h00 01/12 Bến 2 | G30: Dung Quất | H30: Long An/Long Bình | I30: 2000001491 - MITSUI (LONG AN) 2200001196 - OTBD 1770T (LONG BÌNH) 2200001204 - OTBD cân tải (LONG BÌNH) | L30: MT Hà Nội
A31: 27 | B31: MT Hà Nội 39 | C31: 4250 | D31: 20h00 30.11.22 | E31: 02/12 Bến 1 | G31: Dung Quất | H31: Tân Thuận | I31: 2000001502 - TĐA 2000001503 - JFE | J31: HÀNG MỚI SẢN XUẤT CHƯA LÀM ĐƯỢC, THỨ 6 LÀM | L31: MT Hà Nội
A32: 28 | B32: LIANSON DYNAMIC
A33: 29
A34: 30 | H34: Hải Phòng | I34: 2000001493 - KKBV 1500MT tuần sau mới lấy
H35: Tân Thuận | I35: Citicom 600mt Sunsco 300mt
I52: GHÉP HÀNG ĐI LONG AN - 500T - NGÀY 29/11 CÓ LỆNH

Sheet LỊCH TÀU - 06.22
A2: CẬP NHẬT TÌNH HÌNH XUẤT HÀNG HRC THÁNG 06/2022
C3: =SUBTOTAL(9,C7:C375) -> 192114 | I3: =TODAY() -> 45987
A4: STT | B4: Tàu | C4: KHỐI LƯỢNG | D4: CẬP NHẬT TÌNH HÌNH/ETA | E4: CẬP NHẬT ETB | F4: CẢNG XẾP | G4: CẢNG ĐẾN | H4: LỆNH XUẤT HÀNG | I4: GHI CHÚ | J4: ĐẠI LÝ | K4: KL | L4: TỔNG HỢP | M4: =SUM(M5:M10) -> 176641
A5: {=_xlfn.SEQUENCE(60,1,1,)} -> 1 | B5: Thành Đạt 228 | C5: 3200 | D5: Xong | E5: 19h00 ngày 31/05 Bến 1 | F5: Dung Quất | G5: Long Bình | H5: 2200001066 - OTBD Cân tải | J5: MT Hà Nội | K5: =C5 -> 3200 | L5: Mạnh Thắng | M5: =SUMIF($J:$J,L5,K:K) -> 26500
A6: 2 | B6: THÀNH ĐẠT 28 | C6: 3250 | D6: Xong | E6: Bến 1 | F6: Dung Quất | G6: Quy Nhơn | H6: 2000000998 - HSNH 3250MT | I6: Hàng ngày 29 trở về trước làm được rồi có cầu bến đẩy vô làm luôn | J6: Mặt Trời | K6: =C6 -> 3250 | L6: Nam Phát | M6: =SUMIF($J:$J,L6,K:K) -> 12300
A7: 3 | B7: Hiền Anh 688 | C7: 4060 | D7: Xong | E7: 0h00 ngày 02/06 Bến 2 | F7: Dung Quất | G7: PHÚ MỸ | H7: 2000000994 - POSCO - 1000T 2000000981 - TẤM LÁ 2200mt 2200001062 - OTHY đi PM 515mt 2000001006 - Nội Thất cân tải | I7: Hàng Hóa ok Còn lệnh 2*1006 Rel 4 rồi có cầu bến vô làm luôn | J7: Thiên Phúc | K7: =C7 -> 4060 | L7: Thiên Phúc | M7: =SUMIF($J:$J,L7,K:K) -> 45430
A8: 4 | B8: SFL HUDSON | C8: 15000 | D8: Xong | E8: 7h00 ngày 30/05 Bến 5/10 | F8: Dung Quất | G8: RAVENNA | H8: 2400000010 - MARCEGAGLIA | I8: Xuất 643 coils | J8: S&A | K8: =C8 -> 15000 | L8: Bình Sơn | M8: =SUMIF($J:$J,L8,K:K) -> 8361
A9: 5 | B9: Phú Minh 99 | C9: 3050 | D9: Xong | E9: 07h10 ngày 02/06 Bến 1 | F9: Dung Quất | G9: Miền Nam | H9: 2200001066 - OTBD 1000mt 2200001068 - OTBD cân tải | J9: Mặt Trời | K9: =C9 -> 3050 | L9: MT Hà Nội | M9: =SUMIF($J:$J,L9,K:K) -> 41050
A10: 6 | B10: Nam Phát 18 | C10: 1150 | D10: Xong | E10: 14h00 ngày 02/06 Bến 3 | F10: Dung Quất | G10: Hải Phòng | H10: 2200001060 - THP 1150mt 2.00x1232 ưu tiên, xuất hết hàng 1270 | I10: Hàng hóa ok + Cầu trống đẩy vô | J10: Nam Phát | K10: =C10 -> 1150 | L10: Mặt Trời | M10: =SUMIF($J:$J,L10,K:K) -> 43000
A11: 7 | B11: Hoàng Anh 68 | C11: 4000 | D11: Xong | E11: 18h30 ngày 02/06 Bến 2 | F11: Dung Quất | G11: Hải Phòng | H11: 2200001071 - NCMN | I11: Hàng hóa ok + Cầu trống đẩy vô | J11: MT Hà Nội | K11: =C11 -> 4000
A12: 8 | B12: Minh Khánh 25 | C12: 3400 | D12: Xong | E12: 22h15 ngày 02/06 Bến 1 | F12: Dung Quất | G12: Miền Nam | H12: 2200001047 - OTHY đi Tân Thuận 2200001048 - OTHY đi Tân Thuận | I12: Hàng hóa ok + Cầu trống đẩy vô | J12: Mạnh Thắng | K12: =C12 -> 3400
A13: 9 | B13: Minh Tân 68 | C13: 3800 | D13: Xong | E13: 09h00 ngày 03/06 Bến 2 | F13: Dung Quất | G13: Hải Phòng | H13: 2200001071 - NCMN | I13: Hàng hóa ok + Cầu trống đẩy vô | J13: Thiên Phúc | K13: =C13 -> 3800
A14: 10 | B14: Bình Sơn 76 | C14: 2787 | D14: Xong | E14: 11h00 ngày 03/06 Bến 1 | F14: Dung Quất | G14: Hải Phòng | H14: 2200001060 - THP 2787MT | I14: Hàng hóa ok + Cầu trống đẩy vô | J14: Bình Sơn | K14: =C14 -> 2787
A15: 11 | B15: Ninhco 66 | C15: 3750 | D15: Xong | E15: 0h00 ngày 04/06 Bến 2 | F15: Dung Quất | G15: Thiên Lộc Thành | H15: 2000001018 - TÂY NAM (2.00x1212) 2000000992 - TÂY NAM (2.30x1212) (Cân Tải) | J15: Mạnh Thắng | K15: =C15 -> 3750
A16: 12 | B16: Thắng Lợi 89 | C16: 4350 | D16: Xong | E16: 02h00 ngày 04/06 Bến 1 | F16: Dung Quất | G16: Hải Phòng | H16: 2200001069 - OTHY | J16: Thiên Phúc | K16: =C16 -> 4350
A17: 13 | B17: Minh Khánh 86 | C17: 3550 | D17: Xong | E17: 04h30 ngày 04/06 Bến 3 | F17: Dung Quất | G17: Miền Nam | H17: 2200001068 - OTBD không xuất hàng trên list thông tin nhanh | J17: Mạnh Thắng | K17: =C17 -> 3550
A18: 14 | B18: Phương Nam 88 | C18: 4500 | D18: Xong | E18: 14h00 ngày 04/06 Bến 2 | F18: Dung Quất | G18: Hải Phòng | H18: 2200001071 - NCMN 2325T 2200001069 - OTHY cân tải | I18: Hàng hóa ok + Cầu trống đẩy vô | J18: Mạnh Thắng | K18: =C18 -> 4500
A19: 15 | B19: PHƯƠNG NAM 145 | C19: 4600 | D19: Xong | E19: 16h30 ngày 04/06 Bến 1 | F19: Dung Quất | G19: Hải Phòng | H19: 2200001069 - OTHY 2400T 2200001060 - THP 2200MT | I19: Hàng hóa ok + Cầu trống đẩy vô | J19: Nam Phát | K19: =C19 -> 4600
A20: 16 | B20: An Bình 99 | C20: 3500 | D20: Xong | E20: 13h20 ngày 05/06 Bến 2 | F20: Dung Quất | G20: Hải Phòng | H20: 2200001069 - OTHY (Hết mapping) 2200001060 - THP Cân tải | I20: Hàng hóa ok + Cầu trống đẩy vô | J20: MT Hà Nội | K20: =C20 -> 3500
A21: 17 | B21: Thành Đạt 28 | C21: 3250 | D21: Xong | E21: 22h50 ngày 05/06 Bến 1 | F21: Dung Quất | G21: Quy Nhơn | H21: 2000000997 - HSNH 3200MT | I21: tàu này quay lại lấy hàng HRC, ưu tiên xuất nhé Hàng hóa ok rồi ấy. Tàu vô thì đẩy làm luôn đi | J21: Mặt Trời | K21: =C21 -> 3250
A22: 18 | B22: Ninhco 66 | C22: 4300 | D22: Xong | E22: 20h45 ngày 05/06 Bến 5 | F22: Dung Quất | G22: Hải Phòng | H22: 2200001060 - THP 4300MT | I22: 1K hàng ngày ca 2 ngày 03/06 1K hàng ca 1 ngày 04/06 | J22: Mặt Trời | K22: =C22 -> 4300
A23: 19 | B23: Duy Hoàng 99 | C23: 3280 | D23: Xong | E23: 13h30 ngày 06/06 Bến 2 | F23: Dung Quất | G23: Miền Nam | H23: 2200001068 - OTBD không xuất hàng trên list thông tin nhanh | I23: Hàng hóa okay. Tàu đến cho vô làm hàng | J23: Mặt Trời | K23: =C23 -> 3280
A24: 20 | B24: Bình Sơn 79 | C24: 2787 | D24: Xong | E24: 21h15 ngày 06/06 Bến 1 | F24: Dung Quất | G24: Hải Phòng | H24: 2200001060 - THP 2787MT | J24: Bình Sơn | K24: =C24 -> 2787
A25: 21 | B25: Đạt Anh 27 | C25: 3030 | D25: Xong | E25: 04h30 ngày 08/06 Bến 1 | F25: Dung Quất | G25: Miền Nam | H25: 2200001068 - OTBD không xuất hàng trên list thông tin nhanh | J25: Mặt Trời | K25: =C25 -> 3030
A26: 22 | B26: Hải An 36 | C26: 3400 | D26: Xong | E26: 04h30 ngày 09/06 Bến 3 | F26: Dung Quất | G26: Miền Nam | H26: 2200001068 - OTBD không xuất hàng trên list thông tin nhanh | J26: MT Hà Nội | K26: =C26 -> 3400
A27: 23 | B27: Hải Long 27 | C27: 4700 | D27: Xong | E27: 13h00 ngày 10/06 Bến 1 | F27: Dung Quất | G27: Phú Mỹ | H27: 2400000008 - GS Global 1926mt 2000001003 - Nam Hưng 2800mt | I27: Hàng đơn XK cắt trước, đơn Nam Hưng cắt sau | J27: MT Hà Nội | K27: =C27 -> 4700
A28: 24 | B28: Phương Nam 98 | C28: 4720 | D28: Xong | E28: 09h00 ngày 10/06 Bến3 | F28: Dung Quất | G28: Hải Phòng | H28: 2200001060 - THP 1731mt 2000001019 - IPC 1000MT 2200001073 - 800mt 2200001017 - OTHY 1200MT cân tải nhé HUY | I28: Cần chuyển 1 ít hàng của 20*1013 sang 20*1019 | J28: Thiên Phúc | K28: =C28 -> 4720
